2024-04-22 07:39:20,506 -  nornir.core -     INFO -        run() - Running task 'nornir_napalm_get_example' with args {} on 1 hosts
2024-04-22 07:39:20,508 - nornir.core.task -    ERROR -      start() - Host 'R1': task 'napalm_get' failed with traceback:
Traceback (most recent call last):
  File "/home/kali/.local/lib/python3.11/site-packages/nornir/core/task.py", line 99, in start
    r = self.task(self, **self.params)
        ^^^^^^^^^^^^^^^^^^^^^^^^^^^^^^
  File "/home/kali/.local/lib/python3.11/site-packages/nornir_napalm/plugins/tasks/napalm_get.py", line 32, in napalm_get
    device = task.host.get_connection(CONNECTION_NAME, task.nornir.config)
             ^^^^^^^^^^^^^^^^^^^^^^^^^^^^^^^^^^^^^^^^^^^^^^^^^^^^^^^^^^^^^
  File "/home/kali/.local/lib/python3.11/site-packages/nornir/core/inventory.py", line 494, in get_connection
    self.open_connection(
  File "/home/kali/.local/lib/python3.11/site-packages/nornir/core/inventory.py", line 546, in open_connection
    conn_obj.open(
  File "/home/kali/.local/lib/python3.11/site-packages/nornir_napalm/plugins/connections/__init__.py", line 55, in open
    network_driver = get_network_driver(platform)
                     ^^^^^^^^^^^^^^^^^^^^^^^^^^^^
  File "/home/kali/.local/lib/python3.11/site-packages/napalm/base/__init__.py", line 70, in get_network_driver
    raise ModuleImportError("Please provide a valid driver name.")
napalm.base.exceptions.ModuleImportError: Please provide a valid driver name.

2024-04-22 07:39:20,508 - nornir.core.task -    ERROR -      start() - Host 'R1': task 'nornir_napalm_get_example' failed with traceback:
Traceback (most recent call last):
  File "/home/kali/.local/lib/python3.11/site-packages/nornir/core/task.py", line 99, in start
    r = self.task(self, **self.params)
        ^^^^^^^^^^^^^^^^^^^^^^^^^^^^^^
  File "/home/kali/Desktop/Nornir/2023/5.nornir_napalm/test_HPE/Aruba.py", line 12, in nornir_napalm_get_example
    task.run(task=napalm_get, getters=[g])
  File "/home/kali/.local/lib/python3.11/site-packages/nornir/core/task.py", line 174, in run
    raise NornirSubTaskError(task=run_task, result=r)
nornir.core.exceptions.NornirSubTaskError: Subtask: napalm_get (failed)


2024-04-22 07:40:36,494 -  nornir.core -     INFO -        run() - Running task 'nornir_napalm_cli_commands_example' with args {} on 1 hosts
2024-04-22 07:40:36,496 - nornir.core.task -    ERROR -      start() - Host 'R1': task 'napalm_cli' failed with traceback:
Traceback (most recent call last):
  File "/home/kali/.local/lib/python3.11/site-packages/nornir/core/task.py", line 99, in start
    r = self.task(self, **self.params)
        ^^^^^^^^^^^^^^^^^^^^^^^^^^^^^^
  File "/home/kali/.local/lib/python3.11/site-packages/nornir_napalm/plugins/tasks/napalm_cli.py", line 19, in napalm_cli
    device = task.host.get_connection(CONNECTION_NAME, task.nornir.config)
             ^^^^^^^^^^^^^^^^^^^^^^^^^^^^^^^^^^^^^^^^^^^^^^^^^^^^^^^^^^^^^
  File "/home/kali/.local/lib/python3.11/site-packages/nornir/core/inventory.py", line 494, in get_connection
    self.open_connection(
  File "/home/kali/.local/lib/python3.11/site-packages/nornir/core/inventory.py", line 546, in open_connection
    conn_obj.open(
  File "/home/kali/.local/lib/python3.11/site-packages/nornir_napalm/plugins/connections/__init__.py", line 55, in open
    network_driver = get_network_driver(platform)
                     ^^^^^^^^^^^^^^^^^^^^^^^^^^^^
  File "/home/kali/.local/lib/python3.11/site-packages/napalm/base/__init__.py", line 70, in get_network_driver
    raise ModuleImportError("Please provide a valid driver name.")
napalm.base.exceptions.ModuleImportError: Please provide a valid driver name.

2024-04-22 07:40:36,496 - nornir.core.task -    ERROR -      start() - Host 'R1': task 'nornir_napalm_cli_commands_example' failed with traceback:
Traceback (most recent call last):
  File "/home/kali/.local/lib/python3.11/site-packages/nornir/core/task.py", line 99, in start
    r = self.task(self, **self.params)
        ^^^^^^^^^^^^^^^^^^^^^^^^^^^^^^
  File "/home/kali/Desktop/Nornir/2023/5.nornir_napalm/test_HPE/Aruba.py", line 13, in nornir_napalm_cli_commands_example
    task.run(task=napalm_cli, commands=[command])
  File "/home/kali/.local/lib/python3.11/site-packages/nornir/core/task.py", line 174, in run
    raise NornirSubTaskError(task=run_task, result=r)
nornir.core.exceptions.NornirSubTaskError: Subtask: napalm_cli (failed)


2024-04-24 02:11:41,009 -  nornir.core -     INFO -        run() - Running task 'nornir_napalm_cli_commands_example' with args {} on 1 hosts
2024-04-24 02:11:41,011 - nornir.core.task -    ERROR -      start() - Host 'R1': task 'napalm_cli' failed with traceback:
Traceback (most recent call last):
  File "/home/kali/.local/lib/python3.11/site-packages/nornir/core/task.py", line 99, in start
    r = self.task(self, **self.params)
        ^^^^^^^^^^^^^^^^^^^^^^^^^^^^^^
  File "/home/kali/.local/lib/python3.11/site-packages/nornir_napalm/plugins/tasks/napalm_cli.py", line 19, in napalm_cli
    device = task.host.get_connection(CONNECTION_NAME, task.nornir.config)
             ^^^^^^^^^^^^^^^^^^^^^^^^^^^^^^^^^^^^^^^^^^^^^^^^^^^^^^^^^^^^^
  File "/home/kali/.local/lib/python3.11/site-packages/nornir/core/inventory.py", line 494, in get_connection
    self.open_connection(
  File "/home/kali/.local/lib/python3.11/site-packages/nornir/core/inventory.py", line 546, in open_connection
    conn_obj.open(
  File "/home/kali/.local/lib/python3.11/site-packages/nornir_napalm/plugins/connections/__init__.py", line 55, in open
    network_driver = get_network_driver(platform)
                     ^^^^^^^^^^^^^^^^^^^^^^^^^^^^
  File "/home/kali/.local/lib/python3.11/site-packages/napalm/base/__init__.py", line 70, in get_network_driver
    raise ModuleImportError("Please provide a valid driver name.")
napalm.base.exceptions.ModuleImportError: Please provide a valid driver name.

2024-04-24 02:11:41,012 - nornir.core.task -    ERROR -      start() - Host 'R1': task 'nornir_napalm_cli_commands_example' failed with traceback:
Traceback (most recent call last):
  File "/home/kali/.local/lib/python3.11/site-packages/nornir/core/task.py", line 99, in start
    r = self.task(self, **self.params)
        ^^^^^^^^^^^^^^^^^^^^^^^^^^^^^^
  File "/home/kali/Desktop/Nornir/2023/5.nornir_napalm/test_HPE/Aruba.py", line 13, in nornir_napalm_cli_commands_example
    task.run(task=napalm_cli, commands=[command])
  File "/home/kali/.local/lib/python3.11/site-packages/nornir/core/task.py", line 174, in run
    raise NornirSubTaskError(task=run_task, result=r)
nornir.core.exceptions.NornirSubTaskError: Subtask: napalm_cli (failed)


