2024-08-29 02:48:52,704 -  nornir.core -     INFO -        run() - Running task 'nornir_napalm_get_example' with args {} on 2 hosts
2024-08-29 02:49:25,308 -  nornir.core -     INFO -        run() - Running task 'nornir_napalm_get_example' with args {} on 2 hosts
2024-08-29 02:50:08,475 -  nornir.core -     INFO -        run() - Running task 'nornir_napalm_get_example' with args {} on 2 hosts
2024-08-29 02:51:52,937 -  nornir.core -     INFO -        run() - Running task 'nornir_napalm_get_example' with args {} on 2 hosts
2024-08-29 02:56:35,851 -  nornir.core -     INFO -        run() - Running task 'Creating Backup Archive' with args {} on 2 hosts
2024-08-29 02:56:36,820 - nornir.core.task -    ERROR -      start() - Host 'BHP-A-9F-SW': task 'Creating Backup Archive' failed with traceback:
Traceback (most recent call last):
  File "/home/kali/.local/lib/python3.11/site-packages/nornir/core/task.py", line 99, in start
    r = self.task(self, **self.params)
        ^^^^^^^^^^^^^^^^^^^^^^^^^^^^^^
  File "/home/kali/Desktop/Nornir/2023/IITH/config_backup/backup.py", line 23, in backup_configurations
    task=write_file,
         ^^^^^^^^^^
NameError: name 'write_file' is not defined

2024-08-29 02:56:36,821 - nornir.core.task -    ERROR -      start() - Host 'BHP-A-6F-SW': task 'Creating Backup Archive' failed with traceback:
Traceback (most recent call last):
  File "/home/kali/.local/lib/python3.11/site-packages/nornir/core/task.py", line 99, in start
    r = self.task(self, **self.params)
        ^^^^^^^^^^^^^^^^^^^^^^^^^^^^^^
  File "/home/kali/Desktop/Nornir/2023/IITH/config_backup/backup.py", line 23, in backup_configurations
    task=write_file,
         ^^^^^^^^^^
NameError: name 'write_file' is not defined

2024-08-29 03:02:43,451 -  nornir.core -     INFO -        run() - Running task 'Creating Backup Archive' with args {} on 2 hosts
2024-08-29 03:02:44,463 - nornir.core.task -    ERROR -      start() - Host 'BHP-A-9F-SW': task 'Creating Backup Archive' failed with traceback:
Traceback (most recent call last):
  File "/home/kali/.local/lib/python3.11/site-packages/nornir/core/task.py", line 99, in start
    r = self.task(self, **self.params)
        ^^^^^^^^^^^^^^^^^^^^^^^^^^^^^^
  File "/home/kali/Desktop/Nornir/2023/IITH/config_backup/backup.py", line 24, in backup_configurations
    content=r.result["config"]["running"],
            ~~~~~~~~^^^^^^^^^^
KeyError: 'config'

2024-08-29 03:02:44,464 - nornir.core.task -    ERROR -      start() - Host 'BHP-A-6F-SW': task 'Creating Backup Archive' failed with traceback:
Traceback (most recent call last):
  File "/home/kali/.local/lib/python3.11/site-packages/nornir/core/task.py", line 99, in start
    r = self.task(self, **self.params)
        ^^^^^^^^^^^^^^^^^^^^^^^^^^^^^^
  File "/home/kali/Desktop/Nornir/2023/IITH/config_backup/backup.py", line 24, in backup_configurations
    content=r.result["config"]["running"],
            ~~~~~~~~^^^^^^^^^^
KeyError: 'config'

2024-08-29 03:05:13,606 -  nornir.core -     INFO -        run() - Running task 'Creating Backup Archive' with args {} on 2 hosts
2024-08-29 03:05:14,530 - nornir.core.task -    ERROR -      start() - Host 'BHP-A-9F-SW': task 'Creating Backup Archive' failed with traceback:
Traceback (most recent call last):
  File "/home/kali/.local/lib/python3.11/site-packages/nornir/core/task.py", line 99, in start
    r = self.task(self, **self.params)
        ^^^^^^^^^^^^^^^^^^^^^^^^^^^^^^
  File "/home/kali/Desktop/Nornir/2023/IITH/config_backup/backup.py", line 24, in backup_configurations
    content=r.result["config"]["running"],
            ~~~~~~~~^^^^^^^^^^
KeyError: 'config'

2024-08-29 03:05:14,577 - nornir.core.task -    ERROR -      start() - Host 'BHP-A-6F-SW': task 'Creating Backup Archive' failed with traceback:
Traceback (most recent call last):
  File "/home/kali/.local/lib/python3.11/site-packages/nornir/core/task.py", line 99, in start
    r = self.task(self, **self.params)
        ^^^^^^^^^^^^^^^^^^^^^^^^^^^^^^
  File "/home/kali/Desktop/Nornir/2023/IITH/config_backup/backup.py", line 24, in backup_configurations
    content=r.result["config"]["running"],
            ~~~~~~~~^^^^^^^^^^
KeyError: 'config'

2024-08-29 03:10:30,654 -  nornir.core -     INFO -        run() - Running task 'Creating Backup Archive' with args {} on 2 hosts
2024-08-29 03:10:31,602 - nornir.core.task -    ERROR -      start() - Host 'BHP-A-6F-SW': task 'Creating Backup Archive' failed with traceback:
Traceback (most recent call last):
  File "/home/kali/.local/lib/python3.11/site-packages/nornir/core/task.py", line 99, in start
    r = self.task(self, **self.params)
        ^^^^^^^^^^^^^^^^^^^^^^^^^^^^^^
  File "/home/kali/Desktop/Nornir/2023/IITH/config_backup/backup.py", line 24, in backup_configurations
    content=r.result["config"]["running"],
            ~~~~~~~~^^^^^^^^^^
KeyError: 'config'

2024-08-29 03:10:31,612 - nornir.core.task -    ERROR -      start() - Host 'BHP-A-9F-SW': task 'Creating Backup Archive' failed with traceback:
Traceback (most recent call last):
  File "/home/kali/.local/lib/python3.11/site-packages/nornir/core/task.py", line 99, in start
    r = self.task(self, **self.params)
        ^^^^^^^^^^^^^^^^^^^^^^^^^^^^^^
  File "/home/kali/Desktop/Nornir/2023/IITH/config_backup/backup.py", line 24, in backup_configurations
    content=r.result["config"]["running"],
            ~~~~~~~~^^^^^^^^^^
KeyError: 'config'

2024-09-06 06:39:52,845 -  nornir.core -     INFO -        run() - Running task 'Creating Backup Archive' with args {} on 2 hosts
2024-09-06 06:39:52,846 - nornir.core.task -    ERROR -      start() - Host 'BHP-A-6F-SW': task 'Creating Backup Archive' failed with traceback:
Traceback (most recent call last):
  File "/home/kali/.local/lib/python3.11/site-packages/nornir/core/task.py", line 99, in start
    r = self.task(self, **self.params)
        ^^^^^^^^^^^^^^^^^^^^^^^^^^^^^^
  File "/home/kali/Desktop/Nornir/2023/IITH/config_backup/backup.py", line 17, in backup_configurations
    date_dir = config_dir + "/" + str(date.today())
                                      ^^^^
NameError: name 'date' is not defined

2024-09-06 06:39:52,846 - nornir.core.task -    ERROR -      start() - Host 'BHP-A-9F-SW': task 'Creating Backup Archive' failed with traceback:
Traceback (most recent call last):
  File "/home/kali/.local/lib/python3.11/site-packages/nornir/core/task.py", line 99, in start
    r = self.task(self, **self.params)
        ^^^^^^^^^^^^^^^^^^^^^^^^^^^^^^
  File "/home/kali/Desktop/Nornir/2023/IITH/config_backup/backup.py", line 17, in backup_configurations
    date_dir = config_dir + "/" + str(date.today())
                                      ^^^^
NameError: name 'date' is not defined

2024-09-06 06:50:13,484 -  nornir.core -     INFO -        run() - Running task 'Creating Backup Archive' with args {} on 2 hosts
2024-09-06 06:50:14,567 - nornir.core.task -    ERROR -      start() - Host 'BHP-A-9F-SW': task 'Creating Backup Archive' failed with traceback:
Traceback (most recent call last):
  File "/home/kali/.local/lib/python3.11/site-packages/nornir/core/task.py", line 99, in start
    r = self.task(self, **self.params)
        ^^^^^^^^^^^^^^^^^^^^^^^^^^^^^^
  File "/home/kali/Desktop/Nornir/2023/IITH/config_backup/backup.py", line 23, in backup_configurations
    task=fns.write_file,
         ^^^^^^^^^^^^^^
AttributeError: module 'nornir_utils.plugins.functions' has no attribute 'write_file'

2024-09-06 06:50:14,765 - nornir.core.task -    ERROR -      start() - Host 'BHP-A-6F-SW': task 'Creating Backup Archive' failed with traceback:
Traceback (most recent call last):
  File "/home/kali/.local/lib/python3.11/site-packages/nornir/core/task.py", line 99, in start
    r = self.task(self, **self.params)
        ^^^^^^^^^^^^^^^^^^^^^^^^^^^^^^
  File "/home/kali/Desktop/Nornir/2023/IITH/config_backup/backup.py", line 23, in backup_configurations
    task=fns.write_file,
         ^^^^^^^^^^^^^^
AttributeError: module 'nornir_utils.plugins.functions' has no attribute 'write_file'

2024-09-06 06:50:24,813 -  nornir.core -     INFO -        run() - Running task 'Creating Backup Archive' with args {} on 2 hosts
2024-09-06 06:50:25,935 - nornir.core.task -    ERROR -      start() - Host 'BHP-A-6F-SW': task 'Creating Backup Archive' failed with traceback:
Traceback (most recent call last):
  File "/home/kali/.local/lib/python3.11/site-packages/nornir/core/task.py", line 99, in start
    r = self.task(self, **self.params)
        ^^^^^^^^^^^^^^^^^^^^^^^^^^^^^^
  File "/home/kali/Desktop/Nornir/2023/IITH/config_backup/backup.py", line 23, in backup_configurations
    task=fns.write_file,
         ^^^^^^^^^^^^^^
AttributeError: module 'nornir_utils.plugins.functions' has no attribute 'write_file'

2024-09-06 06:50:25,971 - nornir.core.task -    ERROR -      start() - Host 'BHP-A-9F-SW': task 'Creating Backup Archive' failed with traceback:
Traceback (most recent call last):
  File "/home/kali/.local/lib/python3.11/site-packages/nornir/core/task.py", line 99, in start
    r = self.task(self, **self.params)
        ^^^^^^^^^^^^^^^^^^^^^^^^^^^^^^
  File "/home/kali/Desktop/Nornir/2023/IITH/config_backup/backup.py", line 23, in backup_configurations
    task=fns.write_file,
         ^^^^^^^^^^^^^^
AttributeError: module 'nornir_utils.plugins.functions' has no attribute 'write_file'

2024-09-06 06:51:56,861 -  nornir.core -     INFO -        run() - Running task 'Creating Backup Archive' with args {} on 2 hosts
2024-09-06 06:51:57,814 - nornir.core.task -    ERROR -      start() - Host 'BHP-A-6F-SW': task 'Creating Backup Archive' failed with traceback:
Traceback (most recent call last):
  File "/home/kali/.local/lib/python3.11/site-packages/nornir/core/task.py", line 99, in start
    r = self.task(self, **self.params)
        ^^^^^^^^^^^^^^^^^^^^^^^^^^^^^^
  File "/home/kali/Desktop/Nornir/2023/IITH/config_backup/backup.py", line 23, in backup_configurations
    task=fns.write_file,
         ^^^^^^^^^^^^^^
AttributeError: module 'nornir_utils.plugins.functions' has no attribute 'write_file'

2024-09-06 06:51:57,815 - nornir.core.task -    ERROR -      start() - Host 'BHP-A-9F-SW': task 'Creating Backup Archive' failed with traceback:
Traceback (most recent call last):
  File "/home/kali/.local/lib/python3.11/site-packages/nornir/core/task.py", line 99, in start
    r = self.task(self, **self.params)
        ^^^^^^^^^^^^^^^^^^^^^^^^^^^^^^
  File "/home/kali/Desktop/Nornir/2023/IITH/config_backup/backup.py", line 23, in backup_configurations
    task=fns.write_file,
         ^^^^^^^^^^^^^^
AttributeError: module 'nornir_utils.plugins.functions' has no attribute 'write_file'

2024-09-06 06:55:42,127 -  nornir.core -     INFO -        run() - Running task 'Creating Backup Archive' with args {} on 3 hosts
2024-09-06 06:55:52,169 - nornir.core.task -    ERROR -      start() - Host 'BHP-A-3F-SW': task 'napalm_get' failed with traceback:
Traceback (most recent call last):
  File "/home/kali/.local/lib/python3.11/site-packages/netmiko/base_connection.py", line 1137, in establish_connection
    self.remote_conn_pre.connect(**ssh_connect_params)
  File "/usr/lib/python3/dist-packages/paramiko/client.py", line 358, in connect
    retry_on_signal(lambda: sock.connect(addr))
  File "/usr/lib/python3/dist-packages/paramiko/util.py", line 279, in retry_on_signal
    return function()
           ^^^^^^^^^^
  File "/usr/lib/python3/dist-packages/paramiko/client.py", line 358, in <lambda>
    retry_on_signal(lambda: sock.connect(addr))
                            ^^^^^^^^^^^^^^^^^^
TimeoutError: timed out

During handling of the above exception, another exception occurred:

Traceback (most recent call last):
  File "/home/kali/.local/lib/python3.11/site-packages/napalm/base/base.py", line 114, in _netmiko_open
    self._netmiko_device = ConnectHandler(
                           ^^^^^^^^^^^^^^^
  File "/home/kali/.local/lib/python3.11/site-packages/netmiko/ssh_dispatcher.py", line 399, in ConnectHandler
    return ConnectionClass(*args, **kwargs)
           ^^^^^^^^^^^^^^^^^^^^^^^^^^^^^^^^
  File "/home/kali/.local/lib/python3.11/site-packages/netmiko/base_connection.py", line 488, in __init__
    self._open()
  File "/home/kali/.local/lib/python3.11/site-packages/netmiko/base_connection.py", line 493, in _open
    self.establish_connection()
  File "/home/kali/.local/lib/python3.11/site-packages/netmiko/base_connection.py", line 1159, in establish_connection
    raise NetmikoTimeoutException(msg)
netmiko.exceptions.NetmikoTimeoutException: TCP connection to device failed.

Common causes of this problem are:
1. Incorrect hostname or IP address.
2. Wrong TCP port.
3. Intermediate firewall blocking access.

Device settings: cisco_ios 10.5.48.62:22



During handling of the above exception, another exception occurred:

Traceback (most recent call last):
  File "/home/kali/.local/lib/python3.11/site-packages/nornir/core/task.py", line 99, in start
    r = self.task(self, **self.params)
        ^^^^^^^^^^^^^^^^^^^^^^^^^^^^^^
  File "/home/kali/.local/lib/python3.11/site-packages/nornir_napalm/plugins/tasks/napalm_get.py", line 32, in napalm_get
    device = task.host.get_connection(CONNECTION_NAME, task.nornir.config)
             ^^^^^^^^^^^^^^^^^^^^^^^^^^^^^^^^^^^^^^^^^^^^^^^^^^^^^^^^^^^^^
  File "/home/kali/.local/lib/python3.11/site-packages/nornir/core/inventory.py", line 494, in get_connection
    self.open_connection(
  File "/home/kali/.local/lib/python3.11/site-packages/nornir/core/inventory.py", line 546, in open_connection
    conn_obj.open(
  File "/home/kali/.local/lib/python3.11/site-packages/nornir_napalm/plugins/connections/__init__.py", line 57, in open
    connection.open()
  File "/home/kali/.local/lib/python3.11/site-packages/napalm/ios/ios.py", line 173, in open
    self.device = self._netmiko_open(
                  ^^^^^^^^^^^^^^^^^^^
  File "/home/kali/.local/lib/python3.11/site-packages/napalm/base/base.py", line 123, in _netmiko_open
    raise ConnectionException("Cannot connect to {}".format(self.hostname))
napalm.base.exceptions.ConnectionException: Cannot connect to 10.5.48.62

2024-09-06 06:55:52,170 - nornir.core.task -    ERROR -      start() - Host 'BHP-A-3F-SW': task 'Creating Backup Archive' failed with traceback:
Traceback (most recent call last):
  File "/home/kali/.local/lib/python3.11/site-packages/nornir/core/task.py", line 99, in start
    r = self.task(self, **self.params)
        ^^^^^^^^^^^^^^^^^^^^^^^^^^^^^^
  File "/home/kali/Desktop/Nornir/2023/IITH/config_backup/backup.py", line 21, in backup_configurations
    r = task.run(task=napalm_get, getters=[g])
        ^^^^^^^^^^^^^^^^^^^^^^^^^^^^^^^^^^^^^^
  File "/home/kali/.local/lib/python3.11/site-packages/nornir/core/task.py", line 174, in run
    raise NornirSubTaskError(task=run_task, result=r)
nornir.core.exceptions.NornirSubTaskError: Subtask: napalm_get (failed)


2024-09-06 06:55:52,170 - nornir.core.task -    ERROR -      start() - Host 'BHP-A-9F-SW': task 'napalm_get' failed with traceback:
Traceback (most recent call last):
  File "/home/kali/.local/lib/python3.11/site-packages/netmiko/base_connection.py", line 1137, in establish_connection
    self.remote_conn_pre.connect(**ssh_connect_params)
  File "/usr/lib/python3/dist-packages/paramiko/client.py", line 358, in connect
    retry_on_signal(lambda: sock.connect(addr))
  File "/usr/lib/python3/dist-packages/paramiko/util.py", line 279, in retry_on_signal
    return function()
           ^^^^^^^^^^
  File "/usr/lib/python3/dist-packages/paramiko/client.py", line 358, in <lambda>
    retry_on_signal(lambda: sock.connect(addr))
                            ^^^^^^^^^^^^^^^^^^
TimeoutError: timed out

During handling of the above exception, another exception occurred:

Traceback (most recent call last):
  File "/home/kali/.local/lib/python3.11/site-packages/napalm/base/base.py", line 114, in _netmiko_open
    self._netmiko_device = ConnectHandler(
                           ^^^^^^^^^^^^^^^
  File "/home/kali/.local/lib/python3.11/site-packages/netmiko/ssh_dispatcher.py", line 399, in ConnectHandler
    return ConnectionClass(*args, **kwargs)
           ^^^^^^^^^^^^^^^^^^^^^^^^^^^^^^^^
  File "/home/kali/.local/lib/python3.11/site-packages/netmiko/base_connection.py", line 488, in __init__
    self._open()
  File "/home/kali/.local/lib/python3.11/site-packages/netmiko/base_connection.py", line 493, in _open
    self.establish_connection()
  File "/home/kali/.local/lib/python3.11/site-packages/netmiko/base_connection.py", line 1159, in establish_connection
    raise NetmikoTimeoutException(msg)
netmiko.exceptions.NetmikoTimeoutException: TCP connection to device failed.

Common causes of this problem are:
1. Incorrect hostname or IP address.
2. Wrong TCP port.
3. Intermediate firewall blocking access.

Device settings: cisco_ios 10.5.48.64:22



During handling of the above exception, another exception occurred:

Traceback (most recent call last):
  File "/home/kali/.local/lib/python3.11/site-packages/nornir/core/task.py", line 99, in start
    r = self.task(self, **self.params)
        ^^^^^^^^^^^^^^^^^^^^^^^^^^^^^^
  File "/home/kali/.local/lib/python3.11/site-packages/nornir_napalm/plugins/tasks/napalm_get.py", line 32, in napalm_get
    device = task.host.get_connection(CONNECTION_NAME, task.nornir.config)
             ^^^^^^^^^^^^^^^^^^^^^^^^^^^^^^^^^^^^^^^^^^^^^^^^^^^^^^^^^^^^^
  File "/home/kali/.local/lib/python3.11/site-packages/nornir/core/inventory.py", line 494, in get_connection
    self.open_connection(
  File "/home/kali/.local/lib/python3.11/site-packages/nornir/core/inventory.py", line 546, in open_connection
    conn_obj.open(
  File "/home/kali/.local/lib/python3.11/site-packages/nornir_napalm/plugins/connections/__init__.py", line 57, in open
    connection.open()
  File "/home/kali/.local/lib/python3.11/site-packages/napalm/ios/ios.py", line 173, in open
    self.device = self._netmiko_open(
                  ^^^^^^^^^^^^^^^^^^^
  File "/home/kali/.local/lib/python3.11/site-packages/napalm/base/base.py", line 123, in _netmiko_open
    raise ConnectionException("Cannot connect to {}".format(self.hostname))
napalm.base.exceptions.ConnectionException: Cannot connect to 10.5.48.64

2024-09-06 06:55:52,171 - nornir.core.task -    ERROR -      start() - Host 'BHP-A-9F-SW': task 'Creating Backup Archive' failed with traceback:
Traceback (most recent call last):
  File "/home/kali/.local/lib/python3.11/site-packages/nornir/core/task.py", line 99, in start
    r = self.task(self, **self.params)
        ^^^^^^^^^^^^^^^^^^^^^^^^^^^^^^
  File "/home/kali/Desktop/Nornir/2023/IITH/config_backup/backup.py", line 21, in backup_configurations
    r = task.run(task=napalm_get, getters=[g])
        ^^^^^^^^^^^^^^^^^^^^^^^^^^^^^^^^^^^^^^
  File "/home/kali/.local/lib/python3.11/site-packages/nornir/core/task.py", line 174, in run
    raise NornirSubTaskError(task=run_task, result=r)
nornir.core.exceptions.NornirSubTaskError: Subtask: napalm_get (failed)


2024-09-06 06:55:52,169 - nornir.core.task -    ERROR -      start() - Host 'BHP-A-6F-SW': task 'napalm_get' failed with traceback:
Traceback (most recent call last):
  File "/home/kali/.local/lib/python3.11/site-packages/netmiko/base_connection.py", line 1137, in establish_connection
    self.remote_conn_pre.connect(**ssh_connect_params)
  File "/usr/lib/python3/dist-packages/paramiko/client.py", line 358, in connect
    retry_on_signal(lambda: sock.connect(addr))
  File "/usr/lib/python3/dist-packages/paramiko/util.py", line 279, in retry_on_signal
    return function()
           ^^^^^^^^^^
  File "/usr/lib/python3/dist-packages/paramiko/client.py", line 358, in <lambda>
    retry_on_signal(lambda: sock.connect(addr))
                            ^^^^^^^^^^^^^^^^^^
TimeoutError: timed out

During handling of the above exception, another exception occurred:

Traceback (most recent call last):
  File "/home/kali/.local/lib/python3.11/site-packages/napalm/base/base.py", line 114, in _netmiko_open
    self._netmiko_device = ConnectHandler(
                           ^^^^^^^^^^^^^^^
  File "/home/kali/.local/lib/python3.11/site-packages/netmiko/ssh_dispatcher.py", line 399, in ConnectHandler
    return ConnectionClass(*args, **kwargs)
           ^^^^^^^^^^^^^^^^^^^^^^^^^^^^^^^^
  File "/home/kali/.local/lib/python3.11/site-packages/netmiko/base_connection.py", line 488, in __init__
    self._open()
  File "/home/kali/.local/lib/python3.11/site-packages/netmiko/base_connection.py", line 493, in _open
    self.establish_connection()
  File "/home/kali/.local/lib/python3.11/site-packages/netmiko/base_connection.py", line 1159, in establish_connection
    raise NetmikoTimeoutException(msg)
netmiko.exceptions.NetmikoTimeoutException: TCP connection to device failed.

Common causes of this problem are:
1. Incorrect hostname or IP address.
2. Wrong TCP port.
3. Intermediate firewall blocking access.

Device settings: cisco_ios 10.5.48.63:22



During handling of the above exception, another exception occurred:

Traceback (most recent call last):
  File "/home/kali/.local/lib/python3.11/site-packages/nornir/core/task.py", line 99, in start
    r = self.task(self, **self.params)
        ^^^^^^^^^^^^^^^^^^^^^^^^^^^^^^
  File "/home/kali/.local/lib/python3.11/site-packages/nornir_napalm/plugins/tasks/napalm_get.py", line 32, in napalm_get
    device = task.host.get_connection(CONNECTION_NAME, task.nornir.config)
             ^^^^^^^^^^^^^^^^^^^^^^^^^^^^^^^^^^^^^^^^^^^^^^^^^^^^^^^^^^^^^
  File "/home/kali/.local/lib/python3.11/site-packages/nornir/core/inventory.py", line 494, in get_connection
    self.open_connection(
  File "/home/kali/.local/lib/python3.11/site-packages/nornir/core/inventory.py", line 546, in open_connection
    conn_obj.open(
  File "/home/kali/.local/lib/python3.11/site-packages/nornir_napalm/plugins/connections/__init__.py", line 57, in open
    connection.open()
  File "/home/kali/.local/lib/python3.11/site-packages/napalm/ios/ios.py", line 173, in open
    self.device = self._netmiko_open(
                  ^^^^^^^^^^^^^^^^^^^
  File "/home/kali/.local/lib/python3.11/site-packages/napalm/base/base.py", line 123, in _netmiko_open
    raise ConnectionException("Cannot connect to {}".format(self.hostname))
napalm.base.exceptions.ConnectionException: Cannot connect to 10.5.48.63

2024-09-06 06:55:52,171 - nornir.core.task -    ERROR -      start() - Host 'BHP-A-6F-SW': task 'Creating Backup Archive' failed with traceback:
Traceback (most recent call last):
  File "/home/kali/.local/lib/python3.11/site-packages/nornir/core/task.py", line 99, in start
    r = self.task(self, **self.params)
        ^^^^^^^^^^^^^^^^^^^^^^^^^^^^^^
  File "/home/kali/Desktop/Nornir/2023/IITH/config_backup/backup.py", line 21, in backup_configurations
    r = task.run(task=napalm_get, getters=[g])
        ^^^^^^^^^^^^^^^^^^^^^^^^^^^^^^^^^^^^^^
  File "/home/kali/.local/lib/python3.11/site-packages/nornir/core/task.py", line 174, in run
    raise NornirSubTaskError(task=run_task, result=r)
nornir.core.exceptions.NornirSubTaskError: Subtask: napalm_get (failed)


