2024-08-14 05:27:04,325 -  nornir.core -     INFO -        run() - Running task 'nornir_napalm_cli_commands_example' with args {} on 1 hosts
2024-08-14 05:30:22,590 -  nornir.core -     INFO -        run() - Running task 'nornir_napalm_cli_commands_example' with args {} on 1 hosts
2024-08-14 06:08:05,649 -  nornir.core -     INFO -        run() - Running task 'napalm_cli' with args {'commands': ['show inventory', 'show license all | include Start Date', 'show license all | include End Date']} on 1 hosts
2024-08-14 06:09:00,507 -  nornir.core -     INFO -        run() - Running task 'nornir_napalm_cli_commands_example' with args {} on 1 hosts
2024-08-14 06:11:47,319 -  nornir.core -     INFO -        run() - Running task 'nornir_napalm_cli_commands_example' with args {} on 1 hosts
2024-08-14 06:15:01,846 -  nornir.core -     INFO -        run() - Running task 'nornir_napalm_cli_commands_example' with args {} on 1 hosts
2024-08-14 06:25:39,807 -  nornir.core -     INFO -        run() - Running task 'nornir_napalm_cli_commands_example' with args {} on 1 hosts
2024-08-14 06:26:05,940 -  nornir.core -     INFO -        run() - Running task 'nornir_napalm_cli_commands_example' with args {} on 1 hosts
2024-08-22 02:47:29,159 -  nornir.core -     INFO -        run() - Running task 'nornir_napalm_cli_commands_example' with args {} on 1 hosts
2024-08-22 05:46:47,144 -  nornir.core -     INFO -        run() - Running task 'nornir_napalm_cli_commands_example' with args {} on 1 hosts
2024-08-27 06:38:31,765 -  nornir.core -     INFO -        run() - Running task 'nornir_napalm_cli_commands_example' with args {} on 212 hosts
2024-08-27 06:38:43,180 - nornir.core.task -    ERROR -      start() - Host 'MSME-1F-SW': task 'napalm_cli' failed with traceback:
Traceback (most recent call last):
  File "/home/kali/.local/lib/python3.11/site-packages/nornir/core/task.py", line 99, in start
    r = self.task(self, **self.params)
        ^^^^^^^^^^^^^^^^^^^^^^^^^^^^^^
  File "/home/kali/.local/lib/python3.11/site-packages/nornir_napalm/plugins/tasks/napalm_cli.py", line 19, in napalm_cli
    device = task.host.get_connection(CONNECTION_NAME, task.nornir.config)
             ^^^^^^^^^^^^^^^^^^^^^^^^^^^^^^^^^^^^^^^^^^^^^^^^^^^^^^^^^^^^^
  File "/home/kali/.local/lib/python3.11/site-packages/nornir/core/inventory.py", line 494, in get_connection
    self.open_connection(
  File "/home/kali/.local/lib/python3.11/site-packages/nornir/core/inventory.py", line 546, in open_connection
    conn_obj.open(
  File "/home/kali/.local/lib/python3.11/site-packages/nornir_napalm/plugins/connections/__init__.py", line 57, in open
    connection.open()
  File "/home/kali/.local/lib/python3.11/site-packages/napalm/ios/ios.py", line 173, in open
    self.device = self._netmiko_open(
                  ^^^^^^^^^^^^^^^^^^^
  File "/home/kali/.local/lib/python3.11/site-packages/napalm/base/base.py", line 129, in _netmiko_open
    self._netmiko_device.enable()
  File "/home/kali/.local/lib/python3.11/site-packages/netmiko/cisco_base_connection.py", line 26, in enable
    return super().enable(
           ^^^^^^^^^^^^^^^
  File "/home/kali/.local/lib/python3.11/site-packages/netmiko/base_connection.py", line 2049, in enable
    raise ValueError(msg)
ValueError: Failed to enter enable mode. Please ensure you pass the 'secret' argument to ConnectHandler.

2024-08-27 06:38:43,181 - nornir.core.task -    ERROR -      start() - Host 'MSME-1F-SW': task 'nornir_napalm_cli_commands_example' failed with traceback:
Traceback (most recent call last):
  File "/home/kali/.local/lib/python3.11/site-packages/nornir/core/task.py", line 99, in start
    r = self.task(self, **self.params)
        ^^^^^^^^^^^^^^^^^^^^^^^^^^^^^^
  File "/home/kali/Desktop/Nornir/2023/IITH/Inventory/cli_complete_inventory_nornir_napalm.py", line 13, in nornir_napalm_cli_commands_example
    task.run(task=napalm_cli, commands=[command])
  File "/home/kali/.local/lib/python3.11/site-packages/nornir/core/task.py", line 174, in run
    raise NornirSubTaskError(task=run_task, result=r)
nornir.core.exceptions.NornirSubTaskError: Subtask: napalm_cli (failed)


2024-08-27 06:40:17,279 -  nornir.core -     INFO -        run() - Running task 'nornir_napalm_cli_commands_example' with args {} on 212 hosts
2024-08-27 06:40:28,594 - nornir.core.task -    ERROR -      start() - Host 'MSME-1F-SW': task 'napalm_cli' failed with traceback:
Traceback (most recent call last):
  File "/home/kali/.local/lib/python3.11/site-packages/nornir/core/task.py", line 99, in start
    r = self.task(self, **self.params)
        ^^^^^^^^^^^^^^^^^^^^^^^^^^^^^^
  File "/home/kali/.local/lib/python3.11/site-packages/nornir_napalm/plugins/tasks/napalm_cli.py", line 19, in napalm_cli
    device = task.host.get_connection(CONNECTION_NAME, task.nornir.config)
             ^^^^^^^^^^^^^^^^^^^^^^^^^^^^^^^^^^^^^^^^^^^^^^^^^^^^^^^^^^^^^
  File "/home/kali/.local/lib/python3.11/site-packages/nornir/core/inventory.py", line 494, in get_connection
    self.open_connection(
  File "/home/kali/.local/lib/python3.11/site-packages/nornir/core/inventory.py", line 546, in open_connection
    conn_obj.open(
  File "/home/kali/.local/lib/python3.11/site-packages/nornir_napalm/plugins/connections/__init__.py", line 57, in open
    connection.open()
  File "/home/kali/.local/lib/python3.11/site-packages/napalm/ios/ios.py", line 173, in open
    self.device = self._netmiko_open(
                  ^^^^^^^^^^^^^^^^^^^
  File "/home/kali/.local/lib/python3.11/site-packages/napalm/base/base.py", line 129, in _netmiko_open
    self._netmiko_device.enable()
  File "/home/kali/.local/lib/python3.11/site-packages/netmiko/cisco_base_connection.py", line 26, in enable
    return super().enable(
           ^^^^^^^^^^^^^^^
  File "/home/kali/.local/lib/python3.11/site-packages/netmiko/base_connection.py", line 2049, in enable
    raise ValueError(msg)
ValueError: Failed to enter enable mode. Please ensure you pass the 'secret' argument to ConnectHandler.

2024-08-27 06:40:28,597 - nornir.core.task -    ERROR -      start() - Host 'MSME-1F-SW': task 'nornir_napalm_cli_commands_example' failed with traceback:
Traceback (most recent call last):
  File "/home/kali/.local/lib/python3.11/site-packages/nornir/core/task.py", line 99, in start
    r = self.task(self, **self.params)
        ^^^^^^^^^^^^^^^^^^^^^^^^^^^^^^
  File "/home/kali/Desktop/Nornir/2023/IITH/Inventory/cli_complete_inventory_nornir_napalm.py", line 13, in nornir_napalm_cli_commands_example
    task.run(task=napalm_cli, commands=[command])
  File "/home/kali/.local/lib/python3.11/site-packages/nornir/core/task.py", line 174, in run
    raise NornirSubTaskError(task=run_task, result=r)
nornir.core.exceptions.NornirSubTaskError: Subtask: napalm_cli (failed)


2024-08-27 06:40:39,610 -  nornir.core -     INFO -        run() - Running task 'nornir_napalm_cli_commands_example' with args {} on 211 hosts
2024-08-27 06:44:58,941 -  nornir.core -     INFO -        run() - Running task 'nornir_napalm_cli_commands_example' with args {} on 211 hosts
2024-08-29 01:07:42,132 -  nornir.core -     INFO -        run() - Running task 'nornir_napalm_cli_commands_example' with args {} on 1 hosts
2024-08-29 01:08:58,973 -  nornir.core -     INFO -        run() - Running task 'nornir_napalm_cli_commands_example' with args {} on 1 hosts
2024-08-29 01:14:43,254 -  nornir.core -     INFO -        run() - Running task 'nornir_napalm_cli_commands_example' with args {} on 212 hosts
