2024-08-14 05:27:04,325 -  nornir.core -     INFO -        run() - Running task 'nornir_napalm_cli_commands_example' with args {} on 1 hosts
2024-08-14 05:30:22,590 -  nornir.core -     INFO -        run() - Running task 'nornir_napalm_cli_commands_example' with args {} on 1 hosts
2024-08-14 06:08:05,649 -  nornir.core -     INFO -        run() - Running task 'napalm_cli' with args {'commands': ['show inventory', 'show license all | include Start Date', 'show license all | include End Date']} on 1 hosts
2024-08-14 06:09:00,507 -  nornir.core -     INFO -        run() - Running task 'nornir_napalm_cli_commands_example' with args {} on 1 hosts
2024-08-14 06:11:47,319 -  nornir.core -     INFO -        run() - Running task 'nornir_napalm_cli_commands_example' with args {} on 1 hosts
2024-08-14 06:15:01,846 -  nornir.core -     INFO -        run() - Running task 'nornir_napalm_cli_commands_example' with args {} on 1 hosts
2024-08-14 06:25:39,807 -  nornir.core -     INFO -        run() - Running task 'nornir_napalm_cli_commands_example' with args {} on 1 hosts
2024-08-14 06:26:05,940 -  nornir.core -     INFO -        run() - Running task 'nornir_napalm_cli_commands_example' with args {} on 1 hosts
2024-08-22 02:47:29,159 -  nornir.core -     INFO -        run() - Running task 'nornir_napalm_cli_commands_example' with args {} on 1 hosts
2024-08-22 05:46:47,144 -  nornir.core -     INFO -        run() - Running task 'nornir_napalm_cli_commands_example' with args {} on 1 hosts
2024-08-27 06:38:31,765 -  nornir.core -     INFO -        run() - Running task 'nornir_napalm_cli_commands_example' with args {} on 212 hosts
2024-08-27 06:38:43,180 - nornir.core.task -    ERROR -      start() - Host 'MSME-1F-SW': task 'napalm_cli' failed with traceback:
Traceback (most recent call last):
  File "/home/kali/.local/lib/python3.11/site-packages/nornir/core/task.py", line 99, in start
    r = self.task(self, **self.params)
        ^^^^^^^^^^^^^^^^^^^^^^^^^^^^^^
  File "/home/kali/.local/lib/python3.11/site-packages/nornir_napalm/plugins/tasks/napalm_cli.py", line 19, in napalm_cli
    device = task.host.get_connection(CONNECTION_NAME, task.nornir.config)
             ^^^^^^^^^^^^^^^^^^^^^^^^^^^^^^^^^^^^^^^^^^^^^^^^^^^^^^^^^^^^^
  File "/home/kali/.local/lib/python3.11/site-packages/nornir/core/inventory.py", line 494, in get_connection
    self.open_connection(
  File "/home/kali/.local/lib/python3.11/site-packages/nornir/core/inventory.py", line 546, in open_connection
    conn_obj.open(
  File "/home/kali/.local/lib/python3.11/site-packages/nornir_napalm/plugins/connections/__init__.py", line 57, in open
    connection.open()
  File "/home/kali/.local/lib/python3.11/site-packages/napalm/ios/ios.py", line 173, in open
    self.device = self._netmiko_open(
                  ^^^^^^^^^^^^^^^^^^^
  File "/home/kali/.local/lib/python3.11/site-packages/napalm/base/base.py", line 129, in _netmiko_open
    self._netmiko_device.enable()
  File "/home/kali/.local/lib/python3.11/site-packages/netmiko/cisco_base_connection.py", line 26, in enable
    return super().enable(
           ^^^^^^^^^^^^^^^
  File "/home/kali/.local/lib/python3.11/site-packages/netmiko/base_connection.py", line 2049, in enable
    raise ValueError(msg)
ValueError: Failed to enter enable mode. Please ensure you pass the 'secret' argument to ConnectHandler.

2024-08-27 06:38:43,181 - nornir.core.task -    ERROR -      start() - Host 'MSME-1F-SW': task 'nornir_napalm_cli_commands_example' failed with traceback:
Traceback (most recent call last):
  File "/home/kali/.local/lib/python3.11/site-packages/nornir/core/task.py", line 99, in start
    r = self.task(self, **self.params)
        ^^^^^^^^^^^^^^^^^^^^^^^^^^^^^^
  File "/home/kali/Desktop/Nornir/2023/IITH/Inventory/cli_complete_inventory_nornir_napalm.py", line 13, in nornir_napalm_cli_commands_example
    task.run(task=napalm_cli, commands=[command])
  File "/home/kali/.local/lib/python3.11/site-packages/nornir/core/task.py", line 174, in run
    raise NornirSubTaskError(task=run_task, result=r)
nornir.core.exceptions.NornirSubTaskError: Subtask: napalm_cli (failed)


2024-08-27 06:40:17,279 -  nornir.core -     INFO -        run() - Running task 'nornir_napalm_cli_commands_example' with args {} on 212 hosts
2024-08-27 06:40:28,594 - nornir.core.task -    ERROR -      start() - Host 'MSME-1F-SW': task 'napalm_cli' failed with traceback:
Traceback (most recent call last):
  File "/home/kali/.local/lib/python3.11/site-packages/nornir/core/task.py", line 99, in start
    r = self.task(self, **self.params)
        ^^^^^^^^^^^^^^^^^^^^^^^^^^^^^^
  File "/home/kali/.local/lib/python3.11/site-packages/nornir_napalm/plugins/tasks/napalm_cli.py", line 19, in napalm_cli
    device = task.host.get_connection(CONNECTION_NAME, task.nornir.config)
             ^^^^^^^^^^^^^^^^^^^^^^^^^^^^^^^^^^^^^^^^^^^^^^^^^^^^^^^^^^^^^
  File "/home/kali/.local/lib/python3.11/site-packages/nornir/core/inventory.py", line 494, in get_connection
    self.open_connection(
  File "/home/kali/.local/lib/python3.11/site-packages/nornir/core/inventory.py", line 546, in open_connection
    conn_obj.open(
  File "/home/kali/.local/lib/python3.11/site-packages/nornir_napalm/plugins/connections/__init__.py", line 57, in open
    connection.open()
  File "/home/kali/.local/lib/python3.11/site-packages/napalm/ios/ios.py", line 173, in open
    self.device = self._netmiko_open(
                  ^^^^^^^^^^^^^^^^^^^
  File "/home/kali/.local/lib/python3.11/site-packages/napalm/base/base.py", line 129, in _netmiko_open
    self._netmiko_device.enable()
  File "/home/kali/.local/lib/python3.11/site-packages/netmiko/cisco_base_connection.py", line 26, in enable
    return super().enable(
           ^^^^^^^^^^^^^^^
  File "/home/kali/.local/lib/python3.11/site-packages/netmiko/base_connection.py", line 2049, in enable
    raise ValueError(msg)
ValueError: Failed to enter enable mode. Please ensure you pass the 'secret' argument to ConnectHandler.

2024-08-27 06:40:28,597 - nornir.core.task -    ERROR -      start() - Host 'MSME-1F-SW': task 'nornir_napalm_cli_commands_example' failed with traceback:
Traceback (most recent call last):
  File "/home/kali/.local/lib/python3.11/site-packages/nornir/core/task.py", line 99, in start
    r = self.task(self, **self.params)
        ^^^^^^^^^^^^^^^^^^^^^^^^^^^^^^
  File "/home/kali/Desktop/Nornir/2023/IITH/Inventory/cli_complete_inventory_nornir_napalm.py", line 13, in nornir_napalm_cli_commands_example
    task.run(task=napalm_cli, commands=[command])
  File "/home/kali/.local/lib/python3.11/site-packages/nornir/core/task.py", line 174, in run
    raise NornirSubTaskError(task=run_task, result=r)
nornir.core.exceptions.NornirSubTaskError: Subtask: napalm_cli (failed)


2024-08-27 06:40:39,610 -  nornir.core -     INFO -        run() - Running task 'nornir_napalm_cli_commands_example' with args {} on 211 hosts
2024-08-27 06:44:58,941 -  nornir.core -     INFO -        run() - Running task 'nornir_napalm_cli_commands_example' with args {} on 211 hosts
2024-08-29 01:07:42,132 -  nornir.core -     INFO -        run() - Running task 'nornir_napalm_cli_commands_example' with args {} on 1 hosts
2024-08-29 01:08:58,973 -  nornir.core -     INFO -        run() - Running task 'nornir_napalm_cli_commands_example' with args {} on 1 hosts
2024-08-29 01:14:43,254 -  nornir.core -     INFO -        run() - Running task 'nornir_napalm_cli_commands_example' with args {} on 212 hosts
2024-10-03 10:13:40,161 -  nornir.core -     INFO -        run() - Running task 'nornir_napalm_cli_commands_example' with args {} on 212 hosts
2024-10-03 10:24:42,913 -  nornir.core -     INFO -        run() - Running task 'nornir_napalm_cli_commands_example' with args {} on 212 hosts
2024-12-23 14:25:20,224 -  nornir.core -     INFO -        run() - Running task 'nornir_napalm_cli_commands_example' with args {} on 212 hosts
2024-12-23 14:25:34,119 - nornir.core.task -    ERROR -      start() - Host 'Hospital-1F': task 'napalm_cli' failed with traceback:
Traceback (most recent call last):
  File "/home/kali/.local/lib/python3.11/site-packages/netmiko/base_connection.py", line 1137, in establish_connection
    self.remote_conn_pre.connect(**ssh_connect_params)
  File "/usr/lib/python3/dist-packages/paramiko/client.py", line 450, in connect
    self._auth(
  File "/usr/lib/python3/dist-packages/paramiko/client.py", line 781, in _auth
    raise saved_exception
  File "/usr/lib/python3/dist-packages/paramiko/client.py", line 768, in _auth
    self._transport.auth_password(username, password)
  File "/usr/lib/python3/dist-packages/paramiko/transport.py", line 1564, in auth_password
    return self.auth_handler.wait_for_response(my_event)
           ^^^^^^^^^^^^^^^^^^^^^^^^^^^^^^^^^^^^^^^^^^^^^
  File "/usr/lib/python3/dist-packages/paramiko/auth_handler.py", line 259, in wait_for_response
    raise e
paramiko.ssh_exception.AuthenticationException: Authentication failed.

During handling of the above exception, another exception occurred:

Traceback (most recent call last):
  File "/home/kali/.local/lib/python3.11/site-packages/nornir/core/task.py", line 99, in start
    r = self.task(self, **self.params)
        ^^^^^^^^^^^^^^^^^^^^^^^^^^^^^^
  File "/home/kali/.local/lib/python3.11/site-packages/nornir_napalm/plugins/tasks/napalm_cli.py", line 19, in napalm_cli
    device = task.host.get_connection(CONNECTION_NAME, task.nornir.config)
             ^^^^^^^^^^^^^^^^^^^^^^^^^^^^^^^^^^^^^^^^^^^^^^^^^^^^^^^^^^^^^
  File "/home/kali/.local/lib/python3.11/site-packages/nornir/core/inventory.py", line 494, in get_connection
    self.open_connection(
  File "/home/kali/.local/lib/python3.11/site-packages/nornir/core/inventory.py", line 546, in open_connection
    conn_obj.open(
  File "/home/kali/.local/lib/python3.11/site-packages/nornir_napalm/plugins/connections/__init__.py", line 57, in open
    connection.open()
  File "/home/kali/.local/lib/python3.11/site-packages/napalm/ios/ios.py", line 173, in open
    self.device = self._netmiko_open(
                  ^^^^^^^^^^^^^^^^^^^
  File "/home/kali/.local/lib/python3.11/site-packages/napalm/base/base.py", line 114, in _netmiko_open
    self._netmiko_device = ConnectHandler(
                           ^^^^^^^^^^^^^^^
  File "/home/kali/.local/lib/python3.11/site-packages/netmiko/ssh_dispatcher.py", line 399, in ConnectHandler
    return ConnectionClass(*args, **kwargs)
           ^^^^^^^^^^^^^^^^^^^^^^^^^^^^^^^^
  File "/home/kali/.local/lib/python3.11/site-packages/netmiko/base_connection.py", line 488, in __init__
    self._open()
  File "/home/kali/.local/lib/python3.11/site-packages/netmiko/base_connection.py", line 493, in _open
    self.establish_connection()
  File "/home/kali/.local/lib/python3.11/site-packages/netmiko/base_connection.py", line 1174, in establish_connection
    raise NetmikoAuthenticationException(msg)
netmiko.exceptions.NetmikoAuthenticationException: Authentication to device failed.

Common causes of this problem are:
1. Invalid username and password
2. Incorrect SSH-key file
3. Connecting to the wrong device

Device settings: cisco_ios 192.168.9.140:22


Authentication failed.

2024-12-23 14:25:34,119 - nornir.core.task -    ERROR -      start() - Host 'Hospital-1F': task 'nornir_napalm_cli_commands_example' failed with traceback:
Traceback (most recent call last):
  File "/home/kali/.local/lib/python3.11/site-packages/nornir/core/task.py", line 99, in start
    r = self.task(self, **self.params)
        ^^^^^^^^^^^^^^^^^^^^^^^^^^^^^^
  File "/home/kali/Desktop/Nornir/2023/IITH/Cisco Ph2/Inventory/cli_short_inv_withDates.py", line 14, in nornir_napalm_cli_commands_example
    task.run(task=napalm_cli, commands=[command, command1, command2])
  File "/home/kali/.local/lib/python3.11/site-packages/nornir/core/task.py", line 174, in run
    raise NornirSubTaskError(task=run_task, result=r)
nornir.core.exceptions.NornirSubTaskError: Subtask: napalm_cli (failed)


2024-12-23 14:25:45,014 - nornir.core.task -    ERROR -      start() - Host 'LH-Dist-SW': task 'napalm_cli' failed with traceback:
Traceback (most recent call last):
  File "/home/kali/.local/lib/python3.11/site-packages/netmiko/base_connection.py", line 1137, in establish_connection
    self.remote_conn_pre.connect(**ssh_connect_params)
  File "/usr/lib/python3/dist-packages/paramiko/client.py", line 358, in connect
    retry_on_signal(lambda: sock.connect(addr))
  File "/usr/lib/python3/dist-packages/paramiko/util.py", line 279, in retry_on_signal
    return function()
           ^^^^^^^^^^
  File "/usr/lib/python3/dist-packages/paramiko/client.py", line 358, in <lambda>
    retry_on_signal(lambda: sock.connect(addr))
                            ^^^^^^^^^^^^^^^^^^
TimeoutError: timed out

During handling of the above exception, another exception occurred:

Traceback (most recent call last):
  File "/home/kali/.local/lib/python3.11/site-packages/napalm/base/base.py", line 114, in _netmiko_open
    self._netmiko_device = ConnectHandler(
                           ^^^^^^^^^^^^^^^
  File "/home/kali/.local/lib/python3.11/site-packages/netmiko/ssh_dispatcher.py", line 399, in ConnectHandler
    return ConnectionClass(*args, **kwargs)
           ^^^^^^^^^^^^^^^^^^^^^^^^^^^^^^^^
  File "/home/kali/.local/lib/python3.11/site-packages/netmiko/base_connection.py", line 488, in __init__
    self._open()
  File "/home/kali/.local/lib/python3.11/site-packages/netmiko/base_connection.py", line 493, in _open
    self.establish_connection()
  File "/home/kali/.local/lib/python3.11/site-packages/netmiko/base_connection.py", line 1159, in establish_connection
    raise NetmikoTimeoutException(msg)
netmiko.exceptions.NetmikoTimeoutException: TCP connection to device failed.

Common causes of this problem are:
1. Incorrect hostname or IP address.
2. Wrong TCP port.
3. Intermediate firewall blocking access.

Device settings: cisco_ios 192.168.41.130:22



During handling of the above exception, another exception occurred:

Traceback (most recent call last):
  File "/home/kali/.local/lib/python3.11/site-packages/nornir/core/task.py", line 99, in start
    r = self.task(self, **self.params)
        ^^^^^^^^^^^^^^^^^^^^^^^^^^^^^^
  File "/home/kali/.local/lib/python3.11/site-packages/nornir_napalm/plugins/tasks/napalm_cli.py", line 19, in napalm_cli
    device = task.host.get_connection(CONNECTION_NAME, task.nornir.config)
             ^^^^^^^^^^^^^^^^^^^^^^^^^^^^^^^^^^^^^^^^^^^^^^^^^^^^^^^^^^^^^
  File "/home/kali/.local/lib/python3.11/site-packages/nornir/core/inventory.py", line 494, in get_connection
    self.open_connection(
  File "/home/kali/.local/lib/python3.11/site-packages/nornir/core/inventory.py", line 546, in open_connection
    conn_obj.open(
  File "/home/kali/.local/lib/python3.11/site-packages/nornir_napalm/plugins/connections/__init__.py", line 57, in open
    connection.open()
  File "/home/kali/.local/lib/python3.11/site-packages/napalm/ios/ios.py", line 173, in open
    self.device = self._netmiko_open(
                  ^^^^^^^^^^^^^^^^^^^
  File "/home/kali/.local/lib/python3.11/site-packages/napalm/base/base.py", line 123, in _netmiko_open
    raise ConnectionException("Cannot connect to {}".format(self.hostname))
napalm.base.exceptions.ConnectionException: Cannot connect to 192.168.41.130

2024-12-23 14:25:45,016 - nornir.core.task -    ERROR -      start() - Host 'LH-Dist-SW': task 'nornir_napalm_cli_commands_example' failed with traceback:
Traceback (most recent call last):
  File "/home/kali/.local/lib/python3.11/site-packages/nornir/core/task.py", line 99, in start
    r = self.task(self, **self.params)
        ^^^^^^^^^^^^^^^^^^^^^^^^^^^^^^
  File "/home/kali/Desktop/Nornir/2023/IITH/Cisco Ph2/Inventory/cli_short_inv_withDates.py", line 14, in nornir_napalm_cli_commands_example
    task.run(task=napalm_cli, commands=[command, command1, command2])
  File "/home/kali/.local/lib/python3.11/site-packages/nornir/core/task.py", line 174, in run
    raise NornirSubTaskError(task=run_task, result=r)
nornir.core.exceptions.NornirSubTaskError: Subtask: napalm_cli (failed)


2024-12-23 14:25:45,143 - nornir.core.task -    ERROR -      start() - Host 'LH-Part 1-LGF': task 'napalm_cli' failed with traceback:
Traceback (most recent call last):
  File "/home/kali/.local/lib/python3.11/site-packages/netmiko/base_connection.py", line 1137, in establish_connection
    self.remote_conn_pre.connect(**ssh_connect_params)
  File "/usr/lib/python3/dist-packages/paramiko/client.py", line 358, in connect
    retry_on_signal(lambda: sock.connect(addr))
  File "/usr/lib/python3/dist-packages/paramiko/util.py", line 279, in retry_on_signal
    return function()
           ^^^^^^^^^^
  File "/usr/lib/python3/dist-packages/paramiko/client.py", line 358, in <lambda>
    retry_on_signal(lambda: sock.connect(addr))
                            ^^^^^^^^^^^^^^^^^^
TimeoutError: timed out

During handling of the above exception, another exception occurred:

Traceback (most recent call last):
  File "/home/kali/.local/lib/python3.11/site-packages/napalm/base/base.py", line 114, in _netmiko_open
    self._netmiko_device = ConnectHandler(
                           ^^^^^^^^^^^^^^^
  File "/home/kali/.local/lib/python3.11/site-packages/netmiko/ssh_dispatcher.py", line 399, in ConnectHandler
    return ConnectionClass(*args, **kwargs)
           ^^^^^^^^^^^^^^^^^^^^^^^^^^^^^^^^
  File "/home/kali/.local/lib/python3.11/site-packages/netmiko/base_connection.py", line 488, in __init__
    self._open()
  File "/home/kali/.local/lib/python3.11/site-packages/netmiko/base_connection.py", line 493, in _open
    self.establish_connection()
  File "/home/kali/.local/lib/python3.11/site-packages/netmiko/base_connection.py", line 1159, in establish_connection
    raise NetmikoTimeoutException(msg)
netmiko.exceptions.NetmikoTimeoutException: TCP connection to device failed.

Common causes of this problem are:
1. Incorrect hostname or IP address.
2. Wrong TCP port.
3. Intermediate firewall blocking access.

Device settings: cisco_ios 10.5.108.101:22



During handling of the above exception, another exception occurred:

Traceback (most recent call last):
  File "/home/kali/.local/lib/python3.11/site-packages/nornir/core/task.py", line 99, in start
    r = self.task(self, **self.params)
        ^^^^^^^^^^^^^^^^^^^^^^^^^^^^^^
  File "/home/kali/.local/lib/python3.11/site-packages/nornir_napalm/plugins/tasks/napalm_cli.py", line 19, in napalm_cli
    device = task.host.get_connection(CONNECTION_NAME, task.nornir.config)
             ^^^^^^^^^^^^^^^^^^^^^^^^^^^^^^^^^^^^^^^^^^^^^^^^^^^^^^^^^^^^^
  File "/home/kali/.local/lib/python3.11/site-packages/nornir/core/inventory.py", line 494, in get_connection
    self.open_connection(
  File "/home/kali/.local/lib/python3.11/site-packages/nornir/core/inventory.py", line 546, in open_connection
    conn_obj.open(
  File "/home/kali/.local/lib/python3.11/site-packages/nornir_napalm/plugins/connections/__init__.py", line 57, in open
    connection.open()
  File "/home/kali/.local/lib/python3.11/site-packages/napalm/ios/ios.py", line 173, in open
    self.device = self._netmiko_open(
                  ^^^^^^^^^^^^^^^^^^^
  File "/home/kali/.local/lib/python3.11/site-packages/napalm/base/base.py", line 123, in _netmiko_open
    raise ConnectionException("Cannot connect to {}".format(self.hostname))
napalm.base.exceptions.ConnectionException: Cannot connect to 10.5.108.101

2024-12-23 14:25:45,144 - nornir.core.task -    ERROR -      start() - Host 'LH-Part 1-LGF': task 'nornir_napalm_cli_commands_example' failed with traceback:
Traceback (most recent call last):
  File "/home/kali/.local/lib/python3.11/site-packages/nornir/core/task.py", line 99, in start
    r = self.task(self, **self.params)
        ^^^^^^^^^^^^^^^^^^^^^^^^^^^^^^
  File "/home/kali/Desktop/Nornir/2023/IITH/Cisco Ph2/Inventory/cli_short_inv_withDates.py", line 14, in nornir_napalm_cli_commands_example
    task.run(task=napalm_cli, commands=[command, command1, command2])
  File "/home/kali/.local/lib/python3.11/site-packages/nornir/core/task.py", line 174, in run
    raise NornirSubTaskError(task=run_task, result=r)
nornir.core.exceptions.NornirSubTaskError: Subtask: napalm_cli (failed)


2024-12-23 14:25:45,180 - nornir.core.task -    ERROR -      start() - Host 'LH-Part 1-UGF': task 'napalm_cli' failed with traceback:
Traceback (most recent call last):
  File "/home/kali/.local/lib/python3.11/site-packages/netmiko/base_connection.py", line 1137, in establish_connection
    self.remote_conn_pre.connect(**ssh_connect_params)
  File "/usr/lib/python3/dist-packages/paramiko/client.py", line 358, in connect
    retry_on_signal(lambda: sock.connect(addr))
  File "/usr/lib/python3/dist-packages/paramiko/util.py", line 279, in retry_on_signal
    return function()
           ^^^^^^^^^^
  File "/usr/lib/python3/dist-packages/paramiko/client.py", line 358, in <lambda>
    retry_on_signal(lambda: sock.connect(addr))
                            ^^^^^^^^^^^^^^^^^^
TimeoutError: timed out

During handling of the above exception, another exception occurred:

Traceback (most recent call last):
  File "/home/kali/.local/lib/python3.11/site-packages/napalm/base/base.py", line 114, in _netmiko_open
    self._netmiko_device = ConnectHandler(
                           ^^^^^^^^^^^^^^^
  File "/home/kali/.local/lib/python3.11/site-packages/netmiko/ssh_dispatcher.py", line 399, in ConnectHandler
    return ConnectionClass(*args, **kwargs)
           ^^^^^^^^^^^^^^^^^^^^^^^^^^^^^^^^
  File "/home/kali/.local/lib/python3.11/site-packages/netmiko/base_connection.py", line 488, in __init__
    self._open()
  File "/home/kali/.local/lib/python3.11/site-packages/netmiko/base_connection.py", line 493, in _open
    self.establish_connection()
  File "/home/kali/.local/lib/python3.11/site-packages/netmiko/base_connection.py", line 1159, in establish_connection
    raise NetmikoTimeoutException(msg)
netmiko.exceptions.NetmikoTimeoutException: TCP connection to device failed.

Common causes of this problem are:
1. Incorrect hostname or IP address.
2. Wrong TCP port.
3. Intermediate firewall blocking access.

Device settings: cisco_ios 10.5.108.102:22



During handling of the above exception, another exception occurred:

Traceback (most recent call last):
  File "/home/kali/.local/lib/python3.11/site-packages/nornir/core/task.py", line 99, in start
    r = self.task(self, **self.params)
        ^^^^^^^^^^^^^^^^^^^^^^^^^^^^^^
  File "/home/kali/.local/lib/python3.11/site-packages/nornir_napalm/plugins/tasks/napalm_cli.py", line 19, in napalm_cli
    device = task.host.get_connection(CONNECTION_NAME, task.nornir.config)
             ^^^^^^^^^^^^^^^^^^^^^^^^^^^^^^^^^^^^^^^^^^^^^^^^^^^^^^^^^^^^^
  File "/home/kali/.local/lib/python3.11/site-packages/nornir/core/inventory.py", line 494, in get_connection
    self.open_connection(
  File "/home/kali/.local/lib/python3.11/site-packages/nornir/core/inventory.py", line 546, in open_connection
    conn_obj.open(
  File "/home/kali/.local/lib/python3.11/site-packages/nornir_napalm/plugins/connections/__init__.py", line 57, in open
    connection.open()
  File "/home/kali/.local/lib/python3.11/site-packages/napalm/ios/ios.py", line 173, in open
    self.device = self._netmiko_open(
                  ^^^^^^^^^^^^^^^^^^^
  File "/home/kali/.local/lib/python3.11/site-packages/napalm/base/base.py", line 123, in _netmiko_open
    raise ConnectionException("Cannot connect to {}".format(self.hostname))
napalm.base.exceptions.ConnectionException: Cannot connect to 10.5.108.102

2024-12-23 14:25:45,180 - nornir.core.task -    ERROR -      start() - Host 'LH-Part 1-UGF': task 'nornir_napalm_cli_commands_example' failed with traceback:
Traceback (most recent call last):
  File "/home/kali/.local/lib/python3.11/site-packages/nornir/core/task.py", line 99, in start
    r = self.task(self, **self.params)
        ^^^^^^^^^^^^^^^^^^^^^^^^^^^^^^
  File "/home/kali/Desktop/Nornir/2023/IITH/Cisco Ph2/Inventory/cli_short_inv_withDates.py", line 14, in nornir_napalm_cli_commands_example
    task.run(task=napalm_cli, commands=[command, command1, command2])
  File "/home/kali/.local/lib/python3.11/site-packages/nornir/core/task.py", line 174, in run
    raise NornirSubTaskError(task=run_task, result=r)
nornir.core.exceptions.NornirSubTaskError: Subtask: napalm_cli (failed)


2024-12-23 14:25:45,818 - nornir.core.task -    ERROR -      start() - Host 'LH-Part 3-UGF': task 'napalm_cli' failed with traceback:
Traceback (most recent call last):
  File "/home/kali/.local/lib/python3.11/site-packages/netmiko/base_connection.py", line 1137, in establish_connection
    self.remote_conn_pre.connect(**ssh_connect_params)
  File "/usr/lib/python3/dist-packages/paramiko/client.py", line 358, in connect
    retry_on_signal(lambda: sock.connect(addr))
  File "/usr/lib/python3/dist-packages/paramiko/util.py", line 279, in retry_on_signal
    return function()
           ^^^^^^^^^^
  File "/usr/lib/python3/dist-packages/paramiko/client.py", line 358, in <lambda>
    retry_on_signal(lambda: sock.connect(addr))
                            ^^^^^^^^^^^^^^^^^^
TimeoutError: timed out

During handling of the above exception, another exception occurred:

Traceback (most recent call last):
  File "/home/kali/.local/lib/python3.11/site-packages/napalm/base/base.py", line 114, in _netmiko_open
    self._netmiko_device = ConnectHandler(
                           ^^^^^^^^^^^^^^^
  File "/home/kali/.local/lib/python3.11/site-packages/netmiko/ssh_dispatcher.py", line 399, in ConnectHandler
    return ConnectionClass(*args, **kwargs)
           ^^^^^^^^^^^^^^^^^^^^^^^^^^^^^^^^
  File "/home/kali/.local/lib/python3.11/site-packages/netmiko/base_connection.py", line 488, in __init__
    self._open()
  File "/home/kali/.local/lib/python3.11/site-packages/netmiko/base_connection.py", line 493, in _open
    self.establish_connection()
  File "/home/kali/.local/lib/python3.11/site-packages/netmiko/base_connection.py", line 1159, in establish_connection
    raise NetmikoTimeoutException(msg)
netmiko.exceptions.NetmikoTimeoutException: TCP connection to device failed.

Common causes of this problem are:
1. Incorrect hostname or IP address.
2. Wrong TCP port.
3. Intermediate firewall blocking access.

Device settings: cisco_ios 10.5.108.103:22



During handling of the above exception, another exception occurred:

Traceback (most recent call last):
  File "/home/kali/.local/lib/python3.11/site-packages/nornir/core/task.py", line 99, in start
    r = self.task(self, **self.params)
        ^^^^^^^^^^^^^^^^^^^^^^^^^^^^^^
  File "/home/kali/.local/lib/python3.11/site-packages/nornir_napalm/plugins/tasks/napalm_cli.py", line 19, in napalm_cli
    device = task.host.get_connection(CONNECTION_NAME, task.nornir.config)
             ^^^^^^^^^^^^^^^^^^^^^^^^^^^^^^^^^^^^^^^^^^^^^^^^^^^^^^^^^^^^^
  File "/home/kali/.local/lib/python3.11/site-packages/nornir/core/inventory.py", line 494, in get_connection
    self.open_connection(
  File "/home/kali/.local/lib/python3.11/site-packages/nornir/core/inventory.py", line 546, in open_connection
    conn_obj.open(
  File "/home/kali/.local/lib/python3.11/site-packages/nornir_napalm/plugins/connections/__init__.py", line 57, in open
    connection.open()
  File "/home/kali/.local/lib/python3.11/site-packages/napalm/ios/ios.py", line 173, in open
    self.device = self._netmiko_open(
                  ^^^^^^^^^^^^^^^^^^^
  File "/home/kali/.local/lib/python3.11/site-packages/napalm/base/base.py", line 123, in _netmiko_open
    raise ConnectionException("Cannot connect to {}".format(self.hostname))
napalm.base.exceptions.ConnectionException: Cannot connect to 10.5.108.103

2024-12-23 14:25:45,819 - nornir.core.task -    ERROR -      start() - Host 'LH-Part 3-UGF': task 'nornir_napalm_cli_commands_example' failed with traceback:
Traceback (most recent call last):
  File "/home/kali/.local/lib/python3.11/site-packages/nornir/core/task.py", line 99, in start
    r = self.task(self, **self.params)
        ^^^^^^^^^^^^^^^^^^^^^^^^^^^^^^
  File "/home/kali/Desktop/Nornir/2023/IITH/Cisco Ph2/Inventory/cli_short_inv_withDates.py", line 14, in nornir_napalm_cli_commands_example
    task.run(task=napalm_cli, commands=[command, command1, command2])
  File "/home/kali/.local/lib/python3.11/site-packages/nornir/core/task.py", line 174, in run
    raise NornirSubTaskError(task=run_task, result=r)
nornir.core.exceptions.NornirSubTaskError: Subtask: napalm_cli (failed)


2024-12-23 14:25:45,855 - nornir.core.task -    ERROR -      start() - Host 'LH-Part 5-UGF': task 'napalm_cli' failed with traceback:
Traceback (most recent call last):
  File "/home/kali/.local/lib/python3.11/site-packages/netmiko/base_connection.py", line 1137, in establish_connection
    self.remote_conn_pre.connect(**ssh_connect_params)
  File "/usr/lib/python3/dist-packages/paramiko/client.py", line 358, in connect
    retry_on_signal(lambda: sock.connect(addr))
  File "/usr/lib/python3/dist-packages/paramiko/util.py", line 279, in retry_on_signal
    return function()
           ^^^^^^^^^^
  File "/usr/lib/python3/dist-packages/paramiko/client.py", line 358, in <lambda>
    retry_on_signal(lambda: sock.connect(addr))
                            ^^^^^^^^^^^^^^^^^^
TimeoutError: timed out

During handling of the above exception, another exception occurred:

Traceback (most recent call last):
  File "/home/kali/.local/lib/python3.11/site-packages/napalm/base/base.py", line 114, in _netmiko_open
    self._netmiko_device = ConnectHandler(
                           ^^^^^^^^^^^^^^^
  File "/home/kali/.local/lib/python3.11/site-packages/netmiko/ssh_dispatcher.py", line 399, in ConnectHandler
    return ConnectionClass(*args, **kwargs)
           ^^^^^^^^^^^^^^^^^^^^^^^^^^^^^^^^
  File "/home/kali/.local/lib/python3.11/site-packages/netmiko/base_connection.py", line 488, in __init__
    self._open()
  File "/home/kali/.local/lib/python3.11/site-packages/netmiko/base_connection.py", line 493, in _open
    self.establish_connection()
  File "/home/kali/.local/lib/python3.11/site-packages/netmiko/base_connection.py", line 1159, in establish_connection
    raise NetmikoTimeoutException(msg)
netmiko.exceptions.NetmikoTimeoutException: TCP connection to device failed.

Common causes of this problem are:
1. Incorrect hostname or IP address.
2. Wrong TCP port.
3. Intermediate firewall blocking access.

Device settings: cisco_ios 10.5.108.104:22



During handling of the above exception, another exception occurred:

Traceback (most recent call last):
  File "/home/kali/.local/lib/python3.11/site-packages/nornir/core/task.py", line 99, in start
    r = self.task(self, **self.params)
        ^^^^^^^^^^^^^^^^^^^^^^^^^^^^^^
  File "/home/kali/.local/lib/python3.11/site-packages/nornir_napalm/plugins/tasks/napalm_cli.py", line 19, in napalm_cli
    device = task.host.get_connection(CONNECTION_NAME, task.nornir.config)
             ^^^^^^^^^^^^^^^^^^^^^^^^^^^^^^^^^^^^^^^^^^^^^^^^^^^^^^^^^^^^^
  File "/home/kali/.local/lib/python3.11/site-packages/nornir/core/inventory.py", line 494, in get_connection
    self.open_connection(
  File "/home/kali/.local/lib/python3.11/site-packages/nornir/core/inventory.py", line 546, in open_connection
    conn_obj.open(
  File "/home/kali/.local/lib/python3.11/site-packages/nornir_napalm/plugins/connections/__init__.py", line 57, in open
    connection.open()
  File "/home/kali/.local/lib/python3.11/site-packages/napalm/ios/ios.py", line 173, in open
    self.device = self._netmiko_open(
                  ^^^^^^^^^^^^^^^^^^^
  File "/home/kali/.local/lib/python3.11/site-packages/napalm/base/base.py", line 123, in _netmiko_open
    raise ConnectionException("Cannot connect to {}".format(self.hostname))
napalm.base.exceptions.ConnectionException: Cannot connect to 10.5.108.104

2024-12-23 14:25:45,855 - nornir.core.task -    ERROR -      start() - Host 'LH-Part 5-UGF': task 'nornir_napalm_cli_commands_example' failed with traceback:
Traceback (most recent call last):
  File "/home/kali/.local/lib/python3.11/site-packages/nornir/core/task.py", line 99, in start
    r = self.task(self, **self.params)
        ^^^^^^^^^^^^^^^^^^^^^^^^^^^^^^
  File "/home/kali/Desktop/Nornir/2023/IITH/Cisco Ph2/Inventory/cli_short_inv_withDates.py", line 14, in nornir_napalm_cli_commands_example
    task.run(task=napalm_cli, commands=[command, command1, command2])
  File "/home/kali/.local/lib/python3.11/site-packages/nornir/core/task.py", line 174, in run
    raise NornirSubTaskError(task=run_task, result=r)
nornir.core.exceptions.NornirSubTaskError: Subtask: napalm_cli (failed)


2024-12-23 14:25:47,597 - nornir.core.task -    ERROR -      start() - Host 'NewDH-SW': task 'napalm_cli' failed with traceback:
Traceback (most recent call last):
  File "/home/kali/.local/lib/python3.11/site-packages/netmiko/base_connection.py", line 1137, in establish_connection
    self.remote_conn_pre.connect(**ssh_connect_params)
  File "/usr/lib/python3/dist-packages/paramiko/client.py", line 358, in connect
    retry_on_signal(lambda: sock.connect(addr))
  File "/usr/lib/python3/dist-packages/paramiko/util.py", line 279, in retry_on_signal
    return function()
           ^^^^^^^^^^
  File "/usr/lib/python3/dist-packages/paramiko/client.py", line 358, in <lambda>
    retry_on_signal(lambda: sock.connect(addr))
                            ^^^^^^^^^^^^^^^^^^
TimeoutError: timed out

During handling of the above exception, another exception occurred:

Traceback (most recent call last):
  File "/home/kali/.local/lib/python3.11/site-packages/napalm/base/base.py", line 114, in _netmiko_open
    self._netmiko_device = ConnectHandler(
                           ^^^^^^^^^^^^^^^
  File "/home/kali/.local/lib/python3.11/site-packages/netmiko/ssh_dispatcher.py", line 399, in ConnectHandler
    return ConnectionClass(*args, **kwargs)
           ^^^^^^^^^^^^^^^^^^^^^^^^^^^^^^^^
  File "/home/kali/.local/lib/python3.11/site-packages/netmiko/base_connection.py", line 488, in __init__
    self._open()
  File "/home/kali/.local/lib/python3.11/site-packages/netmiko/base_connection.py", line 493, in _open
    self.establish_connection()
  File "/home/kali/.local/lib/python3.11/site-packages/netmiko/base_connection.py", line 1159, in establish_connection
    raise NetmikoTimeoutException(msg)
netmiko.exceptions.NetmikoTimeoutException: TCP connection to device failed.

Common causes of this problem are:
1. Incorrect hostname or IP address.
2. Wrong TCP port.
3. Intermediate firewall blocking access.

Device settings: cisco_ios 10.5.100.101:22



During handling of the above exception, another exception occurred:

Traceback (most recent call last):
  File "/home/kali/.local/lib/python3.11/site-packages/nornir/core/task.py", line 99, in start
    r = self.task(self, **self.params)
        ^^^^^^^^^^^^^^^^^^^^^^^^^^^^^^
  File "/home/kali/.local/lib/python3.11/site-packages/nornir_napalm/plugins/tasks/napalm_cli.py", line 19, in napalm_cli
    device = task.host.get_connection(CONNECTION_NAME, task.nornir.config)
             ^^^^^^^^^^^^^^^^^^^^^^^^^^^^^^^^^^^^^^^^^^^^^^^^^^^^^^^^^^^^^
  File "/home/kali/.local/lib/python3.11/site-packages/nornir/core/inventory.py", line 494, in get_connection
    self.open_connection(
  File "/home/kali/.local/lib/python3.11/site-packages/nornir/core/inventory.py", line 546, in open_connection
    conn_obj.open(
  File "/home/kali/.local/lib/python3.11/site-packages/nornir_napalm/plugins/connections/__init__.py", line 57, in open
    connection.open()
  File "/home/kali/.local/lib/python3.11/site-packages/napalm/ios/ios.py", line 173, in open
    self.device = self._netmiko_open(
                  ^^^^^^^^^^^^^^^^^^^
  File "/home/kali/.local/lib/python3.11/site-packages/napalm/base/base.py", line 123, in _netmiko_open
    raise ConnectionException("Cannot connect to {}".format(self.hostname))
napalm.base.exceptions.ConnectionException: Cannot connect to 10.5.100.101

2024-12-23 14:25:47,599 - nornir.core.task -    ERROR -      start() - Host 'NewDH-SW': task 'nornir_napalm_cli_commands_example' failed with traceback:
Traceback (most recent call last):
  File "/home/kali/.local/lib/python3.11/site-packages/nornir/core/task.py", line 99, in start
    r = self.task(self, **self.params)
        ^^^^^^^^^^^^^^^^^^^^^^^^^^^^^^
  File "/home/kali/Desktop/Nornir/2023/IITH/Cisco Ph2/Inventory/cli_short_inv_withDates.py", line 14, in nornir_napalm_cli_commands_example
    task.run(task=napalm_cli, commands=[command, command1, command2])
  File "/home/kali/.local/lib/python3.11/site-packages/nornir/core/task.py", line 174, in run
    raise NornirSubTaskError(task=run_task, result=r)
nornir.core.exceptions.NornirSubTaskError: Subtask: napalm_cli (failed)


2025-05-27 11:23:23,179 -  nornir.core -     INFO -        run() - Running task 'nornir_napalm_cli_commands_example' with args {} on 224 hosts
2025-05-27 11:23:34,094 - nornir.core.task -    ERROR -      start() - Host 'AD3-MA321': task 'napalm_cli' failed with traceback:
Traceback (most recent call last):
  File "/home/kali/.local/lib/python3.11/site-packages/netmiko/base_connection.py", line 1142, in establish_connection
    self.remote_conn_pre.connect(**ssh_connect_params)
  File "/usr/lib/python3/dist-packages/paramiko/client.py", line 358, in connect
    retry_on_signal(lambda: sock.connect(addr))
  File "/usr/lib/python3/dist-packages/paramiko/util.py", line 279, in retry_on_signal
    return function()
           ^^^^^^^^^^
  File "/usr/lib/python3/dist-packages/paramiko/client.py", line 358, in <lambda>
    retry_on_signal(lambda: sock.connect(addr))
                            ^^^^^^^^^^^^^^^^^^
TimeoutError: timed out

During handling of the above exception, another exception occurred:

Traceback (most recent call last):
  File "/home/kali/.local/lib/python3.11/site-packages/napalm/base/base.py", line 114, in _netmiko_open
    self._netmiko_device = ConnectHandler(
                           ^^^^^^^^^^^^^^^
  File "/home/kali/.local/lib/python3.11/site-packages/netmiko/ssh_dispatcher.py", line 410, in ConnectHandler
    return ConnectionClass(*args, **kwargs)
           ^^^^^^^^^^^^^^^^^^^^^^^^^^^^^^^^
  File "/home/kali/.local/lib/python3.11/site-packages/netmiko/base_connection.py", line 493, in __init__
    self._open()
  File "/home/kali/.local/lib/python3.11/site-packages/netmiko/base_connection.py", line 498, in _open
    self.establish_connection()
  File "/home/kali/.local/lib/python3.11/site-packages/netmiko/base_connection.py", line 1164, in establish_connection
    raise NetmikoTimeoutException(msg)
netmiko.exceptions.NetmikoTimeoutException: TCP connection to device failed.

Common causes of this problem are:
1. Incorrect hostname or IP address.
2. Wrong TCP port.
3. Intermediate firewall blocking access.

Device settings: cisco_ios 10.5.116.108:22



During handling of the above exception, another exception occurred:

Traceback (most recent call last):
  File "/home/kali/.local/lib/python3.11/site-packages/nornir/core/task.py", line 99, in start
    r = self.task(self, **self.params)
        ^^^^^^^^^^^^^^^^^^^^^^^^^^^^^^
  File "/home/kali/.local/lib/python3.11/site-packages/nornir_napalm/plugins/tasks/napalm_cli.py", line 19, in napalm_cli
    device = task.host.get_connection(CONNECTION_NAME, task.nornir.config)
             ^^^^^^^^^^^^^^^^^^^^^^^^^^^^^^^^^^^^^^^^^^^^^^^^^^^^^^^^^^^^^
  File "/home/kali/.local/lib/python3.11/site-packages/nornir/core/inventory.py", line 494, in get_connection
    self.open_connection(
  File "/home/kali/.local/lib/python3.11/site-packages/nornir/core/inventory.py", line 546, in open_connection
    conn_obj.open(
  File "/home/kali/.local/lib/python3.11/site-packages/nornir_napalm/plugins/connections/__init__.py", line 57, in open
    connection.open()
  File "/home/kali/.local/lib/python3.11/site-packages/napalm/ios/ios.py", line 173, in open
    self.device = self._netmiko_open(
                  ^^^^^^^^^^^^^^^^^^^
  File "/home/kali/.local/lib/python3.11/site-packages/napalm/base/base.py", line 123, in _netmiko_open
    raise ConnectionException("Cannot connect to {}".format(self.hostname))
napalm.base.exceptions.ConnectionException: Cannot connect to 10.5.116.108

2025-05-27 11:23:34,095 - nornir.core.task -    ERROR -      start() - Host 'AD3-MA321': task 'nornir_napalm_cli_commands_example' failed with traceback:
Traceback (most recent call last):
  File "/home/kali/.local/lib/python3.11/site-packages/nornir/core/task.py", line 99, in start
    r = self.task(self, **self.params)
        ^^^^^^^^^^^^^^^^^^^^^^^^^^^^^^
  File "/home/kali/Desktop/Nornir/2023/IITH/CiscoPh2/Inventory/cli_short_inv_withDates.py", line 14, in nornir_napalm_cli_commands_example
    task.run(task=napalm_cli, commands=[command, command1, command2])
  File "/home/kali/.local/lib/python3.11/site-packages/nornir/core/task.py", line 174, in run
    raise NornirSubTaskError(task=run_task, result=r)
nornir.core.exceptions.NornirSubTaskError: Subtask: napalm_cli (failed)


2025-05-27 11:23:43,634 - nornir.core.task -    ERROR -      start() - Host 'CAMPUS-SCHOOL-2F': task 'napalm_cli' failed with traceback:
Traceback (most recent call last):
  File "/home/kali/.local/lib/python3.11/site-packages/netmiko/base_connection.py", line 1142, in establish_connection
    self.remote_conn_pre.connect(**ssh_connect_params)
  File "/usr/lib/python3/dist-packages/paramiko/client.py", line 358, in connect
    retry_on_signal(lambda: sock.connect(addr))
  File "/usr/lib/python3/dist-packages/paramiko/util.py", line 279, in retry_on_signal
    return function()
           ^^^^^^^^^^
  File "/usr/lib/python3/dist-packages/paramiko/client.py", line 358, in <lambda>
    retry_on_signal(lambda: sock.connect(addr))
                            ^^^^^^^^^^^^^^^^^^
TimeoutError: timed out

During handling of the above exception, another exception occurred:

Traceback (most recent call last):
  File "/home/kali/.local/lib/python3.11/site-packages/napalm/base/base.py", line 114, in _netmiko_open
    self._netmiko_device = ConnectHandler(
                           ^^^^^^^^^^^^^^^
  File "/home/kali/.local/lib/python3.11/site-packages/netmiko/ssh_dispatcher.py", line 410, in ConnectHandler
    return ConnectionClass(*args, **kwargs)
           ^^^^^^^^^^^^^^^^^^^^^^^^^^^^^^^^
  File "/home/kali/.local/lib/python3.11/site-packages/netmiko/base_connection.py", line 493, in __init__
    self._open()
  File "/home/kali/.local/lib/python3.11/site-packages/netmiko/base_connection.py", line 498, in _open
    self.establish_connection()
  File "/home/kali/.local/lib/python3.11/site-packages/netmiko/base_connection.py", line 1164, in establish_connection
    raise NetmikoTimeoutException(msg)
netmiko.exceptions.NetmikoTimeoutException: TCP connection to device failed.

Common causes of this problem are:
1. Incorrect hostname or IP address.
2. Wrong TCP port.
3. Intermediate firewall blocking access.

Device settings: cisco_ios 10.5.100.96:22



During handling of the above exception, another exception occurred:

Traceback (most recent call last):
  File "/home/kali/.local/lib/python3.11/site-packages/nornir/core/task.py", line 99, in start
    r = self.task(self, **self.params)
        ^^^^^^^^^^^^^^^^^^^^^^^^^^^^^^
  File "/home/kali/.local/lib/python3.11/site-packages/nornir_napalm/plugins/tasks/napalm_cli.py", line 19, in napalm_cli
    device = task.host.get_connection(CONNECTION_NAME, task.nornir.config)
             ^^^^^^^^^^^^^^^^^^^^^^^^^^^^^^^^^^^^^^^^^^^^^^^^^^^^^^^^^^^^^
  File "/home/kali/.local/lib/python3.11/site-packages/nornir/core/inventory.py", line 494, in get_connection
    self.open_connection(
  File "/home/kali/.local/lib/python3.11/site-packages/nornir/core/inventory.py", line 546, in open_connection
    conn_obj.open(
  File "/home/kali/.local/lib/python3.11/site-packages/nornir_napalm/plugins/connections/__init__.py", line 57, in open
    connection.open()
  File "/home/kali/.local/lib/python3.11/site-packages/napalm/ios/ios.py", line 173, in open
    self.device = self._netmiko_open(
                  ^^^^^^^^^^^^^^^^^^^
  File "/home/kali/.local/lib/python3.11/site-packages/napalm/base/base.py", line 123, in _netmiko_open
    raise ConnectionException("Cannot connect to {}".format(self.hostname))
napalm.base.exceptions.ConnectionException: Cannot connect to 10.5.100.96

2025-05-27 11:23:43,634 - nornir.core.task -    ERROR -      start() - Host 'CAMPUS-SCHOOL-2F': task 'nornir_napalm_cli_commands_example' failed with traceback:
Traceback (most recent call last):
  File "/home/kali/.local/lib/python3.11/site-packages/nornir/core/task.py", line 99, in start
    r = self.task(self, **self.params)
        ^^^^^^^^^^^^^^^^^^^^^^^^^^^^^^
  File "/home/kali/Desktop/Nornir/2023/IITH/CiscoPh2/Inventory/cli_short_inv_withDates.py", line 14, in nornir_napalm_cli_commands_example
    task.run(task=napalm_cli, commands=[command, command1, command2])
  File "/home/kali/.local/lib/python3.11/site-packages/nornir/core/task.py", line 174, in run
    raise NornirSubTaskError(task=run_task, result=r)
nornir.core.exceptions.NornirSubTaskError: Subtask: napalm_cli (failed)


2025-05-27 11:23:43,767 - nornir.core.task -    ERROR -      start() - Host 'CAMPUS-SCHOOL-GF': task 'napalm_cli' failed with traceback:
Traceback (most recent call last):
  File "/home/kali/.local/lib/python3.11/site-packages/netmiko/base_connection.py", line 1142, in establish_connection
    self.remote_conn_pre.connect(**ssh_connect_params)
  File "/usr/lib/python3/dist-packages/paramiko/client.py", line 358, in connect
    retry_on_signal(lambda: sock.connect(addr))
  File "/usr/lib/python3/dist-packages/paramiko/util.py", line 279, in retry_on_signal
    return function()
           ^^^^^^^^^^
  File "/usr/lib/python3/dist-packages/paramiko/client.py", line 358, in <lambda>
    retry_on_signal(lambda: sock.connect(addr))
                            ^^^^^^^^^^^^^^^^^^
TimeoutError: timed out

During handling of the above exception, another exception occurred:

Traceback (most recent call last):
  File "/home/kali/.local/lib/python3.11/site-packages/napalm/base/base.py", line 114, in _netmiko_open
    self._netmiko_device = ConnectHandler(
                           ^^^^^^^^^^^^^^^
  File "/home/kali/.local/lib/python3.11/site-packages/netmiko/ssh_dispatcher.py", line 410, in ConnectHandler
    return ConnectionClass(*args, **kwargs)
           ^^^^^^^^^^^^^^^^^^^^^^^^^^^^^^^^
  File "/home/kali/.local/lib/python3.11/site-packages/netmiko/base_connection.py", line 493, in __init__
    self._open()
  File "/home/kali/.local/lib/python3.11/site-packages/netmiko/base_connection.py", line 498, in _open
    self.establish_connection()
  File "/home/kali/.local/lib/python3.11/site-packages/netmiko/base_connection.py", line 1164, in establish_connection
    raise NetmikoTimeoutException(msg)
netmiko.exceptions.NetmikoTimeoutException: TCP connection to device failed.

Common causes of this problem are:
1. Incorrect hostname or IP address.
2. Wrong TCP port.
3. Intermediate firewall blocking access.

Device settings: cisco_ios 10.5.100.95:22



During handling of the above exception, another exception occurred:

Traceback (most recent call last):
  File "/home/kali/.local/lib/python3.11/site-packages/nornir/core/task.py", line 99, in start
    r = self.task(self, **self.params)
        ^^^^^^^^^^^^^^^^^^^^^^^^^^^^^^
  File "/home/kali/.local/lib/python3.11/site-packages/nornir_napalm/plugins/tasks/napalm_cli.py", line 19, in napalm_cli
    device = task.host.get_connection(CONNECTION_NAME, task.nornir.config)
             ^^^^^^^^^^^^^^^^^^^^^^^^^^^^^^^^^^^^^^^^^^^^^^^^^^^^^^^^^^^^^
  File "/home/kali/.local/lib/python3.11/site-packages/nornir/core/inventory.py", line 494, in get_connection
    self.open_connection(
  File "/home/kali/.local/lib/python3.11/site-packages/nornir/core/inventory.py", line 546, in open_connection
    conn_obj.open(
  File "/home/kali/.local/lib/python3.11/site-packages/nornir_napalm/plugins/connections/__init__.py", line 57, in open
    connection.open()
  File "/home/kali/.local/lib/python3.11/site-packages/napalm/ios/ios.py", line 173, in open
    self.device = self._netmiko_open(
                  ^^^^^^^^^^^^^^^^^^^
  File "/home/kali/.local/lib/python3.11/site-packages/napalm/base/base.py", line 123, in _netmiko_open
    raise ConnectionException("Cannot connect to {}".format(self.hostname))
napalm.base.exceptions.ConnectionException: Cannot connect to 10.5.100.95

2025-05-27 11:23:43,767 - nornir.core.task -    ERROR -      start() - Host 'CAMPUS-SCHOOL-GF': task 'nornir_napalm_cli_commands_example' failed with traceback:
Traceback (most recent call last):
  File "/home/kali/.local/lib/python3.11/site-packages/nornir/core/task.py", line 99, in start
    r = self.task(self, **self.params)
        ^^^^^^^^^^^^^^^^^^^^^^^^^^^^^^
  File "/home/kali/Desktop/Nornir/2023/IITH/CiscoPh2/Inventory/cli_short_inv_withDates.py", line 14, in nornir_napalm_cli_commands_example
    task.run(task=napalm_cli, commands=[command, command1, command2])
  File "/home/kali/.local/lib/python3.11/site-packages/nornir/core/task.py", line 174, in run
    raise NornirSubTaskError(task=run_task, result=r)
nornir.core.exceptions.NornirSubTaskError: Subtask: napalm_cli (failed)


2025-05-27 11:23:51,788 - nornir.core.task -    ERROR -      start() - Host 'LH-5-800Seater-AVRoom': task 'napalm_cli' failed with traceback:
Traceback (most recent call last):
  File "/home/kali/.local/lib/python3.11/site-packages/netmiko/base_connection.py", line 1142, in establish_connection
    self.remote_conn_pre.connect(**ssh_connect_params)
  File "/usr/lib/python3/dist-packages/paramiko/client.py", line 358, in connect
    retry_on_signal(lambda: sock.connect(addr))
  File "/usr/lib/python3/dist-packages/paramiko/util.py", line 279, in retry_on_signal
    return function()
           ^^^^^^^^^^
  File "/usr/lib/python3/dist-packages/paramiko/client.py", line 358, in <lambda>
    retry_on_signal(lambda: sock.connect(addr))
                            ^^^^^^^^^^^^^^^^^^
TimeoutError: timed out

During handling of the above exception, another exception occurred:

Traceback (most recent call last):
  File "/home/kali/.local/lib/python3.11/site-packages/napalm/base/base.py", line 114, in _netmiko_open
    self._netmiko_device = ConnectHandler(
                           ^^^^^^^^^^^^^^^
  File "/home/kali/.local/lib/python3.11/site-packages/netmiko/ssh_dispatcher.py", line 410, in ConnectHandler
    return ConnectionClass(*args, **kwargs)
           ^^^^^^^^^^^^^^^^^^^^^^^^^^^^^^^^
  File "/home/kali/.local/lib/python3.11/site-packages/netmiko/base_connection.py", line 493, in __init__
    self._open()
  File "/home/kali/.local/lib/python3.11/site-packages/netmiko/base_connection.py", line 498, in _open
    self.establish_connection()
  File "/home/kali/.local/lib/python3.11/site-packages/netmiko/base_connection.py", line 1164, in establish_connection
    raise NetmikoTimeoutException(msg)
netmiko.exceptions.NetmikoTimeoutException: TCP connection to device failed.

Common causes of this problem are:
1. Incorrect hostname or IP address.
2. Wrong TCP port.
3. Intermediate firewall blocking access.

Device settings: cisco_ios 10.5.108.106:22



During handling of the above exception, another exception occurred:

Traceback (most recent call last):
  File "/home/kali/.local/lib/python3.11/site-packages/nornir/core/task.py", line 99, in start
    r = self.task(self, **self.params)
        ^^^^^^^^^^^^^^^^^^^^^^^^^^^^^^
  File "/home/kali/.local/lib/python3.11/site-packages/nornir_napalm/plugins/tasks/napalm_cli.py", line 19, in napalm_cli
    device = task.host.get_connection(CONNECTION_NAME, task.nornir.config)
             ^^^^^^^^^^^^^^^^^^^^^^^^^^^^^^^^^^^^^^^^^^^^^^^^^^^^^^^^^^^^^
  File "/home/kali/.local/lib/python3.11/site-packages/nornir/core/inventory.py", line 494, in get_connection
    self.open_connection(
  File "/home/kali/.local/lib/python3.11/site-packages/nornir/core/inventory.py", line 546, in open_connection
    conn_obj.open(
  File "/home/kali/.local/lib/python3.11/site-packages/nornir_napalm/plugins/connections/__init__.py", line 57, in open
    connection.open()
  File "/home/kali/.local/lib/python3.11/site-packages/napalm/ios/ios.py", line 173, in open
    self.device = self._netmiko_open(
                  ^^^^^^^^^^^^^^^^^^^
  File "/home/kali/.local/lib/python3.11/site-packages/napalm/base/base.py", line 123, in _netmiko_open
    raise ConnectionException("Cannot connect to {}".format(self.hostname))
napalm.base.exceptions.ConnectionException: Cannot connect to 10.5.108.106

2025-05-27 11:23:51,790 - nornir.core.task -    ERROR -      start() - Host 'LH-5-800Seater-AVRoom': task 'nornir_napalm_cli_commands_example' failed with traceback:
Traceback (most recent call last):
  File "/home/kali/.local/lib/python3.11/site-packages/nornir/core/task.py", line 99, in start
    r = self.task(self, **self.params)
        ^^^^^^^^^^^^^^^^^^^^^^^^^^^^^^
  File "/home/kali/Desktop/Nornir/2023/IITH/CiscoPh2/Inventory/cli_short_inv_withDates.py", line 14, in nornir_napalm_cli_commands_example
    task.run(task=napalm_cli, commands=[command, command1, command2])
  File "/home/kali/.local/lib/python3.11/site-packages/nornir/core/task.py", line 174, in run
    raise NornirSubTaskError(task=run_task, result=r)
nornir.core.exceptions.NornirSubTaskError: Subtask: napalm_cli (failed)


2025-05-27 11:23:54,136 - nornir.core.task -    ERROR -      start() - Host 'RCC-R1-2F': task 'napalm_cli' failed with traceback:
Traceback (most recent call last):
  File "/home/kali/.local/lib/python3.11/site-packages/netmiko/base_connection.py", line 1142, in establish_connection
    self.remote_conn_pre.connect(**ssh_connect_params)
  File "/usr/lib/python3/dist-packages/paramiko/client.py", line 358, in connect
    retry_on_signal(lambda: sock.connect(addr))
  File "/usr/lib/python3/dist-packages/paramiko/util.py", line 279, in retry_on_signal
    return function()
           ^^^^^^^^^^
  File "/usr/lib/python3/dist-packages/paramiko/client.py", line 358, in <lambda>
    retry_on_signal(lambda: sock.connect(addr))
                            ^^^^^^^^^^^^^^^^^^
TimeoutError: timed out

During handling of the above exception, another exception occurred:

Traceback (most recent call last):
  File "/home/kali/.local/lib/python3.11/site-packages/napalm/base/base.py", line 114, in _netmiko_open
    self._netmiko_device = ConnectHandler(
                           ^^^^^^^^^^^^^^^
  File "/home/kali/.local/lib/python3.11/site-packages/netmiko/ssh_dispatcher.py", line 410, in ConnectHandler
    return ConnectionClass(*args, **kwargs)
           ^^^^^^^^^^^^^^^^^^^^^^^^^^^^^^^^
  File "/home/kali/.local/lib/python3.11/site-packages/netmiko/base_connection.py", line 493, in __init__
    self._open()
  File "/home/kali/.local/lib/python3.11/site-packages/netmiko/base_connection.py", line 498, in _open
    self.establish_connection()
  File "/home/kali/.local/lib/python3.11/site-packages/netmiko/base_connection.py", line 1164, in establish_connection
    raise NetmikoTimeoutException(msg)
netmiko.exceptions.NetmikoTimeoutException: TCP connection to device failed.

Common causes of this problem are:
1. Incorrect hostname or IP address.
2. Wrong TCP port.
3. Intermediate firewall blocking access.

Device settings: cisco_ios 10.4.112.102:22



During handling of the above exception, another exception occurred:

Traceback (most recent call last):
  File "/home/kali/.local/lib/python3.11/site-packages/nornir/core/task.py", line 99, in start
    r = self.task(self, **self.params)
        ^^^^^^^^^^^^^^^^^^^^^^^^^^^^^^
  File "/home/kali/.local/lib/python3.11/site-packages/nornir_napalm/plugins/tasks/napalm_cli.py", line 19, in napalm_cli
    device = task.host.get_connection(CONNECTION_NAME, task.nornir.config)
             ^^^^^^^^^^^^^^^^^^^^^^^^^^^^^^^^^^^^^^^^^^^^^^^^^^^^^^^^^^^^^
  File "/home/kali/.local/lib/python3.11/site-packages/nornir/core/inventory.py", line 494, in get_connection
    self.open_connection(
  File "/home/kali/.local/lib/python3.11/site-packages/nornir/core/inventory.py", line 546, in open_connection
    conn_obj.open(
  File "/home/kali/.local/lib/python3.11/site-packages/nornir_napalm/plugins/connections/__init__.py", line 57, in open
    connection.open()
  File "/home/kali/.local/lib/python3.11/site-packages/napalm/ios/ios.py", line 173, in open
    self.device = self._netmiko_open(
                  ^^^^^^^^^^^^^^^^^^^
  File "/home/kali/.local/lib/python3.11/site-packages/napalm/base/base.py", line 123, in _netmiko_open
    raise ConnectionException("Cannot connect to {}".format(self.hostname))
napalm.base.exceptions.ConnectionException: Cannot connect to 10.4.112.102

2025-05-27 11:23:54,136 - nornir.core.task -    ERROR -      start() - Host 'RCC-R1-2F': task 'nornir_napalm_cli_commands_example' failed with traceback:
Traceback (most recent call last):
  File "/home/kali/.local/lib/python3.11/site-packages/nornir/core/task.py", line 99, in start
    r = self.task(self, **self.params)
        ^^^^^^^^^^^^^^^^^^^^^^^^^^^^^^
  File "/home/kali/Desktop/Nornir/2023/IITH/CiscoPh2/Inventory/cli_short_inv_withDates.py", line 14, in nornir_napalm_cli_commands_example
    task.run(task=napalm_cli, commands=[command, command1, command2])
  File "/home/kali/.local/lib/python3.11/site-packages/nornir/core/task.py", line 174, in run
    raise NornirSubTaskError(task=run_task, result=r)
nornir.core.exceptions.NornirSubTaskError: Subtask: napalm_cli (failed)


2025-05-27 11:25:05,238 -  nornir.core -     INFO -        run() - Running task 'nornir_napalm_cli_commands_example' with args {} on 220 hosts
2025-05-27 11:25:16,132 - nornir.core.task -    ERROR -      start() - Host 'AD3-MA321': task 'napalm_cli' failed with traceback:
Traceback (most recent call last):
  File "/home/kali/.local/lib/python3.11/site-packages/netmiko/base_connection.py", line 1142, in establish_connection
    self.remote_conn_pre.connect(**ssh_connect_params)
  File "/usr/lib/python3/dist-packages/paramiko/client.py", line 358, in connect
    retry_on_signal(lambda: sock.connect(addr))
  File "/usr/lib/python3/dist-packages/paramiko/util.py", line 279, in retry_on_signal
    return function()
           ^^^^^^^^^^
  File "/usr/lib/python3/dist-packages/paramiko/client.py", line 358, in <lambda>
    retry_on_signal(lambda: sock.connect(addr))
                            ^^^^^^^^^^^^^^^^^^
TimeoutError: timed out

During handling of the above exception, another exception occurred:

Traceback (most recent call last):
  File "/home/kali/.local/lib/python3.11/site-packages/napalm/base/base.py", line 114, in _netmiko_open
    self._netmiko_device = ConnectHandler(
                           ^^^^^^^^^^^^^^^
  File "/home/kali/.local/lib/python3.11/site-packages/netmiko/ssh_dispatcher.py", line 410, in ConnectHandler
    return ConnectionClass(*args, **kwargs)
           ^^^^^^^^^^^^^^^^^^^^^^^^^^^^^^^^
  File "/home/kali/.local/lib/python3.11/site-packages/netmiko/base_connection.py", line 493, in __init__
    self._open()
  File "/home/kali/.local/lib/python3.11/site-packages/netmiko/base_connection.py", line 498, in _open
    self.establish_connection()
  File "/home/kali/.local/lib/python3.11/site-packages/netmiko/base_connection.py", line 1164, in establish_connection
    raise NetmikoTimeoutException(msg)
netmiko.exceptions.NetmikoTimeoutException: TCP connection to device failed.

Common causes of this problem are:
1. Incorrect hostname or IP address.
2. Wrong TCP port.
3. Intermediate firewall blocking access.

Device settings: cisco_ios 10.5.116.108:22



During handling of the above exception, another exception occurred:

Traceback (most recent call last):
  File "/home/kali/.local/lib/python3.11/site-packages/nornir/core/task.py", line 99, in start
    r = self.task(self, **self.params)
        ^^^^^^^^^^^^^^^^^^^^^^^^^^^^^^
  File "/home/kali/.local/lib/python3.11/site-packages/nornir_napalm/plugins/tasks/napalm_cli.py", line 19, in napalm_cli
    device = task.host.get_connection(CONNECTION_NAME, task.nornir.config)
             ^^^^^^^^^^^^^^^^^^^^^^^^^^^^^^^^^^^^^^^^^^^^^^^^^^^^^^^^^^^^^
  File "/home/kali/.local/lib/python3.11/site-packages/nornir/core/inventory.py", line 494, in get_connection
    self.open_connection(
  File "/home/kali/.local/lib/python3.11/site-packages/nornir/core/inventory.py", line 546, in open_connection
    conn_obj.open(
  File "/home/kali/.local/lib/python3.11/site-packages/nornir_napalm/plugins/connections/__init__.py", line 57, in open
    connection.open()
  File "/home/kali/.local/lib/python3.11/site-packages/napalm/ios/ios.py", line 173, in open
    self.device = self._netmiko_open(
                  ^^^^^^^^^^^^^^^^^^^
  File "/home/kali/.local/lib/python3.11/site-packages/napalm/base/base.py", line 123, in _netmiko_open
    raise ConnectionException("Cannot connect to {}".format(self.hostname))
napalm.base.exceptions.ConnectionException: Cannot connect to 10.5.116.108

2025-05-27 11:25:16,135 - nornir.core.task -    ERROR -      start() - Host 'AD3-MA321': task 'nornir_napalm_cli_commands_example' failed with traceback:
Traceback (most recent call last):
  File "/home/kali/.local/lib/python3.11/site-packages/nornir/core/task.py", line 99, in start
    r = self.task(self, **self.params)
        ^^^^^^^^^^^^^^^^^^^^^^^^^^^^^^
  File "/home/kali/Desktop/Nornir/2023/IITH/CiscoPh2/Inventory/cli_short_inv_withDates.py", line 14, in nornir_napalm_cli_commands_example
    task.run(task=napalm_cli, commands=[command, command1, command2])
  File "/home/kali/.local/lib/python3.11/site-packages/nornir/core/task.py", line 174, in run
    raise NornirSubTaskError(task=run_task, result=r)
nornir.core.exceptions.NornirSubTaskError: Subtask: napalm_cli (failed)


2025-05-27 11:26:35,761 -  nornir.core -     INFO -        run() - Running task 'napalm_cli' with args {'commands': ['show inventory', 'show license all | include Start Date', 'show license all | include End Date']} on 220 hosts
2025-05-27 11:26:46,651 - nornir.core.task -    ERROR -      start() - Host 'AD3-MA321': task 'napalm_cli' failed with traceback:
Traceback (most recent call last):
  File "/home/kali/.local/lib/python3.11/site-packages/netmiko/base_connection.py", line 1142, in establish_connection
    self.remote_conn_pre.connect(**ssh_connect_params)
  File "/usr/lib/python3/dist-packages/paramiko/client.py", line 358, in connect
    retry_on_signal(lambda: sock.connect(addr))
  File "/usr/lib/python3/dist-packages/paramiko/util.py", line 279, in retry_on_signal
    return function()
           ^^^^^^^^^^
  File "/usr/lib/python3/dist-packages/paramiko/client.py", line 358, in <lambda>
    retry_on_signal(lambda: sock.connect(addr))
                            ^^^^^^^^^^^^^^^^^^
TimeoutError: timed out

During handling of the above exception, another exception occurred:

Traceback (most recent call last):
  File "/home/kali/.local/lib/python3.11/site-packages/napalm/base/base.py", line 114, in _netmiko_open
    self._netmiko_device = ConnectHandler(
                           ^^^^^^^^^^^^^^^
  File "/home/kali/.local/lib/python3.11/site-packages/netmiko/ssh_dispatcher.py", line 410, in ConnectHandler
    return ConnectionClass(*args, **kwargs)
           ^^^^^^^^^^^^^^^^^^^^^^^^^^^^^^^^
  File "/home/kali/.local/lib/python3.11/site-packages/netmiko/base_connection.py", line 493, in __init__
    self._open()
  File "/home/kali/.local/lib/python3.11/site-packages/netmiko/base_connection.py", line 498, in _open
    self.establish_connection()
  File "/home/kali/.local/lib/python3.11/site-packages/netmiko/base_connection.py", line 1164, in establish_connection
    raise NetmikoTimeoutException(msg)
netmiko.exceptions.NetmikoTimeoutException: TCP connection to device failed.

Common causes of this problem are:
1. Incorrect hostname or IP address.
2. Wrong TCP port.
3. Intermediate firewall blocking access.

Device settings: cisco_ios 10.5.116.108:22



During handling of the above exception, another exception occurred:

Traceback (most recent call last):
  File "/home/kali/.local/lib/python3.11/site-packages/nornir/core/task.py", line 99, in start
    r = self.task(self, **self.params)
        ^^^^^^^^^^^^^^^^^^^^^^^^^^^^^^
  File "/home/kali/.local/lib/python3.11/site-packages/nornir_napalm/plugins/tasks/napalm_cli.py", line 19, in napalm_cli
    device = task.host.get_connection(CONNECTION_NAME, task.nornir.config)
             ^^^^^^^^^^^^^^^^^^^^^^^^^^^^^^^^^^^^^^^^^^^^^^^^^^^^^^^^^^^^^
  File "/home/kali/.local/lib/python3.11/site-packages/nornir/core/inventory.py", line 494, in get_connection
    self.open_connection(
  File "/home/kali/.local/lib/python3.11/site-packages/nornir/core/inventory.py", line 546, in open_connection
    conn_obj.open(
  File "/home/kali/.local/lib/python3.11/site-packages/nornir_napalm/plugins/connections/__init__.py", line 57, in open
    connection.open()
  File "/home/kali/.local/lib/python3.11/site-packages/napalm/ios/ios.py", line 173, in open
    self.device = self._netmiko_open(
                  ^^^^^^^^^^^^^^^^^^^
  File "/home/kali/.local/lib/python3.11/site-packages/napalm/base/base.py", line 123, in _netmiko_open
    raise ConnectionException("Cannot connect to {}".format(self.hostname))
napalm.base.exceptions.ConnectionException: Cannot connect to 10.5.116.108

2025-05-27 11:28:11,537 -  nornir.core -     INFO -        run() - Running task 'napalm_cli' with args {'commands': ['show inventory', 'show license all | include Start Date', 'show license all | include End Date']} on 219 hosts
