2024-04-18 03:12:49,789 -  nornir.core -     INFO -        run() - Running task 'nornir_napalm_cli_commands_example' with args {} on 4 hosts
2024-04-18 06:26:33,253 -  nornir.core -     INFO -        run() - Running task 'nornir_napalm_get_example' with args {} on 4 hosts
2024-04-19 00:33:15,635 -  nornir.core -     INFO -        run() - Running task 'nornir_napalm_cli_commands_example' with args {} on 57 hosts
2024-04-19 00:33:19,720 - nornir.core.task -    ERROR -      start() - Host 'BHN-A-6F-SW': task 'napalm_cli' failed with traceback:
Traceback (most recent call last):
  File "/home/kali/.local/lib/python3.11/site-packages/netmiko/base_connection.py", line 1137, in establish_connection
    self.remote_conn_pre.connect(**ssh_connect_params)
  File "/usr/lib/python3/dist-packages/paramiko/client.py", line 450, in connect
    self._auth(
  File "/usr/lib/python3/dist-packages/paramiko/client.py", line 781, in _auth
    raise saved_exception
  File "/usr/lib/python3/dist-packages/paramiko/client.py", line 768, in _auth
    self._transport.auth_password(username, password)
  File "/usr/lib/python3/dist-packages/paramiko/transport.py", line 1564, in auth_password
    return self.auth_handler.wait_for_response(my_event)
           ^^^^^^^^^^^^^^^^^^^^^^^^^^^^^^^^^^^^^^^^^^^^^
  File "/usr/lib/python3/dist-packages/paramiko/auth_handler.py", line 259, in wait_for_response
    raise e
paramiko.ssh_exception.AuthenticationException: Authentication failed.

During handling of the above exception, another exception occurred:

Traceback (most recent call last):
  File "/home/kali/.local/lib/python3.11/site-packages/nornir/core/task.py", line 99, in start
    r = self.task(self, **self.params)
        ^^^^^^^^^^^^^^^^^^^^^^^^^^^^^^
  File "/home/kali/.local/lib/python3.11/site-packages/nornir_napalm/plugins/tasks/napalm_cli.py", line 19, in napalm_cli
    device = task.host.get_connection(CONNECTION_NAME, task.nornir.config)
             ^^^^^^^^^^^^^^^^^^^^^^^^^^^^^^^^^^^^^^^^^^^^^^^^^^^^^^^^^^^^^
  File "/home/kali/.local/lib/python3.11/site-packages/nornir/core/inventory.py", line 494, in get_connection
    self.open_connection(
  File "/home/kali/.local/lib/python3.11/site-packages/nornir/core/inventory.py", line 546, in open_connection
    conn_obj.open(
  File "/home/kali/.local/lib/python3.11/site-packages/nornir_napalm/plugins/connections/__init__.py", line 57, in open
    connection.open()
  File "/home/kali/.local/lib/python3.11/site-packages/napalm/ios/ios.py", line 173, in open
    self.device = self._netmiko_open(
                  ^^^^^^^^^^^^^^^^^^^
  File "/home/kali/.local/lib/python3.11/site-packages/napalm/base/base.py", line 114, in _netmiko_open
    self._netmiko_device = ConnectHandler(
                           ^^^^^^^^^^^^^^^
  File "/home/kali/.local/lib/python3.11/site-packages/netmiko/ssh_dispatcher.py", line 399, in ConnectHandler
    return ConnectionClass(*args, **kwargs)
           ^^^^^^^^^^^^^^^^^^^^^^^^^^^^^^^^
  File "/home/kali/.local/lib/python3.11/site-packages/netmiko/base_connection.py", line 488, in __init__
    self._open()
  File "/home/kali/.local/lib/python3.11/site-packages/netmiko/base_connection.py", line 493, in _open
    self.establish_connection()
  File "/home/kali/.local/lib/python3.11/site-packages/netmiko/base_connection.py", line 1174, in establish_connection
    raise NetmikoAuthenticationException(msg)
netmiko.exceptions.NetmikoAuthenticationException: Authentication to device failed.

Common causes of this problem are:
1. Invalid username and password
2. Incorrect SSH-key file
3. Connecting to the wrong device

Device settings: cisco_ios 10.5.48.53:22


Authentication failed.

2024-04-19 00:33:19,721 - nornir.core.task -    ERROR -      start() - Host 'BHN-A-6F-SW': task 'nornir_napalm_cli_commands_example' failed with traceback:
Traceback (most recent call last):
  File "/home/kali/.local/lib/python3.11/site-packages/nornir/core/task.py", line 99, in start
    r = self.task(self, **self.params)
        ^^^^^^^^^^^^^^^^^^^^^^^^^^^^^^
  File "/home/kali/Desktop/Nornir/2023/5.nornir_napalm/IITH/cli_inventory_nornir_napalm.py", line 13, in nornir_napalm_cli_commands_example
    task.run(task=napalm_cli, commands=[command])
  File "/home/kali/.local/lib/python3.11/site-packages/nornir/core/task.py", line 174, in run
    raise NornirSubTaskError(task=run_task, result=r)
nornir.core.exceptions.NornirSubTaskError: Subtask: napalm_cli (failed)


2024-04-19 00:33:19,721 - nornir.core.task -    ERROR -      start() - Host 'BHN-A-9F-SW': task 'napalm_cli' failed with traceback:
Traceback (most recent call last):
  File "/home/kali/.local/lib/python3.11/site-packages/netmiko/base_connection.py", line 1137, in establish_connection
    self.remote_conn_pre.connect(**ssh_connect_params)
  File "/usr/lib/python3/dist-packages/paramiko/client.py", line 450, in connect
    self._auth(
  File "/usr/lib/python3/dist-packages/paramiko/client.py", line 781, in _auth
    raise saved_exception
  File "/usr/lib/python3/dist-packages/paramiko/client.py", line 768, in _auth
    self._transport.auth_password(username, password)
  File "/usr/lib/python3/dist-packages/paramiko/transport.py", line 1564, in auth_password
    return self.auth_handler.wait_for_response(my_event)
           ^^^^^^^^^^^^^^^^^^^^^^^^^^^^^^^^^^^^^^^^^^^^^
  File "/usr/lib/python3/dist-packages/paramiko/auth_handler.py", line 259, in wait_for_response
    raise e
paramiko.ssh_exception.AuthenticationException: Authentication failed.

During handling of the above exception, another exception occurred:

Traceback (most recent call last):
  File "/home/kali/.local/lib/python3.11/site-packages/nornir/core/task.py", line 99, in start
    r = self.task(self, **self.params)
        ^^^^^^^^^^^^^^^^^^^^^^^^^^^^^^
  File "/home/kali/.local/lib/python3.11/site-packages/nornir_napalm/plugins/tasks/napalm_cli.py", line 19, in napalm_cli
    device = task.host.get_connection(CONNECTION_NAME, task.nornir.config)
             ^^^^^^^^^^^^^^^^^^^^^^^^^^^^^^^^^^^^^^^^^^^^^^^^^^^^^^^^^^^^^
  File "/home/kali/.local/lib/python3.11/site-packages/nornir/core/inventory.py", line 494, in get_connection
    self.open_connection(
  File "/home/kali/.local/lib/python3.11/site-packages/nornir/core/inventory.py", line 546, in open_connection
    conn_obj.open(
  File "/home/kali/.local/lib/python3.11/site-packages/nornir_napalm/plugins/connections/__init__.py", line 57, in open
    connection.open()
  File "/home/kali/.local/lib/python3.11/site-packages/napalm/ios/ios.py", line 173, in open
    self.device = self._netmiko_open(
                  ^^^^^^^^^^^^^^^^^^^
  File "/home/kali/.local/lib/python3.11/site-packages/napalm/base/base.py", line 114, in _netmiko_open
    self._netmiko_device = ConnectHandler(
                           ^^^^^^^^^^^^^^^
  File "/home/kali/.local/lib/python3.11/site-packages/netmiko/ssh_dispatcher.py", line 399, in ConnectHandler
    return ConnectionClass(*args, **kwargs)
           ^^^^^^^^^^^^^^^^^^^^^^^^^^^^^^^^
  File "/home/kali/.local/lib/python3.11/site-packages/netmiko/base_connection.py", line 488, in __init__
    self._open()
  File "/home/kali/.local/lib/python3.11/site-packages/netmiko/base_connection.py", line 493, in _open
    self.establish_connection()
  File "/home/kali/.local/lib/python3.11/site-packages/netmiko/base_connection.py", line 1174, in establish_connection
    raise NetmikoAuthenticationException(msg)
netmiko.exceptions.NetmikoAuthenticationException: Authentication to device failed.

Common causes of this problem are:
1. Invalid username and password
2. Incorrect SSH-key file
3. Connecting to the wrong device

Device settings: cisco_ios 10.5.48.54:22


Authentication failed.

2024-04-19 00:33:19,722 - nornir.core.task -    ERROR -      start() - Host 'BHN-A-9F-SW': task 'nornir_napalm_cli_commands_example' failed with traceback:
Traceback (most recent call last):
  File "/home/kali/.local/lib/python3.11/site-packages/nornir/core/task.py", line 99, in start
    r = self.task(self, **self.params)
        ^^^^^^^^^^^^^^^^^^^^^^^^^^^^^^
  File "/home/kali/Desktop/Nornir/2023/5.nornir_napalm/IITH/cli_inventory_nornir_napalm.py", line 13, in nornir_napalm_cli_commands_example
    task.run(task=napalm_cli, commands=[command])
  File "/home/kali/.local/lib/python3.11/site-packages/nornir/core/task.py", line 174, in run
    raise NornirSubTaskError(task=run_task, result=r)
nornir.core.exceptions.NornirSubTaskError: Subtask: napalm_cli (failed)


2024-04-19 00:33:19,723 - nornir.core.task -    ERROR -      start() - Host 'BHN-A-3F-SW': task 'napalm_cli' failed with traceback:
Traceback (most recent call last):
  File "/home/kali/.local/lib/python3.11/site-packages/netmiko/base_connection.py", line 1137, in establish_connection
    self.remote_conn_pre.connect(**ssh_connect_params)
  File "/usr/lib/python3/dist-packages/paramiko/client.py", line 450, in connect
    self._auth(
  File "/usr/lib/python3/dist-packages/paramiko/client.py", line 781, in _auth
    raise saved_exception
  File "/usr/lib/python3/dist-packages/paramiko/client.py", line 768, in _auth
    self._transport.auth_password(username, password)
  File "/usr/lib/python3/dist-packages/paramiko/transport.py", line 1564, in auth_password
    return self.auth_handler.wait_for_response(my_event)
           ^^^^^^^^^^^^^^^^^^^^^^^^^^^^^^^^^^^^^^^^^^^^^
  File "/usr/lib/python3/dist-packages/paramiko/auth_handler.py", line 259, in wait_for_response
    raise e
paramiko.ssh_exception.AuthenticationException: Authentication failed.

During handling of the above exception, another exception occurred:

Traceback (most recent call last):
  File "/home/kali/.local/lib/python3.11/site-packages/nornir/core/task.py", line 99, in start
    r = self.task(self, **self.params)
        ^^^^^^^^^^^^^^^^^^^^^^^^^^^^^^
  File "/home/kali/.local/lib/python3.11/site-packages/nornir_napalm/plugins/tasks/napalm_cli.py", line 19, in napalm_cli
    device = task.host.get_connection(CONNECTION_NAME, task.nornir.config)
             ^^^^^^^^^^^^^^^^^^^^^^^^^^^^^^^^^^^^^^^^^^^^^^^^^^^^^^^^^^^^^
  File "/home/kali/.local/lib/python3.11/site-packages/nornir/core/inventory.py", line 494, in get_connection
    self.open_connection(
  File "/home/kali/.local/lib/python3.11/site-packages/nornir/core/inventory.py", line 546, in open_connection
    conn_obj.open(
  File "/home/kali/.local/lib/python3.11/site-packages/nornir_napalm/plugins/connections/__init__.py", line 57, in open
    connection.open()
  File "/home/kali/.local/lib/python3.11/site-packages/napalm/ios/ios.py", line 173, in open
    self.device = self._netmiko_open(
                  ^^^^^^^^^^^^^^^^^^^
  File "/home/kali/.local/lib/python3.11/site-packages/napalm/base/base.py", line 114, in _netmiko_open
    self._netmiko_device = ConnectHandler(
                           ^^^^^^^^^^^^^^^
  File "/home/kali/.local/lib/python3.11/site-packages/netmiko/ssh_dispatcher.py", line 399, in ConnectHandler
    return ConnectionClass(*args, **kwargs)
           ^^^^^^^^^^^^^^^^^^^^^^^^^^^^^^^^
  File "/home/kali/.local/lib/python3.11/site-packages/netmiko/base_connection.py", line 488, in __init__
    self._open()
  File "/home/kali/.local/lib/python3.11/site-packages/netmiko/base_connection.py", line 493, in _open
    self.establish_connection()
  File "/home/kali/.local/lib/python3.11/site-packages/netmiko/base_connection.py", line 1174, in establish_connection
    raise NetmikoAuthenticationException(msg)
netmiko.exceptions.NetmikoAuthenticationException: Authentication to device failed.

Common causes of this problem are:
1. Invalid username and password
2. Incorrect SSH-key file
3. Connecting to the wrong device

Device settings: cisco_ios 10.5.48.52:22


Authentication failed.

2024-04-19 00:33:19,723 - nornir.core.task -    ERROR -      start() - Host 'BHN-A-3F-SW': task 'nornir_napalm_cli_commands_example' failed with traceback:
Traceback (most recent call last):
  File "/home/kali/.local/lib/python3.11/site-packages/nornir/core/task.py", line 99, in start
    r = self.task(self, **self.params)
        ^^^^^^^^^^^^^^^^^^^^^^^^^^^^^^
  File "/home/kali/Desktop/Nornir/2023/5.nornir_napalm/IITH/cli_inventory_nornir_napalm.py", line 13, in nornir_napalm_cli_commands_example
    task.run(task=napalm_cli, commands=[command])
  File "/home/kali/.local/lib/python3.11/site-packages/nornir/core/task.py", line 174, in run
    raise NornirSubTaskError(task=run_task, result=r)
nornir.core.exceptions.NornirSubTaskError: Subtask: napalm_cli (failed)


2024-04-19 00:33:19,725 - nornir.core.task -    ERROR -      start() - Host 'BHN-B-3F-SW': task 'napalm_cli' failed with traceback:
Traceback (most recent call last):
  File "/home/kali/.local/lib/python3.11/site-packages/netmiko/base_connection.py", line 1137, in establish_connection
    self.remote_conn_pre.connect(**ssh_connect_params)
  File "/usr/lib/python3/dist-packages/paramiko/client.py", line 450, in connect
    self._auth(
  File "/usr/lib/python3/dist-packages/paramiko/client.py", line 781, in _auth
    raise saved_exception
  File "/usr/lib/python3/dist-packages/paramiko/client.py", line 768, in _auth
    self._transport.auth_password(username, password)
  File "/usr/lib/python3/dist-packages/paramiko/transport.py", line 1564, in auth_password
    return self.auth_handler.wait_for_response(my_event)
           ^^^^^^^^^^^^^^^^^^^^^^^^^^^^^^^^^^^^^^^^^^^^^
  File "/usr/lib/python3/dist-packages/paramiko/auth_handler.py", line 259, in wait_for_response
    raise e
paramiko.ssh_exception.AuthenticationException: Authentication failed.

During handling of the above exception, another exception occurred:

Traceback (most recent call last):
  File "/home/kali/.local/lib/python3.11/site-packages/nornir/core/task.py", line 99, in start
    r = self.task(self, **self.params)
        ^^^^^^^^^^^^^^^^^^^^^^^^^^^^^^
  File "/home/kali/.local/lib/python3.11/site-packages/nornir_napalm/plugins/tasks/napalm_cli.py", line 19, in napalm_cli
    device = task.host.get_connection(CONNECTION_NAME, task.nornir.config)
             ^^^^^^^^^^^^^^^^^^^^^^^^^^^^^^^^^^^^^^^^^^^^^^^^^^^^^^^^^^^^^
  File "/home/kali/.local/lib/python3.11/site-packages/nornir/core/inventory.py", line 494, in get_connection
    self.open_connection(
  File "/home/kali/.local/lib/python3.11/site-packages/nornir/core/inventory.py", line 546, in open_connection
    conn_obj.open(
  File "/home/kali/.local/lib/python3.11/site-packages/nornir_napalm/plugins/connections/__init__.py", line 57, in open
    connection.open()
  File "/home/kali/.local/lib/python3.11/site-packages/napalm/ios/ios.py", line 173, in open
    self.device = self._netmiko_open(
                  ^^^^^^^^^^^^^^^^^^^
  File "/home/kali/.local/lib/python3.11/site-packages/napalm/base/base.py", line 114, in _netmiko_open
    self._netmiko_device = ConnectHandler(
                           ^^^^^^^^^^^^^^^
  File "/home/kali/.local/lib/python3.11/site-packages/netmiko/ssh_dispatcher.py", line 399, in ConnectHandler
    return ConnectionClass(*args, **kwargs)
           ^^^^^^^^^^^^^^^^^^^^^^^^^^^^^^^^
  File "/home/kali/.local/lib/python3.11/site-packages/netmiko/base_connection.py", line 488, in __init__
    self._open()
  File "/home/kali/.local/lib/python3.11/site-packages/netmiko/base_connection.py", line 493, in _open
    self.establish_connection()
  File "/home/kali/.local/lib/python3.11/site-packages/netmiko/base_connection.py", line 1174, in establish_connection
    raise NetmikoAuthenticationException(msg)
netmiko.exceptions.NetmikoAuthenticationException: Authentication to device failed.

Common causes of this problem are:
1. Invalid username and password
2. Incorrect SSH-key file
3. Connecting to the wrong device

Device settings: cisco_ios 10.5.48.57:22


Authentication failed.

2024-04-19 00:33:19,725 - nornir.core.task -    ERROR -      start() - Host 'BHN-B-3F-SW': task 'nornir_napalm_cli_commands_example' failed with traceback:
Traceback (most recent call last):
  File "/home/kali/.local/lib/python3.11/site-packages/nornir/core/task.py", line 99, in start
    r = self.task(self, **self.params)
        ^^^^^^^^^^^^^^^^^^^^^^^^^^^^^^
  File "/home/kali/Desktop/Nornir/2023/5.nornir_napalm/IITH/cli_inventory_nornir_napalm.py", line 13, in nornir_napalm_cli_commands_example
    task.run(task=napalm_cli, commands=[command])
  File "/home/kali/.local/lib/python3.11/site-packages/nornir/core/task.py", line 174, in run
    raise NornirSubTaskError(task=run_task, result=r)
nornir.core.exceptions.NornirSubTaskError: Subtask: napalm_cli (failed)


2024-04-19 00:33:19,901 - nornir.core.task -    ERROR -      start() - Host 'BHN-B-6F-SW': task 'napalm_cli' failed with traceback:
Traceback (most recent call last):
  File "/home/kali/.local/lib/python3.11/site-packages/netmiko/base_connection.py", line 1137, in establish_connection
    self.remote_conn_pre.connect(**ssh_connect_params)
  File "/usr/lib/python3/dist-packages/paramiko/client.py", line 450, in connect
    self._auth(
  File "/usr/lib/python3/dist-packages/paramiko/client.py", line 781, in _auth
    raise saved_exception
  File "/usr/lib/python3/dist-packages/paramiko/client.py", line 768, in _auth
    self._transport.auth_password(username, password)
  File "/usr/lib/python3/dist-packages/paramiko/transport.py", line 1564, in auth_password
    return self.auth_handler.wait_for_response(my_event)
           ^^^^^^^^^^^^^^^^^^^^^^^^^^^^^^^^^^^^^^^^^^^^^
  File "/usr/lib/python3/dist-packages/paramiko/auth_handler.py", line 259, in wait_for_response
    raise e
paramiko.ssh_exception.AuthenticationException: Authentication failed.

During handling of the above exception, another exception occurred:

Traceback (most recent call last):
  File "/home/kali/.local/lib/python3.11/site-packages/nornir/core/task.py", line 99, in start
    r = self.task(self, **self.params)
        ^^^^^^^^^^^^^^^^^^^^^^^^^^^^^^
  File "/home/kali/.local/lib/python3.11/site-packages/nornir_napalm/plugins/tasks/napalm_cli.py", line 19, in napalm_cli
    device = task.host.get_connection(CONNECTION_NAME, task.nornir.config)
             ^^^^^^^^^^^^^^^^^^^^^^^^^^^^^^^^^^^^^^^^^^^^^^^^^^^^^^^^^^^^^
  File "/home/kali/.local/lib/python3.11/site-packages/nornir/core/inventory.py", line 494, in get_connection
    self.open_connection(
  File "/home/kali/.local/lib/python3.11/site-packages/nornir/core/inventory.py", line 546, in open_connection
    conn_obj.open(
  File "/home/kali/.local/lib/python3.11/site-packages/nornir_napalm/plugins/connections/__init__.py", line 57, in open
    connection.open()
  File "/home/kali/.local/lib/python3.11/site-packages/napalm/ios/ios.py", line 173, in open
    self.device = self._netmiko_open(
                  ^^^^^^^^^^^^^^^^^^^
  File "/home/kali/.local/lib/python3.11/site-packages/napalm/base/base.py", line 114, in _netmiko_open
    self._netmiko_device = ConnectHandler(
                           ^^^^^^^^^^^^^^^
  File "/home/kali/.local/lib/python3.11/site-packages/netmiko/ssh_dispatcher.py", line 399, in ConnectHandler
    return ConnectionClass(*args, **kwargs)
           ^^^^^^^^^^^^^^^^^^^^^^^^^^^^^^^^
  File "/home/kali/.local/lib/python3.11/site-packages/netmiko/base_connection.py", line 488, in __init__
    self._open()
  File "/home/kali/.local/lib/python3.11/site-packages/netmiko/base_connection.py", line 493, in _open
    self.establish_connection()
  File "/home/kali/.local/lib/python3.11/site-packages/netmiko/base_connection.py", line 1174, in establish_connection
    raise NetmikoAuthenticationException(msg)
netmiko.exceptions.NetmikoAuthenticationException: Authentication to device failed.

Common causes of this problem are:
1. Invalid username and password
2. Incorrect SSH-key file
3. Connecting to the wrong device

Device settings: cisco_ios 10.5.48.58:22


Authentication failed.

2024-04-19 00:33:19,902 - nornir.core.task -    ERROR -      start() - Host 'BHN-B-6F-SW': task 'nornir_napalm_cli_commands_example' failed with traceback:
Traceback (most recent call last):
  File "/home/kali/.local/lib/python3.11/site-packages/nornir/core/task.py", line 99, in start
    r = self.task(self, **self.params)
        ^^^^^^^^^^^^^^^^^^^^^^^^^^^^^^
  File "/home/kali/Desktop/Nornir/2023/5.nornir_napalm/IITH/cli_inventory_nornir_napalm.py", line 13, in nornir_napalm_cli_commands_example
    task.run(task=napalm_cli, commands=[command])
  File "/home/kali/.local/lib/python3.11/site-packages/nornir/core/task.py", line 174, in run
    raise NornirSubTaskError(task=run_task, result=r)
nornir.core.exceptions.NornirSubTaskError: Subtask: napalm_cli (failed)


2024-04-19 00:33:19,913 - nornir.core.task -    ERROR -      start() - Host 'BHN-B-9F-SW': task 'napalm_cli' failed with traceback:
Traceback (most recent call last):
  File "/home/kali/.local/lib/python3.11/site-packages/netmiko/base_connection.py", line 1137, in establish_connection
    self.remote_conn_pre.connect(**ssh_connect_params)
  File "/usr/lib/python3/dist-packages/paramiko/client.py", line 450, in connect
    self._auth(
  File "/usr/lib/python3/dist-packages/paramiko/client.py", line 781, in _auth
    raise saved_exception
  File "/usr/lib/python3/dist-packages/paramiko/client.py", line 768, in _auth
    self._transport.auth_password(username, password)
  File "/usr/lib/python3/dist-packages/paramiko/transport.py", line 1564, in auth_password
    return self.auth_handler.wait_for_response(my_event)
           ^^^^^^^^^^^^^^^^^^^^^^^^^^^^^^^^^^^^^^^^^^^^^
  File "/usr/lib/python3/dist-packages/paramiko/auth_handler.py", line 259, in wait_for_response
    raise e
paramiko.ssh_exception.AuthenticationException: Authentication failed.

During handling of the above exception, another exception occurred:

Traceback (most recent call last):
  File "/home/kali/.local/lib/python3.11/site-packages/nornir/core/task.py", line 99, in start
    r = self.task(self, **self.params)
        ^^^^^^^^^^^^^^^^^^^^^^^^^^^^^^
  File "/home/kali/.local/lib/python3.11/site-packages/nornir_napalm/plugins/tasks/napalm_cli.py", line 19, in napalm_cli
    device = task.host.get_connection(CONNECTION_NAME, task.nornir.config)
             ^^^^^^^^^^^^^^^^^^^^^^^^^^^^^^^^^^^^^^^^^^^^^^^^^^^^^^^^^^^^^
  File "/home/kali/.local/lib/python3.11/site-packages/nornir/core/inventory.py", line 494, in get_connection
    self.open_connection(
  File "/home/kali/.local/lib/python3.11/site-packages/nornir/core/inventory.py", line 546, in open_connection
    conn_obj.open(
  File "/home/kali/.local/lib/python3.11/site-packages/nornir_napalm/plugins/connections/__init__.py", line 57, in open
    connection.open()
  File "/home/kali/.local/lib/python3.11/site-packages/napalm/ios/ios.py", line 173, in open
    self.device = self._netmiko_open(
                  ^^^^^^^^^^^^^^^^^^^
  File "/home/kali/.local/lib/python3.11/site-packages/napalm/base/base.py", line 114, in _netmiko_open
    self._netmiko_device = ConnectHandler(
                           ^^^^^^^^^^^^^^^
  File "/home/kali/.local/lib/python3.11/site-packages/netmiko/ssh_dispatcher.py", line 399, in ConnectHandler
    return ConnectionClass(*args, **kwargs)
           ^^^^^^^^^^^^^^^^^^^^^^^^^^^^^^^^
  File "/home/kali/.local/lib/python3.11/site-packages/netmiko/base_connection.py", line 488, in __init__
    self._open()
  File "/home/kali/.local/lib/python3.11/site-packages/netmiko/base_connection.py", line 493, in _open
    self.establish_connection()
  File "/home/kali/.local/lib/python3.11/site-packages/netmiko/base_connection.py", line 1174, in establish_connection
    raise NetmikoAuthenticationException(msg)
netmiko.exceptions.NetmikoAuthenticationException: Authentication to device failed.

Common causes of this problem are:
1. Invalid username and password
2. Incorrect SSH-key file
3. Connecting to the wrong device

Device settings: cisco_ios 10.5.48.59:22


Authentication failed.

2024-04-19 00:33:19,914 - nornir.core.task -    ERROR -      start() - Host 'BHN-B-9F-SW': task 'nornir_napalm_cli_commands_example' failed with traceback:
Traceback (most recent call last):
  File "/home/kali/.local/lib/python3.11/site-packages/nornir/core/task.py", line 99, in start
    r = self.task(self, **self.params)
        ^^^^^^^^^^^^^^^^^^^^^^^^^^^^^^
  File "/home/kali/Desktop/Nornir/2023/5.nornir_napalm/IITH/cli_inventory_nornir_napalm.py", line 13, in nornir_napalm_cli_commands_example
    task.run(task=napalm_cli, commands=[command])
  File "/home/kali/.local/lib/python3.11/site-packages/nornir/core/task.py", line 174, in run
    raise NornirSubTaskError(task=run_task, result=r)
nornir.core.exceptions.NornirSubTaskError: Subtask: napalm_cli (failed)


2024-04-19 00:34:05,529 -  nornir.core -     INFO -        run() - Running task 'nornir_napalm_cli_commands_example' with args {} on 2 hosts
2024-04-19 00:34:25,595 -  nornir.core -     INFO -        run() - Running task 'nornir_napalm_cli_commands_example' with args {} on 8 hosts
2024-04-19 05:02:29,678 -  nornir.core -     INFO -        run() - Running task 'nornir_napalm_cli_commands_example' with args {} on 57 hosts
2024-04-19 05:02:33,807 - nornir.core.task -    ERROR -      start() - Host 'BHN-A-3F-SW': task 'napalm_cli' failed with traceback:
Traceback (most recent call last):
  File "/home/kali/.local/lib/python3.11/site-packages/netmiko/base_connection.py", line 1137, in establish_connection
    self.remote_conn_pre.connect(**ssh_connect_params)
  File "/usr/lib/python3/dist-packages/paramiko/client.py", line 450, in connect
    self._auth(
  File "/usr/lib/python3/dist-packages/paramiko/client.py", line 781, in _auth
    raise saved_exception
  File "/usr/lib/python3/dist-packages/paramiko/client.py", line 768, in _auth
    self._transport.auth_password(username, password)
  File "/usr/lib/python3/dist-packages/paramiko/transport.py", line 1564, in auth_password
    return self.auth_handler.wait_for_response(my_event)
           ^^^^^^^^^^^^^^^^^^^^^^^^^^^^^^^^^^^^^^^^^^^^^
  File "/usr/lib/python3/dist-packages/paramiko/auth_handler.py", line 259, in wait_for_response
    raise e
paramiko.ssh_exception.AuthenticationException: Authentication failed.

During handling of the above exception, another exception occurred:

Traceback (most recent call last):
  File "/home/kali/.local/lib/python3.11/site-packages/nornir/core/task.py", line 99, in start
    r = self.task(self, **self.params)
        ^^^^^^^^^^^^^^^^^^^^^^^^^^^^^^
  File "/home/kali/.local/lib/python3.11/site-packages/nornir_napalm/plugins/tasks/napalm_cli.py", line 19, in napalm_cli
    device = task.host.get_connection(CONNECTION_NAME, task.nornir.config)
             ^^^^^^^^^^^^^^^^^^^^^^^^^^^^^^^^^^^^^^^^^^^^^^^^^^^^^^^^^^^^^
  File "/home/kali/.local/lib/python3.11/site-packages/nornir/core/inventory.py", line 494, in get_connection
    self.open_connection(
  File "/home/kali/.local/lib/python3.11/site-packages/nornir/core/inventory.py", line 546, in open_connection
    conn_obj.open(
  File "/home/kali/.local/lib/python3.11/site-packages/nornir_napalm/plugins/connections/__init__.py", line 57, in open
    connection.open()
  File "/home/kali/.local/lib/python3.11/site-packages/napalm/ios/ios.py", line 173, in open
    self.device = self._netmiko_open(
                  ^^^^^^^^^^^^^^^^^^^
  File "/home/kali/.local/lib/python3.11/site-packages/napalm/base/base.py", line 114, in _netmiko_open
    self._netmiko_device = ConnectHandler(
                           ^^^^^^^^^^^^^^^
  File "/home/kali/.local/lib/python3.11/site-packages/netmiko/ssh_dispatcher.py", line 399, in ConnectHandler
    return ConnectionClass(*args, **kwargs)
           ^^^^^^^^^^^^^^^^^^^^^^^^^^^^^^^^
  File "/home/kali/.local/lib/python3.11/site-packages/netmiko/base_connection.py", line 488, in __init__
    self._open()
  File "/home/kali/.local/lib/python3.11/site-packages/netmiko/base_connection.py", line 493, in _open
    self.establish_connection()
  File "/home/kali/.local/lib/python3.11/site-packages/netmiko/base_connection.py", line 1174, in establish_connection
    raise NetmikoAuthenticationException(msg)
netmiko.exceptions.NetmikoAuthenticationException: Authentication to device failed.

Common causes of this problem are:
1. Invalid username and password
2. Incorrect SSH-key file
3. Connecting to the wrong device

Device settings: cisco_ios 10.5.48.52:22


Authentication failed.

2024-04-19 05:02:33,808 - nornir.core.task -    ERROR -      start() - Host 'BHN-A-3F-SW': task 'nornir_napalm_cli_commands_example' failed with traceback:
Traceback (most recent call last):
  File "/home/kali/.local/lib/python3.11/site-packages/nornir/core/task.py", line 99, in start
    r = self.task(self, **self.params)
        ^^^^^^^^^^^^^^^^^^^^^^^^^^^^^^
  File "/home/kali/Desktop/Nornir/2023/5.nornir_napalm/IITH/cli_inventory_nornir_napalm.py", line 13, in nornir_napalm_cli_commands_example
    task.run(task=napalm_cli, commands=[command])
  File "/home/kali/.local/lib/python3.11/site-packages/nornir/core/task.py", line 174, in run
    raise NornirSubTaskError(task=run_task, result=r)
nornir.core.exceptions.NornirSubTaskError: Subtask: napalm_cli (failed)


2024-04-19 05:02:33,814 - nornir.core.task -    ERROR -      start() - Host 'BHN-A-6F-SW': task 'napalm_cli' failed with traceback:
Traceback (most recent call last):
  File "/home/kali/.local/lib/python3.11/site-packages/netmiko/base_connection.py", line 1137, in establish_connection
    self.remote_conn_pre.connect(**ssh_connect_params)
  File "/usr/lib/python3/dist-packages/paramiko/client.py", line 450, in connect
    self._auth(
  File "/usr/lib/python3/dist-packages/paramiko/client.py", line 781, in _auth
    raise saved_exception
  File "/usr/lib/python3/dist-packages/paramiko/client.py", line 768, in _auth
    self._transport.auth_password(username, password)
  File "/usr/lib/python3/dist-packages/paramiko/transport.py", line 1564, in auth_password
    return self.auth_handler.wait_for_response(my_event)
           ^^^^^^^^^^^^^^^^^^^^^^^^^^^^^^^^^^^^^^^^^^^^^
  File "/usr/lib/python3/dist-packages/paramiko/auth_handler.py", line 259, in wait_for_response
    raise e
paramiko.ssh_exception.AuthenticationException: Authentication failed.

During handling of the above exception, another exception occurred:

Traceback (most recent call last):
  File "/home/kali/.local/lib/python3.11/site-packages/nornir/core/task.py", line 99, in start
    r = self.task(self, **self.params)
        ^^^^^^^^^^^^^^^^^^^^^^^^^^^^^^
  File "/home/kali/.local/lib/python3.11/site-packages/nornir_napalm/plugins/tasks/napalm_cli.py", line 19, in napalm_cli
    device = task.host.get_connection(CONNECTION_NAME, task.nornir.config)
             ^^^^^^^^^^^^^^^^^^^^^^^^^^^^^^^^^^^^^^^^^^^^^^^^^^^^^^^^^^^^^
  File "/home/kali/.local/lib/python3.11/site-packages/nornir/core/inventory.py", line 494, in get_connection
    self.open_connection(
  File "/home/kali/.local/lib/python3.11/site-packages/nornir/core/inventory.py", line 546, in open_connection
    conn_obj.open(
  File "/home/kali/.local/lib/python3.11/site-packages/nornir_napalm/plugins/connections/__init__.py", line 57, in open
    connection.open()
  File "/home/kali/.local/lib/python3.11/site-packages/napalm/ios/ios.py", line 173, in open
    self.device = self._netmiko_open(
                  ^^^^^^^^^^^^^^^^^^^
  File "/home/kali/.local/lib/python3.11/site-packages/napalm/base/base.py", line 114, in _netmiko_open
    self._netmiko_device = ConnectHandler(
                           ^^^^^^^^^^^^^^^
  File "/home/kali/.local/lib/python3.11/site-packages/netmiko/ssh_dispatcher.py", line 399, in ConnectHandler
    return ConnectionClass(*args, **kwargs)
           ^^^^^^^^^^^^^^^^^^^^^^^^^^^^^^^^
  File "/home/kali/.local/lib/python3.11/site-packages/netmiko/base_connection.py", line 488, in __init__
    self._open()
  File "/home/kali/.local/lib/python3.11/site-packages/netmiko/base_connection.py", line 493, in _open
    self.establish_connection()
  File "/home/kali/.local/lib/python3.11/site-packages/netmiko/base_connection.py", line 1174, in establish_connection
    raise NetmikoAuthenticationException(msg)
netmiko.exceptions.NetmikoAuthenticationException: Authentication to device failed.

Common causes of this problem are:
1. Invalid username and password
2. Incorrect SSH-key file
3. Connecting to the wrong device

Device settings: cisco_ios 10.5.48.53:22


Authentication failed.

2024-04-19 05:02:33,815 - nornir.core.task -    ERROR -      start() - Host 'BHN-A-6F-SW': task 'nornir_napalm_cli_commands_example' failed with traceback:
Traceback (most recent call last):
  File "/home/kali/.local/lib/python3.11/site-packages/nornir/core/task.py", line 99, in start
    r = self.task(self, **self.params)
        ^^^^^^^^^^^^^^^^^^^^^^^^^^^^^^
  File "/home/kali/Desktop/Nornir/2023/5.nornir_napalm/IITH/cli_inventory_nornir_napalm.py", line 13, in nornir_napalm_cli_commands_example
    task.run(task=napalm_cli, commands=[command])
  File "/home/kali/.local/lib/python3.11/site-packages/nornir/core/task.py", line 174, in run
    raise NornirSubTaskError(task=run_task, result=r)
nornir.core.exceptions.NornirSubTaskError: Subtask: napalm_cli (failed)


2024-04-19 05:02:33,817 - nornir.core.task -    ERROR -      start() - Host 'BHN-A-9F-SW': task 'napalm_cli' failed with traceback:
Traceback (most recent call last):
  File "/home/kali/.local/lib/python3.11/site-packages/netmiko/base_connection.py", line 1137, in establish_connection
    self.remote_conn_pre.connect(**ssh_connect_params)
  File "/usr/lib/python3/dist-packages/paramiko/client.py", line 450, in connect
    self._auth(
  File "/usr/lib/python3/dist-packages/paramiko/client.py", line 781, in _auth
    raise saved_exception
  File "/usr/lib/python3/dist-packages/paramiko/client.py", line 768, in _auth
    self._transport.auth_password(username, password)
  File "/usr/lib/python3/dist-packages/paramiko/transport.py", line 1564, in auth_password
    return self.auth_handler.wait_for_response(my_event)
           ^^^^^^^^^^^^^^^^^^^^^^^^^^^^^^^^^^^^^^^^^^^^^
  File "/usr/lib/python3/dist-packages/paramiko/auth_handler.py", line 259, in wait_for_response
    raise e
paramiko.ssh_exception.AuthenticationException: Authentication failed.

During handling of the above exception, another exception occurred:

Traceback (most recent call last):
  File "/home/kali/.local/lib/python3.11/site-packages/nornir/core/task.py", line 99, in start
    r = self.task(self, **self.params)
        ^^^^^^^^^^^^^^^^^^^^^^^^^^^^^^
  File "/home/kali/.local/lib/python3.11/site-packages/nornir_napalm/plugins/tasks/napalm_cli.py", line 19, in napalm_cli
    device = task.host.get_connection(CONNECTION_NAME, task.nornir.config)
             ^^^^^^^^^^^^^^^^^^^^^^^^^^^^^^^^^^^^^^^^^^^^^^^^^^^^^^^^^^^^^
  File "/home/kali/.local/lib/python3.11/site-packages/nornir/core/inventory.py", line 494, in get_connection
    self.open_connection(
  File "/home/kali/.local/lib/python3.11/site-packages/nornir/core/inventory.py", line 546, in open_connection
    conn_obj.open(
  File "/home/kali/.local/lib/python3.11/site-packages/nornir_napalm/plugins/connections/__init__.py", line 57, in open
    connection.open()
  File "/home/kali/.local/lib/python3.11/site-packages/napalm/ios/ios.py", line 173, in open
    self.device = self._netmiko_open(
                  ^^^^^^^^^^^^^^^^^^^
  File "/home/kali/.local/lib/python3.11/site-packages/napalm/base/base.py", line 114, in _netmiko_open
    self._netmiko_device = ConnectHandler(
                           ^^^^^^^^^^^^^^^
  File "/home/kali/.local/lib/python3.11/site-packages/netmiko/ssh_dispatcher.py", line 399, in ConnectHandler
    return ConnectionClass(*args, **kwargs)
           ^^^^^^^^^^^^^^^^^^^^^^^^^^^^^^^^
  File "/home/kali/.local/lib/python3.11/site-packages/netmiko/base_connection.py", line 488, in __init__
    self._open()
  File "/home/kali/.local/lib/python3.11/site-packages/netmiko/base_connection.py", line 493, in _open
    self.establish_connection()
  File "/home/kali/.local/lib/python3.11/site-packages/netmiko/base_connection.py", line 1174, in establish_connection
    raise NetmikoAuthenticationException(msg)
netmiko.exceptions.NetmikoAuthenticationException: Authentication to device failed.

Common causes of this problem are:
1. Invalid username and password
2. Incorrect SSH-key file
3. Connecting to the wrong device

Device settings: cisco_ios 10.5.48.54:22


Authentication failed.

2024-04-19 05:02:33,818 - nornir.core.task -    ERROR -      start() - Host 'BHN-A-9F-SW': task 'nornir_napalm_cli_commands_example' failed with traceback:
Traceback (most recent call last):
  File "/home/kali/.local/lib/python3.11/site-packages/nornir/core/task.py", line 99, in start
    r = self.task(self, **self.params)
        ^^^^^^^^^^^^^^^^^^^^^^^^^^^^^^
  File "/home/kali/Desktop/Nornir/2023/5.nornir_napalm/IITH/cli_inventory_nornir_napalm.py", line 13, in nornir_napalm_cli_commands_example
    task.run(task=napalm_cli, commands=[command])
  File "/home/kali/.local/lib/python3.11/site-packages/nornir/core/task.py", line 174, in run
    raise NornirSubTaskError(task=run_task, result=r)
nornir.core.exceptions.NornirSubTaskError: Subtask: napalm_cli (failed)


2024-04-19 05:02:33,991 - nornir.core.task -    ERROR -      start() - Host 'BHN-B-6F-SW': task 'napalm_cli' failed with traceback:
Traceback (most recent call last):
  File "/home/kali/.local/lib/python3.11/site-packages/netmiko/base_connection.py", line 1137, in establish_connection
    self.remote_conn_pre.connect(**ssh_connect_params)
  File "/usr/lib/python3/dist-packages/paramiko/client.py", line 450, in connect
    self._auth(
  File "/usr/lib/python3/dist-packages/paramiko/client.py", line 781, in _auth
    raise saved_exception
  File "/usr/lib/python3/dist-packages/paramiko/client.py", line 768, in _auth
    self._transport.auth_password(username, password)
  File "/usr/lib/python3/dist-packages/paramiko/transport.py", line 1564, in auth_password
    return self.auth_handler.wait_for_response(my_event)
           ^^^^^^^^^^^^^^^^^^^^^^^^^^^^^^^^^^^^^^^^^^^^^
  File "/usr/lib/python3/dist-packages/paramiko/auth_handler.py", line 259, in wait_for_response
    raise e
paramiko.ssh_exception.AuthenticationException: Authentication failed.

During handling of the above exception, another exception occurred:

Traceback (most recent call last):
  File "/home/kali/.local/lib/python3.11/site-packages/nornir/core/task.py", line 99, in start
    r = self.task(self, **self.params)
        ^^^^^^^^^^^^^^^^^^^^^^^^^^^^^^
  File "/home/kali/.local/lib/python3.11/site-packages/nornir_napalm/plugins/tasks/napalm_cli.py", line 19, in napalm_cli
    device = task.host.get_connection(CONNECTION_NAME, task.nornir.config)
             ^^^^^^^^^^^^^^^^^^^^^^^^^^^^^^^^^^^^^^^^^^^^^^^^^^^^^^^^^^^^^
  File "/home/kali/.local/lib/python3.11/site-packages/nornir/core/inventory.py", line 494, in get_connection
    self.open_connection(
  File "/home/kali/.local/lib/python3.11/site-packages/nornir/core/inventory.py", line 546, in open_connection
    conn_obj.open(
  File "/home/kali/.local/lib/python3.11/site-packages/nornir_napalm/plugins/connections/__init__.py", line 57, in open
    connection.open()
  File "/home/kali/.local/lib/python3.11/site-packages/napalm/ios/ios.py", line 173, in open
    self.device = self._netmiko_open(
                  ^^^^^^^^^^^^^^^^^^^
  File "/home/kali/.local/lib/python3.11/site-packages/napalm/base/base.py", line 114, in _netmiko_open
    self._netmiko_device = ConnectHandler(
                           ^^^^^^^^^^^^^^^
  File "/home/kali/.local/lib/python3.11/site-packages/netmiko/ssh_dispatcher.py", line 399, in ConnectHandler
    return ConnectionClass(*args, **kwargs)
           ^^^^^^^^^^^^^^^^^^^^^^^^^^^^^^^^
  File "/home/kali/.local/lib/python3.11/site-packages/netmiko/base_connection.py", line 488, in __init__
    self._open()
  File "/home/kali/.local/lib/python3.11/site-packages/netmiko/base_connection.py", line 493, in _open
    self.establish_connection()
  File "/home/kali/.local/lib/python3.11/site-packages/netmiko/base_connection.py", line 1174, in establish_connection
    raise NetmikoAuthenticationException(msg)
netmiko.exceptions.NetmikoAuthenticationException: Authentication to device failed.

Common causes of this problem are:
1. Invalid username and password
2. Incorrect SSH-key file
3. Connecting to the wrong device

Device settings: cisco_ios 10.5.48.58:22


Authentication failed.

2024-04-19 05:02:33,992 - nornir.core.task -    ERROR -      start() - Host 'BHN-B-6F-SW': task 'nornir_napalm_cli_commands_example' failed with traceback:
Traceback (most recent call last):
  File "/home/kali/.local/lib/python3.11/site-packages/nornir/core/task.py", line 99, in start
    r = self.task(self, **self.params)
        ^^^^^^^^^^^^^^^^^^^^^^^^^^^^^^
  File "/home/kali/Desktop/Nornir/2023/5.nornir_napalm/IITH/cli_inventory_nornir_napalm.py", line 13, in nornir_napalm_cli_commands_example
    task.run(task=napalm_cli, commands=[command])
  File "/home/kali/.local/lib/python3.11/site-packages/nornir/core/task.py", line 174, in run
    raise NornirSubTaskError(task=run_task, result=r)
nornir.core.exceptions.NornirSubTaskError: Subtask: napalm_cli (failed)


2024-04-19 05:02:34,185 - nornir.core.task -    ERROR -      start() - Host 'BHN-B-9F-SW': task 'napalm_cli' failed with traceback:
Traceback (most recent call last):
  File "/home/kali/.local/lib/python3.11/site-packages/netmiko/base_connection.py", line 1137, in establish_connection
    self.remote_conn_pre.connect(**ssh_connect_params)
  File "/usr/lib/python3/dist-packages/paramiko/client.py", line 450, in connect
    self._auth(
  File "/usr/lib/python3/dist-packages/paramiko/client.py", line 781, in _auth
    raise saved_exception
  File "/usr/lib/python3/dist-packages/paramiko/client.py", line 768, in _auth
    self._transport.auth_password(username, password)
  File "/usr/lib/python3/dist-packages/paramiko/transport.py", line 1564, in auth_password
    return self.auth_handler.wait_for_response(my_event)
           ^^^^^^^^^^^^^^^^^^^^^^^^^^^^^^^^^^^^^^^^^^^^^
  File "/usr/lib/python3/dist-packages/paramiko/auth_handler.py", line 259, in wait_for_response
    raise e
paramiko.ssh_exception.AuthenticationException: Authentication failed.

During handling of the above exception, another exception occurred:

Traceback (most recent call last):
  File "/home/kali/.local/lib/python3.11/site-packages/nornir/core/task.py", line 99, in start
    r = self.task(self, **self.params)
        ^^^^^^^^^^^^^^^^^^^^^^^^^^^^^^
  File "/home/kali/.local/lib/python3.11/site-packages/nornir_napalm/plugins/tasks/napalm_cli.py", line 19, in napalm_cli
    device = task.host.get_connection(CONNECTION_NAME, task.nornir.config)
             ^^^^^^^^^^^^^^^^^^^^^^^^^^^^^^^^^^^^^^^^^^^^^^^^^^^^^^^^^^^^^
  File "/home/kali/.local/lib/python3.11/site-packages/nornir/core/inventory.py", line 494, in get_connection
    self.open_connection(
  File "/home/kali/.local/lib/python3.11/site-packages/nornir/core/inventory.py", line 546, in open_connection
    conn_obj.open(
  File "/home/kali/.local/lib/python3.11/site-packages/nornir_napalm/plugins/connections/__init__.py", line 57, in open
    connection.open()
  File "/home/kali/.local/lib/python3.11/site-packages/napalm/ios/ios.py", line 173, in open
    self.device = self._netmiko_open(
                  ^^^^^^^^^^^^^^^^^^^
  File "/home/kali/.local/lib/python3.11/site-packages/napalm/base/base.py", line 114, in _netmiko_open
    self._netmiko_device = ConnectHandler(
                           ^^^^^^^^^^^^^^^
  File "/home/kali/.local/lib/python3.11/site-packages/netmiko/ssh_dispatcher.py", line 399, in ConnectHandler
    return ConnectionClass(*args, **kwargs)
           ^^^^^^^^^^^^^^^^^^^^^^^^^^^^^^^^
  File "/home/kali/.local/lib/python3.11/site-packages/netmiko/base_connection.py", line 488, in __init__
    self._open()
  File "/home/kali/.local/lib/python3.11/site-packages/netmiko/base_connection.py", line 493, in _open
    self.establish_connection()
  File "/home/kali/.local/lib/python3.11/site-packages/netmiko/base_connection.py", line 1174, in establish_connection
    raise NetmikoAuthenticationException(msg)
netmiko.exceptions.NetmikoAuthenticationException: Authentication to device failed.

Common causes of this problem are:
1. Invalid username and password
2. Incorrect SSH-key file
3. Connecting to the wrong device

Device settings: cisco_ios 10.5.48.59:22


Authentication failed.

2024-04-19 05:02:34,186 - nornir.core.task -    ERROR -      start() - Host 'BHN-B-9F-SW': task 'nornir_napalm_cli_commands_example' failed with traceback:
Traceback (most recent call last):
  File "/home/kali/.local/lib/python3.11/site-packages/nornir/core/task.py", line 99, in start
    r = self.task(self, **self.params)
        ^^^^^^^^^^^^^^^^^^^^^^^^^^^^^^
  File "/home/kali/Desktop/Nornir/2023/5.nornir_napalm/IITH/cli_inventory_nornir_napalm.py", line 13, in nornir_napalm_cli_commands_example
    task.run(task=napalm_cli, commands=[command])
  File "/home/kali/.local/lib/python3.11/site-packages/nornir/core/task.py", line 174, in run
    raise NornirSubTaskError(task=run_task, result=r)
nornir.core.exceptions.NornirSubTaskError: Subtask: napalm_cli (failed)


2024-04-19 05:02:34,209 - nornir.core.task -    ERROR -      start() - Host 'BHN-B-3F-SW': task 'napalm_cli' failed with traceback:
Traceback (most recent call last):
  File "/home/kali/.local/lib/python3.11/site-packages/netmiko/base_connection.py", line 1137, in establish_connection
    self.remote_conn_pre.connect(**ssh_connect_params)
  File "/usr/lib/python3/dist-packages/paramiko/client.py", line 450, in connect
    self._auth(
  File "/usr/lib/python3/dist-packages/paramiko/client.py", line 781, in _auth
    raise saved_exception
  File "/usr/lib/python3/dist-packages/paramiko/client.py", line 768, in _auth
    self._transport.auth_password(username, password)
  File "/usr/lib/python3/dist-packages/paramiko/transport.py", line 1564, in auth_password
    return self.auth_handler.wait_for_response(my_event)
           ^^^^^^^^^^^^^^^^^^^^^^^^^^^^^^^^^^^^^^^^^^^^^
  File "/usr/lib/python3/dist-packages/paramiko/auth_handler.py", line 259, in wait_for_response
    raise e
paramiko.ssh_exception.AuthenticationException: Authentication failed.

During handling of the above exception, another exception occurred:

Traceback (most recent call last):
  File "/home/kali/.local/lib/python3.11/site-packages/nornir/core/task.py", line 99, in start
    r = self.task(self, **self.params)
        ^^^^^^^^^^^^^^^^^^^^^^^^^^^^^^
  File "/home/kali/.local/lib/python3.11/site-packages/nornir_napalm/plugins/tasks/napalm_cli.py", line 19, in napalm_cli
    device = task.host.get_connection(CONNECTION_NAME, task.nornir.config)
             ^^^^^^^^^^^^^^^^^^^^^^^^^^^^^^^^^^^^^^^^^^^^^^^^^^^^^^^^^^^^^
  File "/home/kali/.local/lib/python3.11/site-packages/nornir/core/inventory.py", line 494, in get_connection
    self.open_connection(
  File "/home/kali/.local/lib/python3.11/site-packages/nornir/core/inventory.py", line 546, in open_connection
    conn_obj.open(
  File "/home/kali/.local/lib/python3.11/site-packages/nornir_napalm/plugins/connections/__init__.py", line 57, in open
    connection.open()
  File "/home/kali/.local/lib/python3.11/site-packages/napalm/ios/ios.py", line 173, in open
    self.device = self._netmiko_open(
                  ^^^^^^^^^^^^^^^^^^^
  File "/home/kali/.local/lib/python3.11/site-packages/napalm/base/base.py", line 114, in _netmiko_open
    self._netmiko_device = ConnectHandler(
                           ^^^^^^^^^^^^^^^
  File "/home/kali/.local/lib/python3.11/site-packages/netmiko/ssh_dispatcher.py", line 399, in ConnectHandler
    return ConnectionClass(*args, **kwargs)
           ^^^^^^^^^^^^^^^^^^^^^^^^^^^^^^^^
  File "/home/kali/.local/lib/python3.11/site-packages/netmiko/base_connection.py", line 488, in __init__
    self._open()
  File "/home/kali/.local/lib/python3.11/site-packages/netmiko/base_connection.py", line 493, in _open
    self.establish_connection()
  File "/home/kali/.local/lib/python3.11/site-packages/netmiko/base_connection.py", line 1174, in establish_connection
    raise NetmikoAuthenticationException(msg)
netmiko.exceptions.NetmikoAuthenticationException: Authentication to device failed.

Common causes of this problem are:
1. Invalid username and password
2. Incorrect SSH-key file
3. Connecting to the wrong device

Device settings: cisco_ios 10.5.48.57:22


Authentication failed.

2024-04-19 05:02:34,210 - nornir.core.task -    ERROR -      start() - Host 'BHN-B-3F-SW': task 'nornir_napalm_cli_commands_example' failed with traceback:
Traceback (most recent call last):
  File "/home/kali/.local/lib/python3.11/site-packages/nornir/core/task.py", line 99, in start
    r = self.task(self, **self.params)
        ^^^^^^^^^^^^^^^^^^^^^^^^^^^^^^
  File "/home/kali/Desktop/Nornir/2023/5.nornir_napalm/IITH/cli_inventory_nornir_napalm.py", line 13, in nornir_napalm_cli_commands_example
    task.run(task=napalm_cli, commands=[command])
  File "/home/kali/.local/lib/python3.11/site-packages/nornir/core/task.py", line 174, in run
    raise NornirSubTaskError(task=run_task, result=r)
nornir.core.exceptions.NornirSubTaskError: Subtask: napalm_cli (failed)


2024-04-19 05:02:54,982 -  nornir.core -     INFO -        run() - Running task 'nornir_napalm_cli_commands_example' with args {} on 16 hosts
2024-04-19 05:03:27,165 -  nornir.core -     INFO -        run() - Running task 'nornir_napalm_cli_commands_example' with args {} on 32 hosts
2024-04-19 05:04:00,789 -  nornir.core -     INFO -        run() - Running task 'nornir_napalm_cli_commands_example' with args {} on 48 hosts
2024-04-19 05:04:04,902 - nornir.core.task -    ERROR -      start() - Host 'BHN-A-6F-SW': task 'napalm_cli' failed with traceback:
Traceback (most recent call last):
  File "/home/kali/.local/lib/python3.11/site-packages/netmiko/base_connection.py", line 1137, in establish_connection
    self.remote_conn_pre.connect(**ssh_connect_params)
  File "/usr/lib/python3/dist-packages/paramiko/client.py", line 450, in connect
    self._auth(
  File "/usr/lib/python3/dist-packages/paramiko/client.py", line 781, in _auth
    raise saved_exception
  File "/usr/lib/python3/dist-packages/paramiko/client.py", line 768, in _auth
    self._transport.auth_password(username, password)
  File "/usr/lib/python3/dist-packages/paramiko/transport.py", line 1564, in auth_password
    return self.auth_handler.wait_for_response(my_event)
           ^^^^^^^^^^^^^^^^^^^^^^^^^^^^^^^^^^^^^^^^^^^^^
  File "/usr/lib/python3/dist-packages/paramiko/auth_handler.py", line 259, in wait_for_response
    raise e
paramiko.ssh_exception.AuthenticationException: Authentication failed.

During handling of the above exception, another exception occurred:

Traceback (most recent call last):
  File "/home/kali/.local/lib/python3.11/site-packages/nornir/core/task.py", line 99, in start
    r = self.task(self, **self.params)
        ^^^^^^^^^^^^^^^^^^^^^^^^^^^^^^
  File "/home/kali/.local/lib/python3.11/site-packages/nornir_napalm/plugins/tasks/napalm_cli.py", line 19, in napalm_cli
    device = task.host.get_connection(CONNECTION_NAME, task.nornir.config)
             ^^^^^^^^^^^^^^^^^^^^^^^^^^^^^^^^^^^^^^^^^^^^^^^^^^^^^^^^^^^^^
  File "/home/kali/.local/lib/python3.11/site-packages/nornir/core/inventory.py", line 494, in get_connection
    self.open_connection(
  File "/home/kali/.local/lib/python3.11/site-packages/nornir/core/inventory.py", line 546, in open_connection
    conn_obj.open(
  File "/home/kali/.local/lib/python3.11/site-packages/nornir_napalm/plugins/connections/__init__.py", line 57, in open
    connection.open()
  File "/home/kali/.local/lib/python3.11/site-packages/napalm/ios/ios.py", line 173, in open
    self.device = self._netmiko_open(
                  ^^^^^^^^^^^^^^^^^^^
  File "/home/kali/.local/lib/python3.11/site-packages/napalm/base/base.py", line 114, in _netmiko_open
    self._netmiko_device = ConnectHandler(
                           ^^^^^^^^^^^^^^^
  File "/home/kali/.local/lib/python3.11/site-packages/netmiko/ssh_dispatcher.py", line 399, in ConnectHandler
    return ConnectionClass(*args, **kwargs)
           ^^^^^^^^^^^^^^^^^^^^^^^^^^^^^^^^
  File "/home/kali/.local/lib/python3.11/site-packages/netmiko/base_connection.py", line 488, in __init__
    self._open()
  File "/home/kali/.local/lib/python3.11/site-packages/netmiko/base_connection.py", line 493, in _open
    self.establish_connection()
  File "/home/kali/.local/lib/python3.11/site-packages/netmiko/base_connection.py", line 1174, in establish_connection
    raise NetmikoAuthenticationException(msg)
netmiko.exceptions.NetmikoAuthenticationException: Authentication to device failed.

Common causes of this problem are:
1. Invalid username and password
2. Incorrect SSH-key file
3. Connecting to the wrong device

Device settings: cisco_ios 10.5.48.53:22


Authentication failed.

2024-04-19 05:04:04,903 - nornir.core.task -    ERROR -      start() - Host 'BHN-A-6F-SW': task 'nornir_napalm_cli_commands_example' failed with traceback:
Traceback (most recent call last):
  File "/home/kali/.local/lib/python3.11/site-packages/nornir/core/task.py", line 99, in start
    r = self.task(self, **self.params)
        ^^^^^^^^^^^^^^^^^^^^^^^^^^^^^^
  File "/home/kali/Desktop/Nornir/2023/5.nornir_napalm/IITH/cli_inventory_nornir_napalm.py", line 13, in nornir_napalm_cli_commands_example
    task.run(task=napalm_cli, commands=[command])
  File "/home/kali/.local/lib/python3.11/site-packages/nornir/core/task.py", line 174, in run
    raise NornirSubTaskError(task=run_task, result=r)
nornir.core.exceptions.NornirSubTaskError: Subtask: napalm_cli (failed)


2024-04-19 05:04:04,907 - nornir.core.task -    ERROR -      start() - Host 'BHN-A-9F-SW': task 'napalm_cli' failed with traceback:
Traceback (most recent call last):
  File "/home/kali/.local/lib/python3.11/site-packages/netmiko/base_connection.py", line 1137, in establish_connection
    self.remote_conn_pre.connect(**ssh_connect_params)
  File "/usr/lib/python3/dist-packages/paramiko/client.py", line 450, in connect
    self._auth(
  File "/usr/lib/python3/dist-packages/paramiko/client.py", line 781, in _auth
    raise saved_exception
  File "/usr/lib/python3/dist-packages/paramiko/client.py", line 768, in _auth
    self._transport.auth_password(username, password)
  File "/usr/lib/python3/dist-packages/paramiko/transport.py", line 1564, in auth_password
    return self.auth_handler.wait_for_response(my_event)
           ^^^^^^^^^^^^^^^^^^^^^^^^^^^^^^^^^^^^^^^^^^^^^
  File "/usr/lib/python3/dist-packages/paramiko/auth_handler.py", line 259, in wait_for_response
    raise e
paramiko.ssh_exception.AuthenticationException: Authentication failed.

During handling of the above exception, another exception occurred:

Traceback (most recent call last):
  File "/home/kali/.local/lib/python3.11/site-packages/nornir/core/task.py", line 99, in start
    r = self.task(self, **self.params)
        ^^^^^^^^^^^^^^^^^^^^^^^^^^^^^^
  File "/home/kali/.local/lib/python3.11/site-packages/nornir_napalm/plugins/tasks/napalm_cli.py", line 19, in napalm_cli
    device = task.host.get_connection(CONNECTION_NAME, task.nornir.config)
             ^^^^^^^^^^^^^^^^^^^^^^^^^^^^^^^^^^^^^^^^^^^^^^^^^^^^^^^^^^^^^
  File "/home/kali/.local/lib/python3.11/site-packages/nornir/core/inventory.py", line 494, in get_connection
    self.open_connection(
  File "/home/kali/.local/lib/python3.11/site-packages/nornir/core/inventory.py", line 546, in open_connection
    conn_obj.open(
  File "/home/kali/.local/lib/python3.11/site-packages/nornir_napalm/plugins/connections/__init__.py", line 57, in open
    connection.open()
  File "/home/kali/.local/lib/python3.11/site-packages/napalm/ios/ios.py", line 173, in open
    self.device = self._netmiko_open(
                  ^^^^^^^^^^^^^^^^^^^
  File "/home/kali/.local/lib/python3.11/site-packages/napalm/base/base.py", line 114, in _netmiko_open
    self._netmiko_device = ConnectHandler(
                           ^^^^^^^^^^^^^^^
  File "/home/kali/.local/lib/python3.11/site-packages/netmiko/ssh_dispatcher.py", line 399, in ConnectHandler
    return ConnectionClass(*args, **kwargs)
           ^^^^^^^^^^^^^^^^^^^^^^^^^^^^^^^^
  File "/home/kali/.local/lib/python3.11/site-packages/netmiko/base_connection.py", line 488, in __init__
    self._open()
  File "/home/kali/.local/lib/python3.11/site-packages/netmiko/base_connection.py", line 493, in _open
    self.establish_connection()
  File "/home/kali/.local/lib/python3.11/site-packages/netmiko/base_connection.py", line 1174, in establish_connection
    raise NetmikoAuthenticationException(msg)
netmiko.exceptions.NetmikoAuthenticationException: Authentication to device failed.

Common causes of this problem are:
1. Invalid username and password
2. Incorrect SSH-key file
3. Connecting to the wrong device

Device settings: cisco_ios 10.5.48.54:22


Authentication failed.

2024-04-19 05:04:04,907 - nornir.core.task -    ERROR -      start() - Host 'BHN-A-9F-SW': task 'nornir_napalm_cli_commands_example' failed with traceback:
Traceback (most recent call last):
  File "/home/kali/.local/lib/python3.11/site-packages/nornir/core/task.py", line 99, in start
    r = self.task(self, **self.params)
        ^^^^^^^^^^^^^^^^^^^^^^^^^^^^^^
  File "/home/kali/Desktop/Nornir/2023/5.nornir_napalm/IITH/cli_inventory_nornir_napalm.py", line 13, in nornir_napalm_cli_commands_example
    task.run(task=napalm_cli, commands=[command])
  File "/home/kali/.local/lib/python3.11/site-packages/nornir/core/task.py", line 174, in run
    raise NornirSubTaskError(task=run_task, result=r)
nornir.core.exceptions.NornirSubTaskError: Subtask: napalm_cli (failed)


2024-04-19 05:04:04,908 - nornir.core.task -    ERROR -      start() - Host 'BHN-A-3F-SW': task 'napalm_cli' failed with traceback:
Traceback (most recent call last):
  File "/home/kali/.local/lib/python3.11/site-packages/netmiko/base_connection.py", line 1137, in establish_connection
    self.remote_conn_pre.connect(**ssh_connect_params)
  File "/usr/lib/python3/dist-packages/paramiko/client.py", line 450, in connect
    self._auth(
  File "/usr/lib/python3/dist-packages/paramiko/client.py", line 781, in _auth
    raise saved_exception
  File "/usr/lib/python3/dist-packages/paramiko/client.py", line 768, in _auth
    self._transport.auth_password(username, password)
  File "/usr/lib/python3/dist-packages/paramiko/transport.py", line 1564, in auth_password
    return self.auth_handler.wait_for_response(my_event)
           ^^^^^^^^^^^^^^^^^^^^^^^^^^^^^^^^^^^^^^^^^^^^^
  File "/usr/lib/python3/dist-packages/paramiko/auth_handler.py", line 259, in wait_for_response
    raise e
paramiko.ssh_exception.AuthenticationException: Authentication failed.

During handling of the above exception, another exception occurred:

Traceback (most recent call last):
  File "/home/kali/.local/lib/python3.11/site-packages/nornir/core/task.py", line 99, in start
    r = self.task(self, **self.params)
        ^^^^^^^^^^^^^^^^^^^^^^^^^^^^^^
  File "/home/kali/.local/lib/python3.11/site-packages/nornir_napalm/plugins/tasks/napalm_cli.py", line 19, in napalm_cli
    device = task.host.get_connection(CONNECTION_NAME, task.nornir.config)
             ^^^^^^^^^^^^^^^^^^^^^^^^^^^^^^^^^^^^^^^^^^^^^^^^^^^^^^^^^^^^^
  File "/home/kali/.local/lib/python3.11/site-packages/nornir/core/inventory.py", line 494, in get_connection
    self.open_connection(
  File "/home/kali/.local/lib/python3.11/site-packages/nornir/core/inventory.py", line 546, in open_connection
    conn_obj.open(
  File "/home/kali/.local/lib/python3.11/site-packages/nornir_napalm/plugins/connections/__init__.py", line 57, in open
    connection.open()
  File "/home/kali/.local/lib/python3.11/site-packages/napalm/ios/ios.py", line 173, in open
    self.device = self._netmiko_open(
                  ^^^^^^^^^^^^^^^^^^^
  File "/home/kali/.local/lib/python3.11/site-packages/napalm/base/base.py", line 114, in _netmiko_open
    self._netmiko_device = ConnectHandler(
                           ^^^^^^^^^^^^^^^
  File "/home/kali/.local/lib/python3.11/site-packages/netmiko/ssh_dispatcher.py", line 399, in ConnectHandler
    return ConnectionClass(*args, **kwargs)
           ^^^^^^^^^^^^^^^^^^^^^^^^^^^^^^^^
  File "/home/kali/.local/lib/python3.11/site-packages/netmiko/base_connection.py", line 488, in __init__
    self._open()
  File "/home/kali/.local/lib/python3.11/site-packages/netmiko/base_connection.py", line 493, in _open
    self.establish_connection()
  File "/home/kali/.local/lib/python3.11/site-packages/netmiko/base_connection.py", line 1174, in establish_connection
    raise NetmikoAuthenticationException(msg)
netmiko.exceptions.NetmikoAuthenticationException: Authentication to device failed.

Common causes of this problem are:
1. Invalid username and password
2. Incorrect SSH-key file
3. Connecting to the wrong device

Device settings: cisco_ios 10.5.48.52:22


Authentication failed.

2024-04-19 05:04:04,909 - nornir.core.task -    ERROR -      start() - Host 'BHN-A-3F-SW': task 'nornir_napalm_cli_commands_example' failed with traceback:
Traceback (most recent call last):
  File "/home/kali/.local/lib/python3.11/site-packages/nornir/core/task.py", line 99, in start
    r = self.task(self, **self.params)
        ^^^^^^^^^^^^^^^^^^^^^^^^^^^^^^
  File "/home/kali/Desktop/Nornir/2023/5.nornir_napalm/IITH/cli_inventory_nornir_napalm.py", line 13, in nornir_napalm_cli_commands_example
    task.run(task=napalm_cli, commands=[command])
  File "/home/kali/.local/lib/python3.11/site-packages/nornir/core/task.py", line 174, in run
    raise NornirSubTaskError(task=run_task, result=r)
nornir.core.exceptions.NornirSubTaskError: Subtask: napalm_cli (failed)


2024-04-19 05:04:05,507 - nornir.core.task -    ERROR -      start() - Host 'BHN-B-6F-SW': task 'napalm_cli' failed with traceback:
Traceback (most recent call last):
  File "/home/kali/.local/lib/python3.11/site-packages/netmiko/base_connection.py", line 1137, in establish_connection
    self.remote_conn_pre.connect(**ssh_connect_params)
  File "/usr/lib/python3/dist-packages/paramiko/client.py", line 450, in connect
    self._auth(
  File "/usr/lib/python3/dist-packages/paramiko/client.py", line 781, in _auth
    raise saved_exception
  File "/usr/lib/python3/dist-packages/paramiko/client.py", line 768, in _auth
    self._transport.auth_password(username, password)
  File "/usr/lib/python3/dist-packages/paramiko/transport.py", line 1564, in auth_password
    return self.auth_handler.wait_for_response(my_event)
           ^^^^^^^^^^^^^^^^^^^^^^^^^^^^^^^^^^^^^^^^^^^^^
  File "/usr/lib/python3/dist-packages/paramiko/auth_handler.py", line 259, in wait_for_response
    raise e
paramiko.ssh_exception.AuthenticationException: Authentication failed.

During handling of the above exception, another exception occurred:

Traceback (most recent call last):
  File "/home/kali/.local/lib/python3.11/site-packages/nornir/core/task.py", line 99, in start
    r = self.task(self, **self.params)
        ^^^^^^^^^^^^^^^^^^^^^^^^^^^^^^
  File "/home/kali/.local/lib/python3.11/site-packages/nornir_napalm/plugins/tasks/napalm_cli.py", line 19, in napalm_cli
    device = task.host.get_connection(CONNECTION_NAME, task.nornir.config)
             ^^^^^^^^^^^^^^^^^^^^^^^^^^^^^^^^^^^^^^^^^^^^^^^^^^^^^^^^^^^^^
  File "/home/kali/.local/lib/python3.11/site-packages/nornir/core/inventory.py", line 494, in get_connection
    self.open_connection(
  File "/home/kali/.local/lib/python3.11/site-packages/nornir/core/inventory.py", line 546, in open_connection
    conn_obj.open(
  File "/home/kali/.local/lib/python3.11/site-packages/nornir_napalm/plugins/connections/__init__.py", line 57, in open
    connection.open()
  File "/home/kali/.local/lib/python3.11/site-packages/napalm/ios/ios.py", line 173, in open
    self.device = self._netmiko_open(
                  ^^^^^^^^^^^^^^^^^^^
  File "/home/kali/.local/lib/python3.11/site-packages/napalm/base/base.py", line 114, in _netmiko_open
    self._netmiko_device = ConnectHandler(
                           ^^^^^^^^^^^^^^^
  File "/home/kali/.local/lib/python3.11/site-packages/netmiko/ssh_dispatcher.py", line 399, in ConnectHandler
    return ConnectionClass(*args, **kwargs)
           ^^^^^^^^^^^^^^^^^^^^^^^^^^^^^^^^
  File "/home/kali/.local/lib/python3.11/site-packages/netmiko/base_connection.py", line 488, in __init__
    self._open()
  File "/home/kali/.local/lib/python3.11/site-packages/netmiko/base_connection.py", line 493, in _open
    self.establish_connection()
  File "/home/kali/.local/lib/python3.11/site-packages/netmiko/base_connection.py", line 1174, in establish_connection
    raise NetmikoAuthenticationException(msg)
netmiko.exceptions.NetmikoAuthenticationException: Authentication to device failed.

Common causes of this problem are:
1. Invalid username and password
2. Incorrect SSH-key file
3. Connecting to the wrong device

Device settings: cisco_ios 10.5.48.58:22


Authentication failed.

2024-04-19 05:04:05,508 - nornir.core.task -    ERROR -      start() - Host 'BHN-B-6F-SW': task 'nornir_napalm_cli_commands_example' failed with traceback:
Traceback (most recent call last):
  File "/home/kali/.local/lib/python3.11/site-packages/nornir/core/task.py", line 99, in start
    r = self.task(self, **self.params)
        ^^^^^^^^^^^^^^^^^^^^^^^^^^^^^^
  File "/home/kali/Desktop/Nornir/2023/5.nornir_napalm/IITH/cli_inventory_nornir_napalm.py", line 13, in nornir_napalm_cli_commands_example
    task.run(task=napalm_cli, commands=[command])
  File "/home/kali/.local/lib/python3.11/site-packages/nornir/core/task.py", line 174, in run
    raise NornirSubTaskError(task=run_task, result=r)
nornir.core.exceptions.NornirSubTaskError: Subtask: napalm_cli (failed)


2024-04-19 05:04:05,513 - nornir.core.task -    ERROR -      start() - Host 'BHN-B-9F-SW': task 'napalm_cli' failed with traceback:
Traceback (most recent call last):
  File "/home/kali/.local/lib/python3.11/site-packages/netmiko/base_connection.py", line 1137, in establish_connection
    self.remote_conn_pre.connect(**ssh_connect_params)
  File "/usr/lib/python3/dist-packages/paramiko/client.py", line 450, in connect
    self._auth(
  File "/usr/lib/python3/dist-packages/paramiko/client.py", line 781, in _auth
    raise saved_exception
  File "/usr/lib/python3/dist-packages/paramiko/client.py", line 768, in _auth
    self._transport.auth_password(username, password)
  File "/usr/lib/python3/dist-packages/paramiko/transport.py", line 1564, in auth_password
    return self.auth_handler.wait_for_response(my_event)
           ^^^^^^^^^^^^^^^^^^^^^^^^^^^^^^^^^^^^^^^^^^^^^
  File "/usr/lib/python3/dist-packages/paramiko/auth_handler.py", line 259, in wait_for_response
    raise e
paramiko.ssh_exception.AuthenticationException: Authentication failed.

During handling of the above exception, another exception occurred:

Traceback (most recent call last):
  File "/home/kali/.local/lib/python3.11/site-packages/nornir/core/task.py", line 99, in start
    r = self.task(self, **self.params)
        ^^^^^^^^^^^^^^^^^^^^^^^^^^^^^^
  File "/home/kali/.local/lib/python3.11/site-packages/nornir_napalm/plugins/tasks/napalm_cli.py", line 19, in napalm_cli
    device = task.host.get_connection(CONNECTION_NAME, task.nornir.config)
             ^^^^^^^^^^^^^^^^^^^^^^^^^^^^^^^^^^^^^^^^^^^^^^^^^^^^^^^^^^^^^
  File "/home/kali/.local/lib/python3.11/site-packages/nornir/core/inventory.py", line 494, in get_connection
    self.open_connection(
  File "/home/kali/.local/lib/python3.11/site-packages/nornir/core/inventory.py", line 546, in open_connection
    conn_obj.open(
  File "/home/kali/.local/lib/python3.11/site-packages/nornir_napalm/plugins/connections/__init__.py", line 57, in open
    connection.open()
  File "/home/kali/.local/lib/python3.11/site-packages/napalm/ios/ios.py", line 173, in open
    self.device = self._netmiko_open(
                  ^^^^^^^^^^^^^^^^^^^
  File "/home/kali/.local/lib/python3.11/site-packages/napalm/base/base.py", line 114, in _netmiko_open
    self._netmiko_device = ConnectHandler(
                           ^^^^^^^^^^^^^^^
  File "/home/kali/.local/lib/python3.11/site-packages/netmiko/ssh_dispatcher.py", line 399, in ConnectHandler
    return ConnectionClass(*args, **kwargs)
           ^^^^^^^^^^^^^^^^^^^^^^^^^^^^^^^^
  File "/home/kali/.local/lib/python3.11/site-packages/netmiko/base_connection.py", line 488, in __init__
    self._open()
  File "/home/kali/.local/lib/python3.11/site-packages/netmiko/base_connection.py", line 493, in _open
    self.establish_connection()
  File "/home/kali/.local/lib/python3.11/site-packages/netmiko/base_connection.py", line 1174, in establish_connection
    raise NetmikoAuthenticationException(msg)
netmiko.exceptions.NetmikoAuthenticationException: Authentication to device failed.

Common causes of this problem are:
1. Invalid username and password
2. Incorrect SSH-key file
3. Connecting to the wrong device

Device settings: cisco_ios 10.5.48.59:22


Authentication failed.

2024-04-19 05:04:05,513 - nornir.core.task -    ERROR -      start() - Host 'BHN-B-9F-SW': task 'nornir_napalm_cli_commands_example' failed with traceback:
Traceback (most recent call last):
  File "/home/kali/.local/lib/python3.11/site-packages/nornir/core/task.py", line 99, in start
    r = self.task(self, **self.params)
        ^^^^^^^^^^^^^^^^^^^^^^^^^^^^^^
  File "/home/kali/Desktop/Nornir/2023/5.nornir_napalm/IITH/cli_inventory_nornir_napalm.py", line 13, in nornir_napalm_cli_commands_example
    task.run(task=napalm_cli, commands=[command])
  File "/home/kali/.local/lib/python3.11/site-packages/nornir/core/task.py", line 174, in run
    raise NornirSubTaskError(task=run_task, result=r)
nornir.core.exceptions.NornirSubTaskError: Subtask: napalm_cli (failed)


2024-04-19 05:04:05,521 - nornir.core.task -    ERROR -      start() - Host 'BHN-B-3F-SW': task 'napalm_cli' failed with traceback:
Traceback (most recent call last):
  File "/home/kali/.local/lib/python3.11/site-packages/netmiko/base_connection.py", line 1137, in establish_connection
    self.remote_conn_pre.connect(**ssh_connect_params)
  File "/usr/lib/python3/dist-packages/paramiko/client.py", line 450, in connect
    self._auth(
  File "/usr/lib/python3/dist-packages/paramiko/client.py", line 781, in _auth
    raise saved_exception
  File "/usr/lib/python3/dist-packages/paramiko/client.py", line 768, in _auth
    self._transport.auth_password(username, password)
  File "/usr/lib/python3/dist-packages/paramiko/transport.py", line 1564, in auth_password
    return self.auth_handler.wait_for_response(my_event)
           ^^^^^^^^^^^^^^^^^^^^^^^^^^^^^^^^^^^^^^^^^^^^^
  File "/usr/lib/python3/dist-packages/paramiko/auth_handler.py", line 259, in wait_for_response
    raise e
paramiko.ssh_exception.AuthenticationException: Authentication failed.

During handling of the above exception, another exception occurred:

Traceback (most recent call last):
  File "/home/kali/.local/lib/python3.11/site-packages/nornir/core/task.py", line 99, in start
    r = self.task(self, **self.params)
        ^^^^^^^^^^^^^^^^^^^^^^^^^^^^^^
  File "/home/kali/.local/lib/python3.11/site-packages/nornir_napalm/plugins/tasks/napalm_cli.py", line 19, in napalm_cli
    device = task.host.get_connection(CONNECTION_NAME, task.nornir.config)
             ^^^^^^^^^^^^^^^^^^^^^^^^^^^^^^^^^^^^^^^^^^^^^^^^^^^^^^^^^^^^^
  File "/home/kali/.local/lib/python3.11/site-packages/nornir/core/inventory.py", line 494, in get_connection
    self.open_connection(
  File "/home/kali/.local/lib/python3.11/site-packages/nornir/core/inventory.py", line 546, in open_connection
    conn_obj.open(
  File "/home/kali/.local/lib/python3.11/site-packages/nornir_napalm/plugins/connections/__init__.py", line 57, in open
    connection.open()
  File "/home/kali/.local/lib/python3.11/site-packages/napalm/ios/ios.py", line 173, in open
    self.device = self._netmiko_open(
                  ^^^^^^^^^^^^^^^^^^^
  File "/home/kali/.local/lib/python3.11/site-packages/napalm/base/base.py", line 114, in _netmiko_open
    self._netmiko_device = ConnectHandler(
                           ^^^^^^^^^^^^^^^
  File "/home/kali/.local/lib/python3.11/site-packages/netmiko/ssh_dispatcher.py", line 399, in ConnectHandler
    return ConnectionClass(*args, **kwargs)
           ^^^^^^^^^^^^^^^^^^^^^^^^^^^^^^^^
  File "/home/kali/.local/lib/python3.11/site-packages/netmiko/base_connection.py", line 488, in __init__
    self._open()
  File "/home/kali/.local/lib/python3.11/site-packages/netmiko/base_connection.py", line 493, in _open
    self.establish_connection()
  File "/home/kali/.local/lib/python3.11/site-packages/netmiko/base_connection.py", line 1174, in establish_connection
    raise NetmikoAuthenticationException(msg)
netmiko.exceptions.NetmikoAuthenticationException: Authentication to device failed.

Common causes of this problem are:
1. Invalid username and password
2. Incorrect SSH-key file
3. Connecting to the wrong device

Device settings: cisco_ios 10.5.48.57:22


Authentication failed.

2024-04-19 05:04:05,522 - nornir.core.task -    ERROR -      start() - Host 'BHN-B-3F-SW': task 'nornir_napalm_cli_commands_example' failed with traceback:
Traceback (most recent call last):
  File "/home/kali/.local/lib/python3.11/site-packages/nornir/core/task.py", line 99, in start
    r = self.task(self, **self.params)
        ^^^^^^^^^^^^^^^^^^^^^^^^^^^^^^
  File "/home/kali/Desktop/Nornir/2023/5.nornir_napalm/IITH/cli_inventory_nornir_napalm.py", line 13, in nornir_napalm_cli_commands_example
    task.run(task=napalm_cli, commands=[command])
  File "/home/kali/.local/lib/python3.11/site-packages/nornir/core/task.py", line 174, in run
    raise NornirSubTaskError(task=run_task, result=r)
nornir.core.exceptions.NornirSubTaskError: Subtask: napalm_cli (failed)


2024-04-19 05:04:26,740 -  nornir.core -     INFO -        run() - Running task 'nornir_napalm_cli_commands_example' with args {} on 40 hosts
2024-04-19 05:04:30,859 - nornir.core.task -    ERROR -      start() - Host 'BHN-A-6F-SW': task 'napalm_cli' failed with traceback:
Traceback (most recent call last):
  File "/home/kali/.local/lib/python3.11/site-packages/netmiko/base_connection.py", line 1137, in establish_connection
    self.remote_conn_pre.connect(**ssh_connect_params)
  File "/usr/lib/python3/dist-packages/paramiko/client.py", line 450, in connect
    self._auth(
  File "/usr/lib/python3/dist-packages/paramiko/client.py", line 781, in _auth
    raise saved_exception
  File "/usr/lib/python3/dist-packages/paramiko/client.py", line 768, in _auth
    self._transport.auth_password(username, password)
  File "/usr/lib/python3/dist-packages/paramiko/transport.py", line 1564, in auth_password
    return self.auth_handler.wait_for_response(my_event)
           ^^^^^^^^^^^^^^^^^^^^^^^^^^^^^^^^^^^^^^^^^^^^^
  File "/usr/lib/python3/dist-packages/paramiko/auth_handler.py", line 259, in wait_for_response
    raise e
paramiko.ssh_exception.AuthenticationException: Authentication failed.

During handling of the above exception, another exception occurred:

Traceback (most recent call last):
  File "/home/kali/.local/lib/python3.11/site-packages/nornir/core/task.py", line 99, in start
    r = self.task(self, **self.params)
        ^^^^^^^^^^^^^^^^^^^^^^^^^^^^^^
  File "/home/kali/.local/lib/python3.11/site-packages/nornir_napalm/plugins/tasks/napalm_cli.py", line 19, in napalm_cli
    device = task.host.get_connection(CONNECTION_NAME, task.nornir.config)
             ^^^^^^^^^^^^^^^^^^^^^^^^^^^^^^^^^^^^^^^^^^^^^^^^^^^^^^^^^^^^^
  File "/home/kali/.local/lib/python3.11/site-packages/nornir/core/inventory.py", line 494, in get_connection
    self.open_connection(
  File "/home/kali/.local/lib/python3.11/site-packages/nornir/core/inventory.py", line 546, in open_connection
    conn_obj.open(
  File "/home/kali/.local/lib/python3.11/site-packages/nornir_napalm/plugins/connections/__init__.py", line 57, in open
    connection.open()
  File "/home/kali/.local/lib/python3.11/site-packages/napalm/ios/ios.py", line 173, in open
    self.device = self._netmiko_open(
                  ^^^^^^^^^^^^^^^^^^^
  File "/home/kali/.local/lib/python3.11/site-packages/napalm/base/base.py", line 114, in _netmiko_open
    self._netmiko_device = ConnectHandler(
                           ^^^^^^^^^^^^^^^
  File "/home/kali/.local/lib/python3.11/site-packages/netmiko/ssh_dispatcher.py", line 399, in ConnectHandler
    return ConnectionClass(*args, **kwargs)
           ^^^^^^^^^^^^^^^^^^^^^^^^^^^^^^^^
  File "/home/kali/.local/lib/python3.11/site-packages/netmiko/base_connection.py", line 488, in __init__
    self._open()
  File "/home/kali/.local/lib/python3.11/site-packages/netmiko/base_connection.py", line 493, in _open
    self.establish_connection()
  File "/home/kali/.local/lib/python3.11/site-packages/netmiko/base_connection.py", line 1174, in establish_connection
    raise NetmikoAuthenticationException(msg)
netmiko.exceptions.NetmikoAuthenticationException: Authentication to device failed.

Common causes of this problem are:
1. Invalid username and password
2. Incorrect SSH-key file
3. Connecting to the wrong device

Device settings: cisco_ios 10.5.48.53:22


Authentication failed.

2024-04-19 05:04:30,862 - nornir.core.task -    ERROR -      start() - Host 'BHN-A-3F-SW': task 'napalm_cli' failed with traceback:
Traceback (most recent call last):
  File "/home/kali/.local/lib/python3.11/site-packages/netmiko/base_connection.py", line 1137, in establish_connection
    self.remote_conn_pre.connect(**ssh_connect_params)
  File "/usr/lib/python3/dist-packages/paramiko/client.py", line 450, in connect
    self._auth(
  File "/usr/lib/python3/dist-packages/paramiko/client.py", line 781, in _auth
    raise saved_exception
  File "/usr/lib/python3/dist-packages/paramiko/client.py", line 768, in _auth
    self._transport.auth_password(username, password)
  File "/usr/lib/python3/dist-packages/paramiko/transport.py", line 1564, in auth_password
    return self.auth_handler.wait_for_response(my_event)
           ^^^^^^^^^^^^^^^^^^^^^^^^^^^^^^^^^^^^^^^^^^^^^
  File "/usr/lib/python3/dist-packages/paramiko/auth_handler.py", line 259, in wait_for_response
    raise e
paramiko.ssh_exception.AuthenticationException: Authentication failed.

During handling of the above exception, another exception occurred:

Traceback (most recent call last):
  File "/home/kali/.local/lib/python3.11/site-packages/nornir/core/task.py", line 99, in start
    r = self.task(self, **self.params)
        ^^^^^^^^^^^^^^^^^^^^^^^^^^^^^^
  File "/home/kali/.local/lib/python3.11/site-packages/nornir_napalm/plugins/tasks/napalm_cli.py", line 19, in napalm_cli
    device = task.host.get_connection(CONNECTION_NAME, task.nornir.config)
             ^^^^^^^^^^^^^^^^^^^^^^^^^^^^^^^^^^^^^^^^^^^^^^^^^^^^^^^^^^^^^
  File "/home/kali/.local/lib/python3.11/site-packages/nornir/core/inventory.py", line 494, in get_connection
    self.open_connection(
  File "/home/kali/.local/lib/python3.11/site-packages/nornir/core/inventory.py", line 546, in open_connection
    conn_obj.open(
  File "/home/kali/.local/lib/python3.11/site-packages/nornir_napalm/plugins/connections/__init__.py", line 57, in open
    connection.open()
  File "/home/kali/.local/lib/python3.11/site-packages/napalm/ios/ios.py", line 173, in open
    self.device = self._netmiko_open(
                  ^^^^^^^^^^^^^^^^^^^
  File "/home/kali/.local/lib/python3.11/site-packages/napalm/base/base.py", line 114, in _netmiko_open
    self._netmiko_device = ConnectHandler(
                           ^^^^^^^^^^^^^^^
  File "/home/kali/.local/lib/python3.11/site-packages/netmiko/ssh_dispatcher.py", line 399, in ConnectHandler
    return ConnectionClass(*args, **kwargs)
           ^^^^^^^^^^^^^^^^^^^^^^^^^^^^^^^^
  File "/home/kali/.local/lib/python3.11/site-packages/netmiko/base_connection.py", line 488, in __init__
    self._open()
  File "/home/kali/.local/lib/python3.11/site-packages/netmiko/base_connection.py", line 493, in _open
    self.establish_connection()
  File "/home/kali/.local/lib/python3.11/site-packages/netmiko/base_connection.py", line 1174, in establish_connection
    raise NetmikoAuthenticationException(msg)
netmiko.exceptions.NetmikoAuthenticationException: Authentication to device failed.

Common causes of this problem are:
1. Invalid username and password
2. Incorrect SSH-key file
3. Connecting to the wrong device

Device settings: cisco_ios 10.5.48.52:22


Authentication failed.

2024-04-19 05:04:30,863 - nornir.core.task -    ERROR -      start() - Host 'BHN-A-3F-SW': task 'nornir_napalm_cli_commands_example' failed with traceback:
Traceback (most recent call last):
  File "/home/kali/.local/lib/python3.11/site-packages/nornir/core/task.py", line 99, in start
    r = self.task(self, **self.params)
        ^^^^^^^^^^^^^^^^^^^^^^^^^^^^^^
  File "/home/kali/Desktop/Nornir/2023/5.nornir_napalm/IITH/cli_inventory_nornir_napalm.py", line 13, in nornir_napalm_cli_commands_example
    task.run(task=napalm_cli, commands=[command])
  File "/home/kali/.local/lib/python3.11/site-packages/nornir/core/task.py", line 174, in run
    raise NornirSubTaskError(task=run_task, result=r)
nornir.core.exceptions.NornirSubTaskError: Subtask: napalm_cli (failed)


2024-04-19 05:04:30,862 - nornir.core.task -    ERROR -      start() - Host 'BHN-A-9F-SW': task 'napalm_cli' failed with traceback:
Traceback (most recent call last):
  File "/home/kali/.local/lib/python3.11/site-packages/netmiko/base_connection.py", line 1137, in establish_connection
    self.remote_conn_pre.connect(**ssh_connect_params)
  File "/usr/lib/python3/dist-packages/paramiko/client.py", line 450, in connect
    self._auth(
  File "/usr/lib/python3/dist-packages/paramiko/client.py", line 781, in _auth
    raise saved_exception
  File "/usr/lib/python3/dist-packages/paramiko/client.py", line 768, in _auth
    self._transport.auth_password(username, password)
  File "/usr/lib/python3/dist-packages/paramiko/transport.py", line 1564, in auth_password
    return self.auth_handler.wait_for_response(my_event)
           ^^^^^^^^^^^^^^^^^^^^^^^^^^^^^^^^^^^^^^^^^^^^^
  File "/usr/lib/python3/dist-packages/paramiko/auth_handler.py", line 259, in wait_for_response
    raise e
paramiko.ssh_exception.AuthenticationException: Authentication failed.

During handling of the above exception, another exception occurred:

Traceback (most recent call last):
  File "/home/kali/.local/lib/python3.11/site-packages/nornir/core/task.py", line 99, in start
    r = self.task(self, **self.params)
        ^^^^^^^^^^^^^^^^^^^^^^^^^^^^^^
  File "/home/kali/.local/lib/python3.11/site-packages/nornir_napalm/plugins/tasks/napalm_cli.py", line 19, in napalm_cli
    device = task.host.get_connection(CONNECTION_NAME, task.nornir.config)
             ^^^^^^^^^^^^^^^^^^^^^^^^^^^^^^^^^^^^^^^^^^^^^^^^^^^^^^^^^^^^^
  File "/home/kali/.local/lib/python3.11/site-packages/nornir/core/inventory.py", line 494, in get_connection
    self.open_connection(
  File "/home/kali/.local/lib/python3.11/site-packages/nornir/core/inventory.py", line 546, in open_connection
    conn_obj.open(
  File "/home/kali/.local/lib/python3.11/site-packages/nornir_napalm/plugins/connections/__init__.py", line 57, in open
    connection.open()
  File "/home/kali/.local/lib/python3.11/site-packages/napalm/ios/ios.py", line 173, in open
    self.device = self._netmiko_open(
                  ^^^^^^^^^^^^^^^^^^^
  File "/home/kali/.local/lib/python3.11/site-packages/napalm/base/base.py", line 114, in _netmiko_open
    self._netmiko_device = ConnectHandler(
                           ^^^^^^^^^^^^^^^
  File "/home/kali/.local/lib/python3.11/site-packages/netmiko/ssh_dispatcher.py", line 399, in ConnectHandler
    return ConnectionClass(*args, **kwargs)
           ^^^^^^^^^^^^^^^^^^^^^^^^^^^^^^^^
  File "/home/kali/.local/lib/python3.11/site-packages/netmiko/base_connection.py", line 488, in __init__
    self._open()
  File "/home/kali/.local/lib/python3.11/site-packages/netmiko/base_connection.py", line 493, in _open
    self.establish_connection()
  File "/home/kali/.local/lib/python3.11/site-packages/netmiko/base_connection.py", line 1174, in establish_connection
    raise NetmikoAuthenticationException(msg)
netmiko.exceptions.NetmikoAuthenticationException: Authentication to device failed.

Common causes of this problem are:
1. Invalid username and password
2. Incorrect SSH-key file
3. Connecting to the wrong device

Device settings: cisco_ios 10.5.48.54:22


Authentication failed.

2024-04-19 05:04:30,864 - nornir.core.task -    ERROR -      start() - Host 'BHN-A-9F-SW': task 'nornir_napalm_cli_commands_example' failed with traceback:
Traceback (most recent call last):
  File "/home/kali/.local/lib/python3.11/site-packages/nornir/core/task.py", line 99, in start
    r = self.task(self, **self.params)
        ^^^^^^^^^^^^^^^^^^^^^^^^^^^^^^
  File "/home/kali/Desktop/Nornir/2023/5.nornir_napalm/IITH/cli_inventory_nornir_napalm.py", line 13, in nornir_napalm_cli_commands_example
    task.run(task=napalm_cli, commands=[command])
  File "/home/kali/.local/lib/python3.11/site-packages/nornir/core/task.py", line 174, in run
    raise NornirSubTaskError(task=run_task, result=r)
nornir.core.exceptions.NornirSubTaskError: Subtask: napalm_cli (failed)


2024-04-19 05:04:30,863 - nornir.core.task -    ERROR -      start() - Host 'BHN-A-6F-SW': task 'nornir_napalm_cli_commands_example' failed with traceback:
Traceback (most recent call last):
  File "/home/kali/.local/lib/python3.11/site-packages/nornir/core/task.py", line 99, in start
    r = self.task(self, **self.params)
        ^^^^^^^^^^^^^^^^^^^^^^^^^^^^^^
  File "/home/kali/Desktop/Nornir/2023/5.nornir_napalm/IITH/cli_inventory_nornir_napalm.py", line 13, in nornir_napalm_cli_commands_example
    task.run(task=napalm_cli, commands=[command])
  File "/home/kali/.local/lib/python3.11/site-packages/nornir/core/task.py", line 174, in run
    raise NornirSubTaskError(task=run_task, result=r)
nornir.core.exceptions.NornirSubTaskError: Subtask: napalm_cli (failed)


2024-04-19 05:04:30,869 - nornir.core.task -    ERROR -      start() - Host 'BHN-B-3F-SW': task 'napalm_cli' failed with traceback:
Traceback (most recent call last):
  File "/home/kali/.local/lib/python3.11/site-packages/netmiko/base_connection.py", line 1137, in establish_connection
    self.remote_conn_pre.connect(**ssh_connect_params)
  File "/usr/lib/python3/dist-packages/paramiko/client.py", line 450, in connect
    self._auth(
  File "/usr/lib/python3/dist-packages/paramiko/client.py", line 781, in _auth
    raise saved_exception
  File "/usr/lib/python3/dist-packages/paramiko/client.py", line 768, in _auth
    self._transport.auth_password(username, password)
  File "/usr/lib/python3/dist-packages/paramiko/transport.py", line 1564, in auth_password
    return self.auth_handler.wait_for_response(my_event)
           ^^^^^^^^^^^^^^^^^^^^^^^^^^^^^^^^^^^^^^^^^^^^^
  File "/usr/lib/python3/dist-packages/paramiko/auth_handler.py", line 259, in wait_for_response
    raise e
paramiko.ssh_exception.AuthenticationException: Authentication failed.

During handling of the above exception, another exception occurred:

Traceback (most recent call last):
  File "/home/kali/.local/lib/python3.11/site-packages/nornir/core/task.py", line 99, in start
    r = self.task(self, **self.params)
        ^^^^^^^^^^^^^^^^^^^^^^^^^^^^^^
  File "/home/kali/.local/lib/python3.11/site-packages/nornir_napalm/plugins/tasks/napalm_cli.py", line 19, in napalm_cli
    device = task.host.get_connection(CONNECTION_NAME, task.nornir.config)
             ^^^^^^^^^^^^^^^^^^^^^^^^^^^^^^^^^^^^^^^^^^^^^^^^^^^^^^^^^^^^^
  File "/home/kali/.local/lib/python3.11/site-packages/nornir/core/inventory.py", line 494, in get_connection
    self.open_connection(
  File "/home/kali/.local/lib/python3.11/site-packages/nornir/core/inventory.py", line 546, in open_connection
    conn_obj.open(
  File "/home/kali/.local/lib/python3.11/site-packages/nornir_napalm/plugins/connections/__init__.py", line 57, in open
    connection.open()
  File "/home/kali/.local/lib/python3.11/site-packages/napalm/ios/ios.py", line 173, in open
    self.device = self._netmiko_open(
                  ^^^^^^^^^^^^^^^^^^^
  File "/home/kali/.local/lib/python3.11/site-packages/napalm/base/base.py", line 114, in _netmiko_open
    self._netmiko_device = ConnectHandler(
                           ^^^^^^^^^^^^^^^
  File "/home/kali/.local/lib/python3.11/site-packages/netmiko/ssh_dispatcher.py", line 399, in ConnectHandler
    return ConnectionClass(*args, **kwargs)
           ^^^^^^^^^^^^^^^^^^^^^^^^^^^^^^^^
  File "/home/kali/.local/lib/python3.11/site-packages/netmiko/base_connection.py", line 488, in __init__
    self._open()
  File "/home/kali/.local/lib/python3.11/site-packages/netmiko/base_connection.py", line 493, in _open
    self.establish_connection()
  File "/home/kali/.local/lib/python3.11/site-packages/netmiko/base_connection.py", line 1174, in establish_connection
    raise NetmikoAuthenticationException(msg)
netmiko.exceptions.NetmikoAuthenticationException: Authentication to device failed.

Common causes of this problem are:
1. Invalid username and password
2. Incorrect SSH-key file
3. Connecting to the wrong device

Device settings: cisco_ios 10.5.48.57:22


Authentication failed.

2024-04-19 05:04:30,869 - nornir.core.task -    ERROR -      start() - Host 'BHN-B-3F-SW': task 'nornir_napalm_cli_commands_example' failed with traceback:
Traceback (most recent call last):
  File "/home/kali/.local/lib/python3.11/site-packages/nornir/core/task.py", line 99, in start
    r = self.task(self, **self.params)
        ^^^^^^^^^^^^^^^^^^^^^^^^^^^^^^
  File "/home/kali/Desktop/Nornir/2023/5.nornir_napalm/IITH/cli_inventory_nornir_napalm.py", line 13, in nornir_napalm_cli_commands_example
    task.run(task=napalm_cli, commands=[command])
  File "/home/kali/.local/lib/python3.11/site-packages/nornir/core/task.py", line 174, in run
    raise NornirSubTaskError(task=run_task, result=r)
nornir.core.exceptions.NornirSubTaskError: Subtask: napalm_cli (failed)


2024-04-19 05:04:31,033 - nornir.core.task -    ERROR -      start() - Host 'BHN-B-6F-SW': task 'napalm_cli' failed with traceback:
Traceback (most recent call last):
  File "/home/kali/.local/lib/python3.11/site-packages/netmiko/base_connection.py", line 1137, in establish_connection
    self.remote_conn_pre.connect(**ssh_connect_params)
  File "/usr/lib/python3/dist-packages/paramiko/client.py", line 450, in connect
    self._auth(
  File "/usr/lib/python3/dist-packages/paramiko/client.py", line 781, in _auth
    raise saved_exception
  File "/usr/lib/python3/dist-packages/paramiko/client.py", line 768, in _auth
    self._transport.auth_password(username, password)
  File "/usr/lib/python3/dist-packages/paramiko/transport.py", line 1564, in auth_password
    return self.auth_handler.wait_for_response(my_event)
           ^^^^^^^^^^^^^^^^^^^^^^^^^^^^^^^^^^^^^^^^^^^^^
  File "/usr/lib/python3/dist-packages/paramiko/auth_handler.py", line 259, in wait_for_response
    raise e
paramiko.ssh_exception.AuthenticationException: Authentication failed.

During handling of the above exception, another exception occurred:

Traceback (most recent call last):
  File "/home/kali/.local/lib/python3.11/site-packages/nornir/core/task.py", line 99, in start
    r = self.task(self, **self.params)
        ^^^^^^^^^^^^^^^^^^^^^^^^^^^^^^
  File "/home/kali/.local/lib/python3.11/site-packages/nornir_napalm/plugins/tasks/napalm_cli.py", line 19, in napalm_cli
    device = task.host.get_connection(CONNECTION_NAME, task.nornir.config)
             ^^^^^^^^^^^^^^^^^^^^^^^^^^^^^^^^^^^^^^^^^^^^^^^^^^^^^^^^^^^^^
  File "/home/kali/.local/lib/python3.11/site-packages/nornir/core/inventory.py", line 494, in get_connection
    self.open_connection(
  File "/home/kali/.local/lib/python3.11/site-packages/nornir/core/inventory.py", line 546, in open_connection
    conn_obj.open(
  File "/home/kali/.local/lib/python3.11/site-packages/nornir_napalm/plugins/connections/__init__.py", line 57, in open
    connection.open()
  File "/home/kali/.local/lib/python3.11/site-packages/napalm/ios/ios.py", line 173, in open
    self.device = self._netmiko_open(
                  ^^^^^^^^^^^^^^^^^^^
  File "/home/kali/.local/lib/python3.11/site-packages/napalm/base/base.py", line 114, in _netmiko_open
    self._netmiko_device = ConnectHandler(
                           ^^^^^^^^^^^^^^^
  File "/home/kali/.local/lib/python3.11/site-packages/netmiko/ssh_dispatcher.py", line 399, in ConnectHandler
    return ConnectionClass(*args, **kwargs)
           ^^^^^^^^^^^^^^^^^^^^^^^^^^^^^^^^
  File "/home/kali/.local/lib/python3.11/site-packages/netmiko/base_connection.py", line 488, in __init__
    self._open()
  File "/home/kali/.local/lib/python3.11/site-packages/netmiko/base_connection.py", line 493, in _open
    self.establish_connection()
  File "/home/kali/.local/lib/python3.11/site-packages/netmiko/base_connection.py", line 1174, in establish_connection
    raise NetmikoAuthenticationException(msg)
netmiko.exceptions.NetmikoAuthenticationException: Authentication to device failed.

Common causes of this problem are:
1. Invalid username and password
2. Incorrect SSH-key file
3. Connecting to the wrong device

Device settings: cisco_ios 10.5.48.58:22


Authentication failed.

2024-04-19 05:04:31,036 - nornir.core.task -    ERROR -      start() - Host 'BHN-B-9F-SW': task 'napalm_cli' failed with traceback:
Traceback (most recent call last):
  File "/home/kali/.local/lib/python3.11/site-packages/netmiko/base_connection.py", line 1137, in establish_connection
    self.remote_conn_pre.connect(**ssh_connect_params)
  File "/usr/lib/python3/dist-packages/paramiko/client.py", line 450, in connect
    self._auth(
  File "/usr/lib/python3/dist-packages/paramiko/client.py", line 781, in _auth
    raise saved_exception
  File "/usr/lib/python3/dist-packages/paramiko/client.py", line 768, in _auth
    self._transport.auth_password(username, password)
  File "/usr/lib/python3/dist-packages/paramiko/transport.py", line 1564, in auth_password
    return self.auth_handler.wait_for_response(my_event)
           ^^^^^^^^^^^^^^^^^^^^^^^^^^^^^^^^^^^^^^^^^^^^^
  File "/usr/lib/python3/dist-packages/paramiko/auth_handler.py", line 259, in wait_for_response
    raise e
paramiko.ssh_exception.AuthenticationException: Authentication failed.

During handling of the above exception, another exception occurred:

Traceback (most recent call last):
  File "/home/kali/.local/lib/python3.11/site-packages/nornir/core/task.py", line 99, in start
    r = self.task(self, **self.params)
        ^^^^^^^^^^^^^^^^^^^^^^^^^^^^^^
  File "/home/kali/.local/lib/python3.11/site-packages/nornir_napalm/plugins/tasks/napalm_cli.py", line 19, in napalm_cli
    device = task.host.get_connection(CONNECTION_NAME, task.nornir.config)
             ^^^^^^^^^^^^^^^^^^^^^^^^^^^^^^^^^^^^^^^^^^^^^^^^^^^^^^^^^^^^^
  File "/home/kali/.local/lib/python3.11/site-packages/nornir/core/inventory.py", line 494, in get_connection
    self.open_connection(
  File "/home/kali/.local/lib/python3.11/site-packages/nornir/core/inventory.py", line 546, in open_connection
    conn_obj.open(
  File "/home/kali/.local/lib/python3.11/site-packages/nornir_napalm/plugins/connections/__init__.py", line 57, in open
    connection.open()
  File "/home/kali/.local/lib/python3.11/site-packages/napalm/ios/ios.py", line 173, in open
    self.device = self._netmiko_open(
                  ^^^^^^^^^^^^^^^^^^^
  File "/home/kali/.local/lib/python3.11/site-packages/napalm/base/base.py", line 114, in _netmiko_open
    self._netmiko_device = ConnectHandler(
                           ^^^^^^^^^^^^^^^
  File "/home/kali/.local/lib/python3.11/site-packages/netmiko/ssh_dispatcher.py", line 399, in ConnectHandler
    return ConnectionClass(*args, **kwargs)
           ^^^^^^^^^^^^^^^^^^^^^^^^^^^^^^^^
  File "/home/kali/.local/lib/python3.11/site-packages/netmiko/base_connection.py", line 488, in __init__
    self._open()
  File "/home/kali/.local/lib/python3.11/site-packages/netmiko/base_connection.py", line 493, in _open
    self.establish_connection()
  File "/home/kali/.local/lib/python3.11/site-packages/netmiko/base_connection.py", line 1174, in establish_connection
    raise NetmikoAuthenticationException(msg)
netmiko.exceptions.NetmikoAuthenticationException: Authentication to device failed.

Common causes of this problem are:
1. Invalid username and password
2. Incorrect SSH-key file
3. Connecting to the wrong device

Device settings: cisco_ios 10.5.48.59:22


Authentication failed.

2024-04-19 05:04:31,036 - nornir.core.task -    ERROR -      start() - Host 'BHN-B-9F-SW': task 'nornir_napalm_cli_commands_example' failed with traceback:
Traceback (most recent call last):
  File "/home/kali/.local/lib/python3.11/site-packages/nornir/core/task.py", line 99, in start
    r = self.task(self, **self.params)
        ^^^^^^^^^^^^^^^^^^^^^^^^^^^^^^
  File "/home/kali/Desktop/Nornir/2023/5.nornir_napalm/IITH/cli_inventory_nornir_napalm.py", line 13, in nornir_napalm_cli_commands_example
    task.run(task=napalm_cli, commands=[command])
  File "/home/kali/.local/lib/python3.11/site-packages/nornir/core/task.py", line 174, in run
    raise NornirSubTaskError(task=run_task, result=r)
nornir.core.exceptions.NornirSubTaskError: Subtask: napalm_cli (failed)


2024-04-19 05:04:31,036 - nornir.core.task -    ERROR -      start() - Host 'BHN-B-6F-SW': task 'nornir_napalm_cli_commands_example' failed with traceback:
Traceback (most recent call last):
  File "/home/kali/.local/lib/python3.11/site-packages/nornir/core/task.py", line 99, in start
    r = self.task(self, **self.params)
        ^^^^^^^^^^^^^^^^^^^^^^^^^^^^^^
  File "/home/kali/Desktop/Nornir/2023/5.nornir_napalm/IITH/cli_inventory_nornir_napalm.py", line 13, in nornir_napalm_cli_commands_example
    task.run(task=napalm_cli, commands=[command])
  File "/home/kali/.local/lib/python3.11/site-packages/nornir/core/task.py", line 174, in run
    raise NornirSubTaskError(task=run_task, result=r)
nornir.core.exceptions.NornirSubTaskError: Subtask: napalm_cli (failed)


2024-04-19 05:07:05,138 -  nornir.core -     INFO -        run() - Running task 'nornir_napalm_cli_commands_example' with args {} on 36 hosts
2024-04-19 05:07:09,243 - nornir.core.task -    ERROR -      start() - Host 'BHN-A-6F-SW': task 'napalm_cli' failed with traceback:
Traceback (most recent call last):
  File "/home/kali/.local/lib/python3.11/site-packages/netmiko/base_connection.py", line 1137, in establish_connection
    self.remote_conn_pre.connect(**ssh_connect_params)
  File "/usr/lib/python3/dist-packages/paramiko/client.py", line 450, in connect
    self._auth(
  File "/usr/lib/python3/dist-packages/paramiko/client.py", line 781, in _auth
    raise saved_exception
  File "/usr/lib/python3/dist-packages/paramiko/client.py", line 768, in _auth
    self._transport.auth_password(username, password)
  File "/usr/lib/python3/dist-packages/paramiko/transport.py", line 1564, in auth_password
    return self.auth_handler.wait_for_response(my_event)
           ^^^^^^^^^^^^^^^^^^^^^^^^^^^^^^^^^^^^^^^^^^^^^
  File "/usr/lib/python3/dist-packages/paramiko/auth_handler.py", line 259, in wait_for_response
    raise e
paramiko.ssh_exception.AuthenticationException: Authentication failed.

During handling of the above exception, another exception occurred:

Traceback (most recent call last):
  File "/home/kali/.local/lib/python3.11/site-packages/nornir/core/task.py", line 99, in start
    r = self.task(self, **self.params)
        ^^^^^^^^^^^^^^^^^^^^^^^^^^^^^^
  File "/home/kali/.local/lib/python3.11/site-packages/nornir_napalm/plugins/tasks/napalm_cli.py", line 19, in napalm_cli
    device = task.host.get_connection(CONNECTION_NAME, task.nornir.config)
             ^^^^^^^^^^^^^^^^^^^^^^^^^^^^^^^^^^^^^^^^^^^^^^^^^^^^^^^^^^^^^
  File "/home/kali/.local/lib/python3.11/site-packages/nornir/core/inventory.py", line 494, in get_connection
    self.open_connection(
  File "/home/kali/.local/lib/python3.11/site-packages/nornir/core/inventory.py", line 546, in open_connection
    conn_obj.open(
  File "/home/kali/.local/lib/python3.11/site-packages/nornir_napalm/plugins/connections/__init__.py", line 57, in open
    connection.open()
  File "/home/kali/.local/lib/python3.11/site-packages/napalm/ios/ios.py", line 173, in open
    self.device = self._netmiko_open(
                  ^^^^^^^^^^^^^^^^^^^
  File "/home/kali/.local/lib/python3.11/site-packages/napalm/base/base.py", line 114, in _netmiko_open
    self._netmiko_device = ConnectHandler(
                           ^^^^^^^^^^^^^^^
  File "/home/kali/.local/lib/python3.11/site-packages/netmiko/ssh_dispatcher.py", line 399, in ConnectHandler
    return ConnectionClass(*args, **kwargs)
           ^^^^^^^^^^^^^^^^^^^^^^^^^^^^^^^^
  File "/home/kali/.local/lib/python3.11/site-packages/netmiko/base_connection.py", line 488, in __init__
    self._open()
  File "/home/kali/.local/lib/python3.11/site-packages/netmiko/base_connection.py", line 493, in _open
    self.establish_connection()
  File "/home/kali/.local/lib/python3.11/site-packages/netmiko/base_connection.py", line 1174, in establish_connection
    raise NetmikoAuthenticationException(msg)
netmiko.exceptions.NetmikoAuthenticationException: Authentication to device failed.

Common causes of this problem are:
1. Invalid username and password
2. Incorrect SSH-key file
3. Connecting to the wrong device

Device settings: cisco_ios 10.5.48.53:22


Authentication failed.

2024-04-19 05:07:09,244 - nornir.core.task -    ERROR -      start() - Host 'BHN-A-3F-SW': task 'napalm_cli' failed with traceback:
Traceback (most recent call last):
  File "/home/kali/.local/lib/python3.11/site-packages/netmiko/base_connection.py", line 1137, in establish_connection
    self.remote_conn_pre.connect(**ssh_connect_params)
  File "/usr/lib/python3/dist-packages/paramiko/client.py", line 450, in connect
    self._auth(
  File "/usr/lib/python3/dist-packages/paramiko/client.py", line 781, in _auth
    raise saved_exception
  File "/usr/lib/python3/dist-packages/paramiko/client.py", line 768, in _auth
    self._transport.auth_password(username, password)
  File "/usr/lib/python3/dist-packages/paramiko/transport.py", line 1564, in auth_password
    return self.auth_handler.wait_for_response(my_event)
           ^^^^^^^^^^^^^^^^^^^^^^^^^^^^^^^^^^^^^^^^^^^^^
  File "/usr/lib/python3/dist-packages/paramiko/auth_handler.py", line 259, in wait_for_response
    raise e
paramiko.ssh_exception.AuthenticationException: Authentication failed.

During handling of the above exception, another exception occurred:

Traceback (most recent call last):
  File "/home/kali/.local/lib/python3.11/site-packages/nornir/core/task.py", line 99, in start
    r = self.task(self, **self.params)
        ^^^^^^^^^^^^^^^^^^^^^^^^^^^^^^
  File "/home/kali/.local/lib/python3.11/site-packages/nornir_napalm/plugins/tasks/napalm_cli.py", line 19, in napalm_cli
    device = task.host.get_connection(CONNECTION_NAME, task.nornir.config)
             ^^^^^^^^^^^^^^^^^^^^^^^^^^^^^^^^^^^^^^^^^^^^^^^^^^^^^^^^^^^^^
  File "/home/kali/.local/lib/python3.11/site-packages/nornir/core/inventory.py", line 494, in get_connection
    self.open_connection(
  File "/home/kali/.local/lib/python3.11/site-packages/nornir/core/inventory.py", line 546, in open_connection
    conn_obj.open(
  File "/home/kali/.local/lib/python3.11/site-packages/nornir_napalm/plugins/connections/__init__.py", line 57, in open
    connection.open()
  File "/home/kali/.local/lib/python3.11/site-packages/napalm/ios/ios.py", line 173, in open
    self.device = self._netmiko_open(
                  ^^^^^^^^^^^^^^^^^^^
  File "/home/kali/.local/lib/python3.11/site-packages/napalm/base/base.py", line 114, in _netmiko_open
    self._netmiko_device = ConnectHandler(
                           ^^^^^^^^^^^^^^^
  File "/home/kali/.local/lib/python3.11/site-packages/netmiko/ssh_dispatcher.py", line 399, in ConnectHandler
    return ConnectionClass(*args, **kwargs)
           ^^^^^^^^^^^^^^^^^^^^^^^^^^^^^^^^
  File "/home/kali/.local/lib/python3.11/site-packages/netmiko/base_connection.py", line 488, in __init__
    self._open()
  File "/home/kali/.local/lib/python3.11/site-packages/netmiko/base_connection.py", line 493, in _open
    self.establish_connection()
  File "/home/kali/.local/lib/python3.11/site-packages/netmiko/base_connection.py", line 1174, in establish_connection
    raise NetmikoAuthenticationException(msg)
netmiko.exceptions.NetmikoAuthenticationException: Authentication to device failed.

Common causes of this problem are:
1. Invalid username and password
2. Incorrect SSH-key file
3. Connecting to the wrong device

Device settings: cisco_ios 10.5.48.52:22


Authentication failed.

2024-04-19 05:07:09,245 - nornir.core.task -    ERROR -      start() - Host 'BHN-A-3F-SW': task 'nornir_napalm_cli_commands_example' failed with traceback:
Traceback (most recent call last):
  File "/home/kali/.local/lib/python3.11/site-packages/nornir/core/task.py", line 99, in start
    r = self.task(self, **self.params)
        ^^^^^^^^^^^^^^^^^^^^^^^^^^^^^^
  File "/home/kali/Desktop/Nornir/2023/5.nornir_napalm/IITH/cli_inventory_nornir_napalm.py", line 13, in nornir_napalm_cli_commands_example
    task.run(task=napalm_cli, commands=[command])
  File "/home/kali/.local/lib/python3.11/site-packages/nornir/core/task.py", line 174, in run
    raise NornirSubTaskError(task=run_task, result=r)
nornir.core.exceptions.NornirSubTaskError: Subtask: napalm_cli (failed)


2024-04-19 05:07:09,245 - nornir.core.task -    ERROR -      start() - Host 'BHN-A-6F-SW': task 'nornir_napalm_cli_commands_example' failed with traceback:
Traceback (most recent call last):
  File "/home/kali/.local/lib/python3.11/site-packages/nornir/core/task.py", line 99, in start
    r = self.task(self, **self.params)
        ^^^^^^^^^^^^^^^^^^^^^^^^^^^^^^
  File "/home/kali/Desktop/Nornir/2023/5.nornir_napalm/IITH/cli_inventory_nornir_napalm.py", line 13, in nornir_napalm_cli_commands_example
    task.run(task=napalm_cli, commands=[command])
  File "/home/kali/.local/lib/python3.11/site-packages/nornir/core/task.py", line 174, in run
    raise NornirSubTaskError(task=run_task, result=r)
nornir.core.exceptions.NornirSubTaskError: Subtask: napalm_cli (failed)


2024-04-19 05:07:09,245 - nornir.core.task -    ERROR -      start() - Host 'BHN-A-9F-SW': task 'napalm_cli' failed with traceback:
Traceback (most recent call last):
  File "/home/kali/.local/lib/python3.11/site-packages/netmiko/base_connection.py", line 1137, in establish_connection
    self.remote_conn_pre.connect(**ssh_connect_params)
  File "/usr/lib/python3/dist-packages/paramiko/client.py", line 450, in connect
    self._auth(
  File "/usr/lib/python3/dist-packages/paramiko/client.py", line 781, in _auth
    raise saved_exception
  File "/usr/lib/python3/dist-packages/paramiko/client.py", line 768, in _auth
    self._transport.auth_password(username, password)
  File "/usr/lib/python3/dist-packages/paramiko/transport.py", line 1564, in auth_password
    return self.auth_handler.wait_for_response(my_event)
           ^^^^^^^^^^^^^^^^^^^^^^^^^^^^^^^^^^^^^^^^^^^^^
  File "/usr/lib/python3/dist-packages/paramiko/auth_handler.py", line 259, in wait_for_response
    raise e
paramiko.ssh_exception.AuthenticationException: Authentication failed.

During handling of the above exception, another exception occurred:

Traceback (most recent call last):
  File "/home/kali/.local/lib/python3.11/site-packages/nornir/core/task.py", line 99, in start
    r = self.task(self, **self.params)
        ^^^^^^^^^^^^^^^^^^^^^^^^^^^^^^
  File "/home/kali/.local/lib/python3.11/site-packages/nornir_napalm/plugins/tasks/napalm_cli.py", line 19, in napalm_cli
    device = task.host.get_connection(CONNECTION_NAME, task.nornir.config)
             ^^^^^^^^^^^^^^^^^^^^^^^^^^^^^^^^^^^^^^^^^^^^^^^^^^^^^^^^^^^^^
  File "/home/kali/.local/lib/python3.11/site-packages/nornir/core/inventory.py", line 494, in get_connection
    self.open_connection(
  File "/home/kali/.local/lib/python3.11/site-packages/nornir/core/inventory.py", line 546, in open_connection
    conn_obj.open(
  File "/home/kali/.local/lib/python3.11/site-packages/nornir_napalm/plugins/connections/__init__.py", line 57, in open
    connection.open()
  File "/home/kali/.local/lib/python3.11/site-packages/napalm/ios/ios.py", line 173, in open
    self.device = self._netmiko_open(
                  ^^^^^^^^^^^^^^^^^^^
  File "/home/kali/.local/lib/python3.11/site-packages/napalm/base/base.py", line 114, in _netmiko_open
    self._netmiko_device = ConnectHandler(
                           ^^^^^^^^^^^^^^^
  File "/home/kali/.local/lib/python3.11/site-packages/netmiko/ssh_dispatcher.py", line 399, in ConnectHandler
    return ConnectionClass(*args, **kwargs)
           ^^^^^^^^^^^^^^^^^^^^^^^^^^^^^^^^
  File "/home/kali/.local/lib/python3.11/site-packages/netmiko/base_connection.py", line 488, in __init__
    self._open()
  File "/home/kali/.local/lib/python3.11/site-packages/netmiko/base_connection.py", line 493, in _open
    self.establish_connection()
  File "/home/kali/.local/lib/python3.11/site-packages/netmiko/base_connection.py", line 1174, in establish_connection
    raise NetmikoAuthenticationException(msg)
netmiko.exceptions.NetmikoAuthenticationException: Authentication to device failed.

Common causes of this problem are:
1. Invalid username and password
2. Incorrect SSH-key file
3. Connecting to the wrong device

Device settings: cisco_ios 10.5.48.54:22


Authentication failed.

2024-04-19 05:07:09,246 - nornir.core.task -    ERROR -      start() - Host 'BHN-A-9F-SW': task 'nornir_napalm_cli_commands_example' failed with traceback:
Traceback (most recent call last):
  File "/home/kali/.local/lib/python3.11/site-packages/nornir/core/task.py", line 99, in start
    r = self.task(self, **self.params)
        ^^^^^^^^^^^^^^^^^^^^^^^^^^^^^^
  File "/home/kali/Desktop/Nornir/2023/5.nornir_napalm/IITH/cli_inventory_nornir_napalm.py", line 13, in nornir_napalm_cli_commands_example
    task.run(task=napalm_cli, commands=[command])
  File "/home/kali/.local/lib/python3.11/site-packages/nornir/core/task.py", line 174, in run
    raise NornirSubTaskError(task=run_task, result=r)
nornir.core.exceptions.NornirSubTaskError: Subtask: napalm_cli (failed)


2024-04-19 05:07:33,667 -  nornir.core -     INFO -        run() - Running task 'nornir_napalm_cli_commands_example' with args {} on 33 hosts
2024-04-19 05:07:37,797 - nornir.core.task -    ERROR -      start() - Host 'BHN-A-3F-SW': task 'napalm_cli' failed with traceback:
Traceback (most recent call last):
  File "/home/kali/.local/lib/python3.11/site-packages/netmiko/base_connection.py", line 1137, in establish_connection
    self.remote_conn_pre.connect(**ssh_connect_params)
  File "/usr/lib/python3/dist-packages/paramiko/client.py", line 450, in connect
    self._auth(
  File "/usr/lib/python3/dist-packages/paramiko/client.py", line 781, in _auth
    raise saved_exception
  File "/usr/lib/python3/dist-packages/paramiko/client.py", line 768, in _auth
    self._transport.auth_password(username, password)
  File "/usr/lib/python3/dist-packages/paramiko/transport.py", line 1564, in auth_password
    return self.auth_handler.wait_for_response(my_event)
           ^^^^^^^^^^^^^^^^^^^^^^^^^^^^^^^^^^^^^^^^^^^^^
  File "/usr/lib/python3/dist-packages/paramiko/auth_handler.py", line 259, in wait_for_response
    raise e
paramiko.ssh_exception.AuthenticationException: Authentication failed.

During handling of the above exception, another exception occurred:

Traceback (most recent call last):
  File "/home/kali/.local/lib/python3.11/site-packages/nornir/core/task.py", line 99, in start
    r = self.task(self, **self.params)
        ^^^^^^^^^^^^^^^^^^^^^^^^^^^^^^
  File "/home/kali/.local/lib/python3.11/site-packages/nornir_napalm/plugins/tasks/napalm_cli.py", line 19, in napalm_cli
    device = task.host.get_connection(CONNECTION_NAME, task.nornir.config)
             ^^^^^^^^^^^^^^^^^^^^^^^^^^^^^^^^^^^^^^^^^^^^^^^^^^^^^^^^^^^^^
  File "/home/kali/.local/lib/python3.11/site-packages/nornir/core/inventory.py", line 494, in get_connection
    self.open_connection(
  File "/home/kali/.local/lib/python3.11/site-packages/nornir/core/inventory.py", line 546, in open_connection
    conn_obj.open(
  File "/home/kali/.local/lib/python3.11/site-packages/nornir_napalm/plugins/connections/__init__.py", line 57, in open
    connection.open()
  File "/home/kali/.local/lib/python3.11/site-packages/napalm/ios/ios.py", line 173, in open
    self.device = self._netmiko_open(
                  ^^^^^^^^^^^^^^^^^^^
  File "/home/kali/.local/lib/python3.11/site-packages/napalm/base/base.py", line 114, in _netmiko_open
    self._netmiko_device = ConnectHandler(
                           ^^^^^^^^^^^^^^^
  File "/home/kali/.local/lib/python3.11/site-packages/netmiko/ssh_dispatcher.py", line 399, in ConnectHandler
    return ConnectionClass(*args, **kwargs)
           ^^^^^^^^^^^^^^^^^^^^^^^^^^^^^^^^
  File "/home/kali/.local/lib/python3.11/site-packages/netmiko/base_connection.py", line 488, in __init__
    self._open()
  File "/home/kali/.local/lib/python3.11/site-packages/netmiko/base_connection.py", line 493, in _open
    self.establish_connection()
  File "/home/kali/.local/lib/python3.11/site-packages/netmiko/base_connection.py", line 1174, in establish_connection
    raise NetmikoAuthenticationException(msg)
netmiko.exceptions.NetmikoAuthenticationException: Authentication to device failed.

Common causes of this problem are:
1. Invalid username and password
2. Incorrect SSH-key file
3. Connecting to the wrong device

Device settings: cisco_ios 10.5.48.52:22


Authentication failed.

2024-04-19 05:07:37,798 - nornir.core.task -    ERROR -      start() - Host 'BHN-A-3F-SW': task 'nornir_napalm_cli_commands_example' failed with traceback:
Traceback (most recent call last):
  File "/home/kali/.local/lib/python3.11/site-packages/nornir/core/task.py", line 99, in start
    r = self.task(self, **self.params)
        ^^^^^^^^^^^^^^^^^^^^^^^^^^^^^^
  File "/home/kali/Desktop/Nornir/2023/5.nornir_napalm/IITH/cli_inventory_nornir_napalm.py", line 13, in nornir_napalm_cli_commands_example
    task.run(task=napalm_cli, commands=[command])
  File "/home/kali/.local/lib/python3.11/site-packages/nornir/core/task.py", line 174, in run
    raise NornirSubTaskError(task=run_task, result=r)
nornir.core.exceptions.NornirSubTaskError: Subtask: napalm_cli (failed)


2024-04-19 05:08:10,343 -  nornir.core -     INFO -        run() - Running task 'nornir_napalm_cli_commands_example' with args {} on 57 hosts
2024-04-19 05:08:14,459 - nornir.core.task -    ERROR -      start() - Host 'BHN-B-3F-SW': task 'napalm_cli' failed with traceback:
Traceback (most recent call last):
  File "/home/kali/.local/lib/python3.11/site-packages/netmiko/base_connection.py", line 1137, in establish_connection
    self.remote_conn_pre.connect(**ssh_connect_params)
  File "/usr/lib/python3/dist-packages/paramiko/client.py", line 450, in connect
    self._auth(
  File "/usr/lib/python3/dist-packages/paramiko/client.py", line 781, in _auth
    raise saved_exception
  File "/usr/lib/python3/dist-packages/paramiko/client.py", line 768, in _auth
    self._transport.auth_password(username, password)
  File "/usr/lib/python3/dist-packages/paramiko/transport.py", line 1564, in auth_password
    return self.auth_handler.wait_for_response(my_event)
           ^^^^^^^^^^^^^^^^^^^^^^^^^^^^^^^^^^^^^^^^^^^^^
  File "/usr/lib/python3/dist-packages/paramiko/auth_handler.py", line 259, in wait_for_response
    raise e
paramiko.ssh_exception.AuthenticationException: Authentication failed.

During handling of the above exception, another exception occurred:

Traceback (most recent call last):
  File "/home/kali/.local/lib/python3.11/site-packages/nornir/core/task.py", line 99, in start
    r = self.task(self, **self.params)
        ^^^^^^^^^^^^^^^^^^^^^^^^^^^^^^
  File "/home/kali/.local/lib/python3.11/site-packages/nornir_napalm/plugins/tasks/napalm_cli.py", line 19, in napalm_cli
    device = task.host.get_connection(CONNECTION_NAME, task.nornir.config)
             ^^^^^^^^^^^^^^^^^^^^^^^^^^^^^^^^^^^^^^^^^^^^^^^^^^^^^^^^^^^^^
  File "/home/kali/.local/lib/python3.11/site-packages/nornir/core/inventory.py", line 494, in get_connection
    self.open_connection(
  File "/home/kali/.local/lib/python3.11/site-packages/nornir/core/inventory.py", line 546, in open_connection
    conn_obj.open(
  File "/home/kali/.local/lib/python3.11/site-packages/nornir_napalm/plugins/connections/__init__.py", line 57, in open
    connection.open()
  File "/home/kali/.local/lib/python3.11/site-packages/napalm/ios/ios.py", line 173, in open
    self.device = self._netmiko_open(
                  ^^^^^^^^^^^^^^^^^^^
  File "/home/kali/.local/lib/python3.11/site-packages/napalm/base/base.py", line 114, in _netmiko_open
    self._netmiko_device = ConnectHandler(
                           ^^^^^^^^^^^^^^^
  File "/home/kali/.local/lib/python3.11/site-packages/netmiko/ssh_dispatcher.py", line 399, in ConnectHandler
    return ConnectionClass(*args, **kwargs)
           ^^^^^^^^^^^^^^^^^^^^^^^^^^^^^^^^
  File "/home/kali/.local/lib/python3.11/site-packages/netmiko/base_connection.py", line 488, in __init__
    self._open()
  File "/home/kali/.local/lib/python3.11/site-packages/netmiko/base_connection.py", line 493, in _open
    self.establish_connection()
  File "/home/kali/.local/lib/python3.11/site-packages/netmiko/base_connection.py", line 1174, in establish_connection
    raise NetmikoAuthenticationException(msg)
netmiko.exceptions.NetmikoAuthenticationException: Authentication to device failed.

Common causes of this problem are:
1. Invalid username and password
2. Incorrect SSH-key file
3. Connecting to the wrong device

Device settings: cisco_ios 10.5.48.57:22


Authentication failed.

2024-04-19 05:08:14,461 - nornir.core.task -    ERROR -      start() - Host 'BHN-B-3F-SW': task 'nornir_napalm_cli_commands_example' failed with traceback:
Traceback (most recent call last):
  File "/home/kali/.local/lib/python3.11/site-packages/nornir/core/task.py", line 99, in start
    r = self.task(self, **self.params)
        ^^^^^^^^^^^^^^^^^^^^^^^^^^^^^^
  File "/home/kali/Desktop/Nornir/2023/5.nornir_napalm/IITH/cli_inventory_nornir_napalm.py", line 13, in nornir_napalm_cli_commands_example
    task.run(task=napalm_cli, commands=[command])
  File "/home/kali/.local/lib/python3.11/site-packages/nornir/core/task.py", line 174, in run
    raise NornirSubTaskError(task=run_task, result=r)
nornir.core.exceptions.NornirSubTaskError: Subtask: napalm_cli (failed)


2024-04-19 05:08:14,462 - nornir.core.task -    ERROR -      start() - Host 'BHN-A-6F-SW': task 'napalm_cli' failed with traceback:
Traceback (most recent call last):
  File "/home/kali/.local/lib/python3.11/site-packages/netmiko/base_connection.py", line 1137, in establish_connection
    self.remote_conn_pre.connect(**ssh_connect_params)
  File "/usr/lib/python3/dist-packages/paramiko/client.py", line 450, in connect
    self._auth(
  File "/usr/lib/python3/dist-packages/paramiko/client.py", line 781, in _auth
    raise saved_exception
  File "/usr/lib/python3/dist-packages/paramiko/client.py", line 768, in _auth
    self._transport.auth_password(username, password)
  File "/usr/lib/python3/dist-packages/paramiko/transport.py", line 1564, in auth_password
    return self.auth_handler.wait_for_response(my_event)
           ^^^^^^^^^^^^^^^^^^^^^^^^^^^^^^^^^^^^^^^^^^^^^
  File "/usr/lib/python3/dist-packages/paramiko/auth_handler.py", line 259, in wait_for_response
    raise e
paramiko.ssh_exception.AuthenticationException: Authentication failed.

During handling of the above exception, another exception occurred:

Traceback (most recent call last):
  File "/home/kali/.local/lib/python3.11/site-packages/nornir/core/task.py", line 99, in start
    r = self.task(self, **self.params)
        ^^^^^^^^^^^^^^^^^^^^^^^^^^^^^^
  File "/home/kali/.local/lib/python3.11/site-packages/nornir_napalm/plugins/tasks/napalm_cli.py", line 19, in napalm_cli
    device = task.host.get_connection(CONNECTION_NAME, task.nornir.config)
             ^^^^^^^^^^^^^^^^^^^^^^^^^^^^^^^^^^^^^^^^^^^^^^^^^^^^^^^^^^^^^
  File "/home/kali/.local/lib/python3.11/site-packages/nornir/core/inventory.py", line 494, in get_connection
    self.open_connection(
  File "/home/kali/.local/lib/python3.11/site-packages/nornir/core/inventory.py", line 546, in open_connection
    conn_obj.open(
  File "/home/kali/.local/lib/python3.11/site-packages/nornir_napalm/plugins/connections/__init__.py", line 57, in open
    connection.open()
  File "/home/kali/.local/lib/python3.11/site-packages/napalm/ios/ios.py", line 173, in open
    self.device = self._netmiko_open(
                  ^^^^^^^^^^^^^^^^^^^
  File "/home/kali/.local/lib/python3.11/site-packages/napalm/base/base.py", line 114, in _netmiko_open
    self._netmiko_device = ConnectHandler(
                           ^^^^^^^^^^^^^^^
  File "/home/kali/.local/lib/python3.11/site-packages/netmiko/ssh_dispatcher.py", line 399, in ConnectHandler
    return ConnectionClass(*args, **kwargs)
           ^^^^^^^^^^^^^^^^^^^^^^^^^^^^^^^^
  File "/home/kali/.local/lib/python3.11/site-packages/netmiko/base_connection.py", line 488, in __init__
    self._open()
  File "/home/kali/.local/lib/python3.11/site-packages/netmiko/base_connection.py", line 493, in _open
    self.establish_connection()
  File "/home/kali/.local/lib/python3.11/site-packages/netmiko/base_connection.py", line 1174, in establish_connection
    raise NetmikoAuthenticationException(msg)
netmiko.exceptions.NetmikoAuthenticationException: Authentication to device failed.

Common causes of this problem are:
1. Invalid username and password
2. Incorrect SSH-key file
3. Connecting to the wrong device

Device settings: cisco_ios 10.5.48.53:22


Authentication failed.

2024-04-19 05:08:14,463 - nornir.core.task -    ERROR -      start() - Host 'BHN-B-9F-SW': task 'napalm_cli' failed with traceback:
Traceback (most recent call last):
  File "/home/kali/.local/lib/python3.11/site-packages/netmiko/base_connection.py", line 1137, in establish_connection
    self.remote_conn_pre.connect(**ssh_connect_params)
  File "/usr/lib/python3/dist-packages/paramiko/client.py", line 450, in connect
    self._auth(
  File "/usr/lib/python3/dist-packages/paramiko/client.py", line 781, in _auth
    raise saved_exception
  File "/usr/lib/python3/dist-packages/paramiko/client.py", line 768, in _auth
    self._transport.auth_password(username, password)
  File "/usr/lib/python3/dist-packages/paramiko/transport.py", line 1564, in auth_password
    return self.auth_handler.wait_for_response(my_event)
           ^^^^^^^^^^^^^^^^^^^^^^^^^^^^^^^^^^^^^^^^^^^^^
  File "/usr/lib/python3/dist-packages/paramiko/auth_handler.py", line 259, in wait_for_response
    raise e
paramiko.ssh_exception.AuthenticationException: Authentication failed.

During handling of the above exception, another exception occurred:

Traceback (most recent call last):
  File "/home/kali/.local/lib/python3.11/site-packages/nornir/core/task.py", line 99, in start
    r = self.task(self, **self.params)
        ^^^^^^^^^^^^^^^^^^^^^^^^^^^^^^
  File "/home/kali/.local/lib/python3.11/site-packages/nornir_napalm/plugins/tasks/napalm_cli.py", line 19, in napalm_cli
    device = task.host.get_connection(CONNECTION_NAME, task.nornir.config)
             ^^^^^^^^^^^^^^^^^^^^^^^^^^^^^^^^^^^^^^^^^^^^^^^^^^^^^^^^^^^^^
  File "/home/kali/.local/lib/python3.11/site-packages/nornir/core/inventory.py", line 494, in get_connection
    self.open_connection(
  File "/home/kali/.local/lib/python3.11/site-packages/nornir/core/inventory.py", line 546, in open_connection
    conn_obj.open(
  File "/home/kali/.local/lib/python3.11/site-packages/nornir_napalm/plugins/connections/__init__.py", line 57, in open
    connection.open()
  File "/home/kali/.local/lib/python3.11/site-packages/napalm/ios/ios.py", line 173, in open
    self.device = self._netmiko_open(
                  ^^^^^^^^^^^^^^^^^^^
  File "/home/kali/.local/lib/python3.11/site-packages/napalm/base/base.py", line 114, in _netmiko_open
    self._netmiko_device = ConnectHandler(
                           ^^^^^^^^^^^^^^^
  File "/home/kali/.local/lib/python3.11/site-packages/netmiko/ssh_dispatcher.py", line 399, in ConnectHandler
    return ConnectionClass(*args, **kwargs)
           ^^^^^^^^^^^^^^^^^^^^^^^^^^^^^^^^
  File "/home/kali/.local/lib/python3.11/site-packages/netmiko/base_connection.py", line 488, in __init__
    self._open()
  File "/home/kali/.local/lib/python3.11/site-packages/netmiko/base_connection.py", line 493, in _open
    self.establish_connection()
  File "/home/kali/.local/lib/python3.11/site-packages/netmiko/base_connection.py", line 1174, in establish_connection
    raise NetmikoAuthenticationException(msg)
netmiko.exceptions.NetmikoAuthenticationException: Authentication to device failed.

Common causes of this problem are:
1. Invalid username and password
2. Incorrect SSH-key file
3. Connecting to the wrong device

Device settings: cisco_ios 10.5.48.59:22


Authentication failed.

2024-04-19 05:08:14,464 - nornir.core.task -    ERROR -      start() - Host 'BHN-A-6F-SW': task 'nornir_napalm_cli_commands_example' failed with traceback:
Traceback (most recent call last):
  File "/home/kali/.local/lib/python3.11/site-packages/nornir/core/task.py", line 99, in start
    r = self.task(self, **self.params)
        ^^^^^^^^^^^^^^^^^^^^^^^^^^^^^^
  File "/home/kali/Desktop/Nornir/2023/5.nornir_napalm/IITH/cli_inventory_nornir_napalm.py", line 13, in nornir_napalm_cli_commands_example
    task.run(task=napalm_cli, commands=[command])
  File "/home/kali/.local/lib/python3.11/site-packages/nornir/core/task.py", line 174, in run
    raise NornirSubTaskError(task=run_task, result=r)
nornir.core.exceptions.NornirSubTaskError: Subtask: napalm_cli (failed)


2024-04-19 05:08:14,464 - nornir.core.task -    ERROR -      start() - Host 'BHN-B-9F-SW': task 'nornir_napalm_cli_commands_example' failed with traceback:
Traceback (most recent call last):
  File "/home/kali/.local/lib/python3.11/site-packages/nornir/core/task.py", line 99, in start
    r = self.task(self, **self.params)
        ^^^^^^^^^^^^^^^^^^^^^^^^^^^^^^
  File "/home/kali/Desktop/Nornir/2023/5.nornir_napalm/IITH/cli_inventory_nornir_napalm.py", line 13, in nornir_napalm_cli_commands_example
    task.run(task=napalm_cli, commands=[command])
  File "/home/kali/.local/lib/python3.11/site-packages/nornir/core/task.py", line 174, in run
    raise NornirSubTaskError(task=run_task, result=r)
nornir.core.exceptions.NornirSubTaskError: Subtask: napalm_cli (failed)


2024-04-19 05:08:14,631 - nornir.core.task -    ERROR -      start() - Host 'BHN-B-6F-SW': task 'napalm_cli' failed with traceback:
Traceback (most recent call last):
  File "/home/kali/.local/lib/python3.11/site-packages/netmiko/base_connection.py", line 1137, in establish_connection
    self.remote_conn_pre.connect(**ssh_connect_params)
  File "/usr/lib/python3/dist-packages/paramiko/client.py", line 450, in connect
    self._auth(
  File "/usr/lib/python3/dist-packages/paramiko/client.py", line 781, in _auth
    raise saved_exception
  File "/usr/lib/python3/dist-packages/paramiko/client.py", line 768, in _auth
    self._transport.auth_password(username, password)
  File "/usr/lib/python3/dist-packages/paramiko/transport.py", line 1564, in auth_password
    return self.auth_handler.wait_for_response(my_event)
           ^^^^^^^^^^^^^^^^^^^^^^^^^^^^^^^^^^^^^^^^^^^^^
  File "/usr/lib/python3/dist-packages/paramiko/auth_handler.py", line 259, in wait_for_response
    raise e
paramiko.ssh_exception.AuthenticationException: Authentication failed.

During handling of the above exception, another exception occurred:

Traceback (most recent call last):
  File "/home/kali/.local/lib/python3.11/site-packages/nornir/core/task.py", line 99, in start
    r = self.task(self, **self.params)
        ^^^^^^^^^^^^^^^^^^^^^^^^^^^^^^
  File "/home/kali/.local/lib/python3.11/site-packages/nornir_napalm/plugins/tasks/napalm_cli.py", line 19, in napalm_cli
    device = task.host.get_connection(CONNECTION_NAME, task.nornir.config)
             ^^^^^^^^^^^^^^^^^^^^^^^^^^^^^^^^^^^^^^^^^^^^^^^^^^^^^^^^^^^^^
  File "/home/kali/.local/lib/python3.11/site-packages/nornir/core/inventory.py", line 494, in get_connection
    self.open_connection(
  File "/home/kali/.local/lib/python3.11/site-packages/nornir/core/inventory.py", line 546, in open_connection
    conn_obj.open(
  File "/home/kali/.local/lib/python3.11/site-packages/nornir_napalm/plugins/connections/__init__.py", line 57, in open
    connection.open()
  File "/home/kali/.local/lib/python3.11/site-packages/napalm/ios/ios.py", line 173, in open
    self.device = self._netmiko_open(
                  ^^^^^^^^^^^^^^^^^^^
  File "/home/kali/.local/lib/python3.11/site-packages/napalm/base/base.py", line 114, in _netmiko_open
    self._netmiko_device = ConnectHandler(
                           ^^^^^^^^^^^^^^^
  File "/home/kali/.local/lib/python3.11/site-packages/netmiko/ssh_dispatcher.py", line 399, in ConnectHandler
    return ConnectionClass(*args, **kwargs)
           ^^^^^^^^^^^^^^^^^^^^^^^^^^^^^^^^
  File "/home/kali/.local/lib/python3.11/site-packages/netmiko/base_connection.py", line 488, in __init__
    self._open()
  File "/home/kali/.local/lib/python3.11/site-packages/netmiko/base_connection.py", line 493, in _open
    self.establish_connection()
  File "/home/kali/.local/lib/python3.11/site-packages/netmiko/base_connection.py", line 1174, in establish_connection
    raise NetmikoAuthenticationException(msg)
netmiko.exceptions.NetmikoAuthenticationException: Authentication to device failed.

Common causes of this problem are:
1. Invalid username and password
2. Incorrect SSH-key file
3. Connecting to the wrong device

Device settings: cisco_ios 10.5.48.58:22


Authentication failed.

2024-04-19 05:08:14,634 - nornir.core.task -    ERROR -      start() - Host 'BHN-B-6F-SW': task 'nornir_napalm_cli_commands_example' failed with traceback:
Traceback (most recent call last):
  File "/home/kali/.local/lib/python3.11/site-packages/nornir/core/task.py", line 99, in start
    r = self.task(self, **self.params)
        ^^^^^^^^^^^^^^^^^^^^^^^^^^^^^^
  File "/home/kali/Desktop/Nornir/2023/5.nornir_napalm/IITH/cli_inventory_nornir_napalm.py", line 13, in nornir_napalm_cli_commands_example
    task.run(task=napalm_cli, commands=[command])
  File "/home/kali/.local/lib/python3.11/site-packages/nornir/core/task.py", line 174, in run
    raise NornirSubTaskError(task=run_task, result=r)
nornir.core.exceptions.NornirSubTaskError: Subtask: napalm_cli (failed)


2024-04-19 05:08:14,635 - nornir.core.task -    ERROR -      start() - Host 'BHN-A-9F-SW': task 'napalm_cli' failed with traceback:
Traceback (most recent call last):
  File "/home/kali/.local/lib/python3.11/site-packages/netmiko/base_connection.py", line 1137, in establish_connection
    self.remote_conn_pre.connect(**ssh_connect_params)
  File "/usr/lib/python3/dist-packages/paramiko/client.py", line 450, in connect
    self._auth(
  File "/usr/lib/python3/dist-packages/paramiko/client.py", line 781, in _auth
    raise saved_exception
  File "/usr/lib/python3/dist-packages/paramiko/client.py", line 768, in _auth
    self._transport.auth_password(username, password)
  File "/usr/lib/python3/dist-packages/paramiko/transport.py", line 1564, in auth_password
    return self.auth_handler.wait_for_response(my_event)
           ^^^^^^^^^^^^^^^^^^^^^^^^^^^^^^^^^^^^^^^^^^^^^
  File "/usr/lib/python3/dist-packages/paramiko/auth_handler.py", line 259, in wait_for_response
    raise e
paramiko.ssh_exception.AuthenticationException: Authentication failed.

During handling of the above exception, another exception occurred:

Traceback (most recent call last):
  File "/home/kali/.local/lib/python3.11/site-packages/nornir/core/task.py", line 99, in start
    r = self.task(self, **self.params)
        ^^^^^^^^^^^^^^^^^^^^^^^^^^^^^^
  File "/home/kali/.local/lib/python3.11/site-packages/nornir_napalm/plugins/tasks/napalm_cli.py", line 19, in napalm_cli
    device = task.host.get_connection(CONNECTION_NAME, task.nornir.config)
             ^^^^^^^^^^^^^^^^^^^^^^^^^^^^^^^^^^^^^^^^^^^^^^^^^^^^^^^^^^^^^
  File "/home/kali/.local/lib/python3.11/site-packages/nornir/core/inventory.py", line 494, in get_connection
    self.open_connection(
  File "/home/kali/.local/lib/python3.11/site-packages/nornir/core/inventory.py", line 546, in open_connection
    conn_obj.open(
  File "/home/kali/.local/lib/python3.11/site-packages/nornir_napalm/plugins/connections/__init__.py", line 57, in open
    connection.open()
  File "/home/kali/.local/lib/python3.11/site-packages/napalm/ios/ios.py", line 173, in open
    self.device = self._netmiko_open(
                  ^^^^^^^^^^^^^^^^^^^
  File "/home/kali/.local/lib/python3.11/site-packages/napalm/base/base.py", line 114, in _netmiko_open
    self._netmiko_device = ConnectHandler(
                           ^^^^^^^^^^^^^^^
  File "/home/kali/.local/lib/python3.11/site-packages/netmiko/ssh_dispatcher.py", line 399, in ConnectHandler
    return ConnectionClass(*args, **kwargs)
           ^^^^^^^^^^^^^^^^^^^^^^^^^^^^^^^^
  File "/home/kali/.local/lib/python3.11/site-packages/netmiko/base_connection.py", line 488, in __init__
    self._open()
  File "/home/kali/.local/lib/python3.11/site-packages/netmiko/base_connection.py", line 493, in _open
    self.establish_connection()
  File "/home/kali/.local/lib/python3.11/site-packages/netmiko/base_connection.py", line 1174, in establish_connection
    raise NetmikoAuthenticationException(msg)
netmiko.exceptions.NetmikoAuthenticationException: Authentication to device failed.

Common causes of this problem are:
1. Invalid username and password
2. Incorrect SSH-key file
3. Connecting to the wrong device

Device settings: cisco_ios 10.5.48.54:22


Authentication failed.

2024-04-19 05:08:14,637 - nornir.core.task -    ERROR -      start() - Host 'BHN-A-9F-SW': task 'nornir_napalm_cli_commands_example' failed with traceback:
Traceback (most recent call last):
  File "/home/kali/.local/lib/python3.11/site-packages/nornir/core/task.py", line 99, in start
    r = self.task(self, **self.params)
        ^^^^^^^^^^^^^^^^^^^^^^^^^^^^^^
  File "/home/kali/Desktop/Nornir/2023/5.nornir_napalm/IITH/cli_inventory_nornir_napalm.py", line 13, in nornir_napalm_cli_commands_example
    task.run(task=napalm_cli, commands=[command])
  File "/home/kali/.local/lib/python3.11/site-packages/nornir/core/task.py", line 174, in run
    raise NornirSubTaskError(task=run_task, result=r)
nornir.core.exceptions.NornirSubTaskError: Subtask: napalm_cli (failed)


2024-04-19 05:08:46,788 -  nornir.core -     INFO -        run() - Running task 'nornir_napalm_cli_commands_example' with args {} on 57 hosts
2024-04-19 05:08:50,917 - nornir.core.task -    ERROR -      start() - Host 'BHN-A-9F-SW': task 'napalm_cli' failed with traceback:
Traceback (most recent call last):
  File "/home/kali/.local/lib/python3.11/site-packages/netmiko/base_connection.py", line 1137, in establish_connection
    self.remote_conn_pre.connect(**ssh_connect_params)
  File "/usr/lib/python3/dist-packages/paramiko/client.py", line 450, in connect
    self._auth(
  File "/usr/lib/python3/dist-packages/paramiko/client.py", line 781, in _auth
    raise saved_exception
  File "/usr/lib/python3/dist-packages/paramiko/client.py", line 768, in _auth
    self._transport.auth_password(username, password)
  File "/usr/lib/python3/dist-packages/paramiko/transport.py", line 1564, in auth_password
    return self.auth_handler.wait_for_response(my_event)
           ^^^^^^^^^^^^^^^^^^^^^^^^^^^^^^^^^^^^^^^^^^^^^
  File "/usr/lib/python3/dist-packages/paramiko/auth_handler.py", line 259, in wait_for_response
    raise e
paramiko.ssh_exception.AuthenticationException: Authentication failed.

During handling of the above exception, another exception occurred:

Traceback (most recent call last):
  File "/home/kali/.local/lib/python3.11/site-packages/nornir/core/task.py", line 99, in start
    r = self.task(self, **self.params)
        ^^^^^^^^^^^^^^^^^^^^^^^^^^^^^^
  File "/home/kali/.local/lib/python3.11/site-packages/nornir_napalm/plugins/tasks/napalm_cli.py", line 19, in napalm_cli
    device = task.host.get_connection(CONNECTION_NAME, task.nornir.config)
             ^^^^^^^^^^^^^^^^^^^^^^^^^^^^^^^^^^^^^^^^^^^^^^^^^^^^^^^^^^^^^
  File "/home/kali/.local/lib/python3.11/site-packages/nornir/core/inventory.py", line 494, in get_connection
    self.open_connection(
  File "/home/kali/.local/lib/python3.11/site-packages/nornir/core/inventory.py", line 546, in open_connection
    conn_obj.open(
  File "/home/kali/.local/lib/python3.11/site-packages/nornir_napalm/plugins/connections/__init__.py", line 57, in open
    connection.open()
  File "/home/kali/.local/lib/python3.11/site-packages/napalm/ios/ios.py", line 173, in open
    self.device = self._netmiko_open(
                  ^^^^^^^^^^^^^^^^^^^
  File "/home/kali/.local/lib/python3.11/site-packages/napalm/base/base.py", line 114, in _netmiko_open
    self._netmiko_device = ConnectHandler(
                           ^^^^^^^^^^^^^^^
  File "/home/kali/.local/lib/python3.11/site-packages/netmiko/ssh_dispatcher.py", line 399, in ConnectHandler
    return ConnectionClass(*args, **kwargs)
           ^^^^^^^^^^^^^^^^^^^^^^^^^^^^^^^^
  File "/home/kali/.local/lib/python3.11/site-packages/netmiko/base_connection.py", line 488, in __init__
    self._open()
  File "/home/kali/.local/lib/python3.11/site-packages/netmiko/base_connection.py", line 493, in _open
    self.establish_connection()
  File "/home/kali/.local/lib/python3.11/site-packages/netmiko/base_connection.py", line 1174, in establish_connection
    raise NetmikoAuthenticationException(msg)
netmiko.exceptions.NetmikoAuthenticationException: Authentication to device failed.

Common causes of this problem are:
1. Invalid username and password
2. Incorrect SSH-key file
3. Connecting to the wrong device

Device settings: cisco_ios 10.5.48.54:22


Authentication failed.

2024-04-19 05:08:50,919 - nornir.core.task -    ERROR -      start() - Host 'BHN-B-9F-SW': task 'napalm_cli' failed with traceback:
Traceback (most recent call last):
  File "/home/kali/.local/lib/python3.11/site-packages/netmiko/base_connection.py", line 1137, in establish_connection
    self.remote_conn_pre.connect(**ssh_connect_params)
  File "/usr/lib/python3/dist-packages/paramiko/client.py", line 450, in connect
    self._auth(
  File "/usr/lib/python3/dist-packages/paramiko/client.py", line 781, in _auth
    raise saved_exception
  File "/usr/lib/python3/dist-packages/paramiko/client.py", line 768, in _auth
    self._transport.auth_password(username, password)
  File "/usr/lib/python3/dist-packages/paramiko/transport.py", line 1564, in auth_password
    return self.auth_handler.wait_for_response(my_event)
           ^^^^^^^^^^^^^^^^^^^^^^^^^^^^^^^^^^^^^^^^^^^^^
  File "/usr/lib/python3/dist-packages/paramiko/auth_handler.py", line 259, in wait_for_response
    raise e
paramiko.ssh_exception.AuthenticationException: Authentication failed.

During handling of the above exception, another exception occurred:

Traceback (most recent call last):
  File "/home/kali/.local/lib/python3.11/site-packages/nornir/core/task.py", line 99, in start
    r = self.task(self, **self.params)
        ^^^^^^^^^^^^^^^^^^^^^^^^^^^^^^
  File "/home/kali/.local/lib/python3.11/site-packages/nornir_napalm/plugins/tasks/napalm_cli.py", line 19, in napalm_cli
    device = task.host.get_connection(CONNECTION_NAME, task.nornir.config)
             ^^^^^^^^^^^^^^^^^^^^^^^^^^^^^^^^^^^^^^^^^^^^^^^^^^^^^^^^^^^^^
  File "/home/kali/.local/lib/python3.11/site-packages/nornir/core/inventory.py", line 494, in get_connection
    self.open_connection(
  File "/home/kali/.local/lib/python3.11/site-packages/nornir/core/inventory.py", line 546, in open_connection
    conn_obj.open(
  File "/home/kali/.local/lib/python3.11/site-packages/nornir_napalm/plugins/connections/__init__.py", line 57, in open
    connection.open()
  File "/home/kali/.local/lib/python3.11/site-packages/napalm/ios/ios.py", line 173, in open
    self.device = self._netmiko_open(
                  ^^^^^^^^^^^^^^^^^^^
  File "/home/kali/.local/lib/python3.11/site-packages/napalm/base/base.py", line 114, in _netmiko_open
    self._netmiko_device = ConnectHandler(
                           ^^^^^^^^^^^^^^^
  File "/home/kali/.local/lib/python3.11/site-packages/netmiko/ssh_dispatcher.py", line 399, in ConnectHandler
    return ConnectionClass(*args, **kwargs)
           ^^^^^^^^^^^^^^^^^^^^^^^^^^^^^^^^
  File "/home/kali/.local/lib/python3.11/site-packages/netmiko/base_connection.py", line 488, in __init__
    self._open()
  File "/home/kali/.local/lib/python3.11/site-packages/netmiko/base_connection.py", line 493, in _open
    self.establish_connection()
  File "/home/kali/.local/lib/python3.11/site-packages/netmiko/base_connection.py", line 1174, in establish_connection
    raise NetmikoAuthenticationException(msg)
netmiko.exceptions.NetmikoAuthenticationException: Authentication to device failed.

Common causes of this problem are:
1. Invalid username and password
2. Incorrect SSH-key file
3. Connecting to the wrong device

Device settings: cisco_ios 10.5.48.59:22


Authentication failed.

2024-04-19 05:08:50,921 - nornir.core.task -    ERROR -      start() - Host 'BHN-B-9F-SW': task 'nornir_napalm_cli_commands_example' failed with traceback:
Traceback (most recent call last):
  File "/home/kali/.local/lib/python3.11/site-packages/nornir/core/task.py", line 99, in start
    r = self.task(self, **self.params)
        ^^^^^^^^^^^^^^^^^^^^^^^^^^^^^^
  File "/home/kali/Desktop/Nornir/2023/5.nornir_napalm/IITH/cli_inventory_nornir_napalm.py", line 13, in nornir_napalm_cli_commands_example
    task.run(task=napalm_cli, commands=[command])
  File "/home/kali/.local/lib/python3.11/site-packages/nornir/core/task.py", line 174, in run
    raise NornirSubTaskError(task=run_task, result=r)
nornir.core.exceptions.NornirSubTaskError: Subtask: napalm_cli (failed)


2024-04-19 05:08:50,920 - nornir.core.task -    ERROR -      start() - Host 'BHN-B-6F-SW': task 'napalm_cli' failed with traceback:
Traceback (most recent call last):
  File "/home/kali/.local/lib/python3.11/site-packages/netmiko/base_connection.py", line 1137, in establish_connection
    self.remote_conn_pre.connect(**ssh_connect_params)
  File "/usr/lib/python3/dist-packages/paramiko/client.py", line 450, in connect
    self._auth(
  File "/usr/lib/python3/dist-packages/paramiko/client.py", line 781, in _auth
    raise saved_exception
  File "/usr/lib/python3/dist-packages/paramiko/client.py", line 768, in _auth
    self._transport.auth_password(username, password)
  File "/usr/lib/python3/dist-packages/paramiko/transport.py", line 1564, in auth_password
    return self.auth_handler.wait_for_response(my_event)
           ^^^^^^^^^^^^^^^^^^^^^^^^^^^^^^^^^^^^^^^^^^^^^
  File "/usr/lib/python3/dist-packages/paramiko/auth_handler.py", line 259, in wait_for_response
    raise e
paramiko.ssh_exception.AuthenticationException: Authentication failed.

During handling of the above exception, another exception occurred:

Traceback (most recent call last):
  File "/home/kali/.local/lib/python3.11/site-packages/nornir/core/task.py", line 99, in start
    r = self.task(self, **self.params)
        ^^^^^^^^^^^^^^^^^^^^^^^^^^^^^^
  File "/home/kali/.local/lib/python3.11/site-packages/nornir_napalm/plugins/tasks/napalm_cli.py", line 19, in napalm_cli
    device = task.host.get_connection(CONNECTION_NAME, task.nornir.config)
             ^^^^^^^^^^^^^^^^^^^^^^^^^^^^^^^^^^^^^^^^^^^^^^^^^^^^^^^^^^^^^
  File "/home/kali/.local/lib/python3.11/site-packages/nornir/core/inventory.py", line 494, in get_connection
    self.open_connection(
  File "/home/kali/.local/lib/python3.11/site-packages/nornir/core/inventory.py", line 546, in open_connection
    conn_obj.open(
  File "/home/kali/.local/lib/python3.11/site-packages/nornir_napalm/plugins/connections/__init__.py", line 57, in open
    connection.open()
  File "/home/kali/.local/lib/python3.11/site-packages/napalm/ios/ios.py", line 173, in open
    self.device = self._netmiko_open(
                  ^^^^^^^^^^^^^^^^^^^
  File "/home/kali/.local/lib/python3.11/site-packages/napalm/base/base.py", line 114, in _netmiko_open
    self._netmiko_device = ConnectHandler(
                           ^^^^^^^^^^^^^^^
  File "/home/kali/.local/lib/python3.11/site-packages/netmiko/ssh_dispatcher.py", line 399, in ConnectHandler
    return ConnectionClass(*args, **kwargs)
           ^^^^^^^^^^^^^^^^^^^^^^^^^^^^^^^^
  File "/home/kali/.local/lib/python3.11/site-packages/netmiko/base_connection.py", line 488, in __init__
    self._open()
  File "/home/kali/.local/lib/python3.11/site-packages/netmiko/base_connection.py", line 493, in _open
    self.establish_connection()
  File "/home/kali/.local/lib/python3.11/site-packages/netmiko/base_connection.py", line 1174, in establish_connection
    raise NetmikoAuthenticationException(msg)
netmiko.exceptions.NetmikoAuthenticationException: Authentication to device failed.

Common causes of this problem are:
1. Invalid username and password
2. Incorrect SSH-key file
3. Connecting to the wrong device

Device settings: cisco_ios 10.5.48.58:22


Authentication failed.

2024-04-19 05:08:50,922 - nornir.core.task -    ERROR -      start() - Host 'BHN-B-3F-SW': task 'napalm_cli' failed with traceback:
Traceback (most recent call last):
  File "/home/kali/.local/lib/python3.11/site-packages/netmiko/base_connection.py", line 1137, in establish_connection
    self.remote_conn_pre.connect(**ssh_connect_params)
  File "/usr/lib/python3/dist-packages/paramiko/client.py", line 450, in connect
    self._auth(
  File "/usr/lib/python3/dist-packages/paramiko/client.py", line 781, in _auth
    raise saved_exception
  File "/usr/lib/python3/dist-packages/paramiko/client.py", line 768, in _auth
    self._transport.auth_password(username, password)
  File "/usr/lib/python3/dist-packages/paramiko/transport.py", line 1564, in auth_password
    return self.auth_handler.wait_for_response(my_event)
           ^^^^^^^^^^^^^^^^^^^^^^^^^^^^^^^^^^^^^^^^^^^^^
  File "/usr/lib/python3/dist-packages/paramiko/auth_handler.py", line 259, in wait_for_response
    raise e
paramiko.ssh_exception.AuthenticationException: Authentication failed.

During handling of the above exception, another exception occurred:

Traceback (most recent call last):
  File "/home/kali/.local/lib/python3.11/site-packages/nornir/core/task.py", line 99, in start
    r = self.task(self, **self.params)
        ^^^^^^^^^^^^^^^^^^^^^^^^^^^^^^
  File "/home/kali/.local/lib/python3.11/site-packages/nornir_napalm/plugins/tasks/napalm_cli.py", line 19, in napalm_cli
    device = task.host.get_connection(CONNECTION_NAME, task.nornir.config)
             ^^^^^^^^^^^^^^^^^^^^^^^^^^^^^^^^^^^^^^^^^^^^^^^^^^^^^^^^^^^^^
  File "/home/kali/.local/lib/python3.11/site-packages/nornir/core/inventory.py", line 494, in get_connection
    self.open_connection(
  File "/home/kali/.local/lib/python3.11/site-packages/nornir/core/inventory.py", line 546, in open_connection
    conn_obj.open(
  File "/home/kali/.local/lib/python3.11/site-packages/nornir_napalm/plugins/connections/__init__.py", line 57, in open
    connection.open()
  File "/home/kali/.local/lib/python3.11/site-packages/napalm/ios/ios.py", line 173, in open
    self.device = self._netmiko_open(
                  ^^^^^^^^^^^^^^^^^^^
  File "/home/kali/.local/lib/python3.11/site-packages/napalm/base/base.py", line 114, in _netmiko_open
    self._netmiko_device = ConnectHandler(
                           ^^^^^^^^^^^^^^^
  File "/home/kali/.local/lib/python3.11/site-packages/netmiko/ssh_dispatcher.py", line 399, in ConnectHandler
    return ConnectionClass(*args, **kwargs)
           ^^^^^^^^^^^^^^^^^^^^^^^^^^^^^^^^
  File "/home/kali/.local/lib/python3.11/site-packages/netmiko/base_connection.py", line 488, in __init__
    self._open()
  File "/home/kali/.local/lib/python3.11/site-packages/netmiko/base_connection.py", line 493, in _open
    self.establish_connection()
  File "/home/kali/.local/lib/python3.11/site-packages/netmiko/base_connection.py", line 1174, in establish_connection
    raise NetmikoAuthenticationException(msg)
netmiko.exceptions.NetmikoAuthenticationException: Authentication to device failed.

Common causes of this problem are:
1. Invalid username and password
2. Incorrect SSH-key file
3. Connecting to the wrong device

Device settings: cisco_ios 10.5.48.57:22


Authentication failed.

2024-04-19 05:08:50,922 - nornir.core.task -    ERROR -      start() - Host 'BHN-A-9F-SW': task 'nornir_napalm_cli_commands_example' failed with traceback:
Traceback (most recent call last):
  File "/home/kali/.local/lib/python3.11/site-packages/nornir/core/task.py", line 99, in start
    r = self.task(self, **self.params)
        ^^^^^^^^^^^^^^^^^^^^^^^^^^^^^^
  File "/home/kali/Desktop/Nornir/2023/5.nornir_napalm/IITH/cli_inventory_nornir_napalm.py", line 13, in nornir_napalm_cli_commands_example
    task.run(task=napalm_cli, commands=[command])
  File "/home/kali/.local/lib/python3.11/site-packages/nornir/core/task.py", line 174, in run
    raise NornirSubTaskError(task=run_task, result=r)
nornir.core.exceptions.NornirSubTaskError: Subtask: napalm_cli (failed)


2024-04-19 05:08:50,923 - nornir.core.task -    ERROR -      start() - Host 'BHN-B-3F-SW': task 'nornir_napalm_cli_commands_example' failed with traceback:
Traceback (most recent call last):
  File "/home/kali/.local/lib/python3.11/site-packages/nornir/core/task.py", line 99, in start
    r = self.task(self, **self.params)
        ^^^^^^^^^^^^^^^^^^^^^^^^^^^^^^
  File "/home/kali/Desktop/Nornir/2023/5.nornir_napalm/IITH/cli_inventory_nornir_napalm.py", line 13, in nornir_napalm_cli_commands_example
    task.run(task=napalm_cli, commands=[command])
  File "/home/kali/.local/lib/python3.11/site-packages/nornir/core/task.py", line 174, in run
    raise NornirSubTaskError(task=run_task, result=r)
nornir.core.exceptions.NornirSubTaskError: Subtask: napalm_cli (failed)


2024-04-19 05:08:50,923 - nornir.core.task -    ERROR -      start() - Host 'BHN-B-6F-SW': task 'nornir_napalm_cli_commands_example' failed with traceback:
Traceback (most recent call last):
  File "/home/kali/.local/lib/python3.11/site-packages/nornir/core/task.py", line 99, in start
    r = self.task(self, **self.params)
        ^^^^^^^^^^^^^^^^^^^^^^^^^^^^^^
  File "/home/kali/Desktop/Nornir/2023/5.nornir_napalm/IITH/cli_inventory_nornir_napalm.py", line 13, in nornir_napalm_cli_commands_example
    task.run(task=napalm_cli, commands=[command])
  File "/home/kali/.local/lib/python3.11/site-packages/nornir/core/task.py", line 174, in run
    raise NornirSubTaskError(task=run_task, result=r)
nornir.core.exceptions.NornirSubTaskError: Subtask: napalm_cli (failed)


2024-04-19 05:09:35,312 -  nornir.core -     INFO -        run() - Running task 'nornir_napalm_cli_commands_example' with args {} on 57 hosts
2024-04-19 05:09:39,428 - nornir.core.task -    ERROR -      start() - Host 'BHN-A-GF-SW': task 'napalm_cli' failed with traceback:
Traceback (most recent call last):
  File "/home/kali/.local/lib/python3.11/site-packages/netmiko/base_connection.py", line 1137, in establish_connection
    self.remote_conn_pre.connect(**ssh_connect_params)
  File "/usr/lib/python3/dist-packages/paramiko/client.py", line 450, in connect
    self._auth(
  File "/usr/lib/python3/dist-packages/paramiko/client.py", line 781, in _auth
    raise saved_exception
  File "/usr/lib/python3/dist-packages/paramiko/client.py", line 768, in _auth
    self._transport.auth_password(username, password)
  File "/usr/lib/python3/dist-packages/paramiko/transport.py", line 1564, in auth_password
    return self.auth_handler.wait_for_response(my_event)
           ^^^^^^^^^^^^^^^^^^^^^^^^^^^^^^^^^^^^^^^^^^^^^
  File "/usr/lib/python3/dist-packages/paramiko/auth_handler.py", line 259, in wait_for_response
    raise e
paramiko.ssh_exception.AuthenticationException: Authentication failed.

During handling of the above exception, another exception occurred:

Traceback (most recent call last):
  File "/home/kali/.local/lib/python3.11/site-packages/nornir/core/task.py", line 99, in start
    r = self.task(self, **self.params)
        ^^^^^^^^^^^^^^^^^^^^^^^^^^^^^^
  File "/home/kali/.local/lib/python3.11/site-packages/nornir_napalm/plugins/tasks/napalm_cli.py", line 19, in napalm_cli
    device = task.host.get_connection(CONNECTION_NAME, task.nornir.config)
             ^^^^^^^^^^^^^^^^^^^^^^^^^^^^^^^^^^^^^^^^^^^^^^^^^^^^^^^^^^^^^
  File "/home/kali/.local/lib/python3.11/site-packages/nornir/core/inventory.py", line 494, in get_connection
    self.open_connection(
  File "/home/kali/.local/lib/python3.11/site-packages/nornir/core/inventory.py", line 546, in open_connection
    conn_obj.open(
  File "/home/kali/.local/lib/python3.11/site-packages/nornir_napalm/plugins/connections/__init__.py", line 57, in open
    connection.open()
  File "/home/kali/.local/lib/python3.11/site-packages/napalm/ios/ios.py", line 173, in open
    self.device = self._netmiko_open(
                  ^^^^^^^^^^^^^^^^^^^
  File "/home/kali/.local/lib/python3.11/site-packages/napalm/base/base.py", line 114, in _netmiko_open
    self._netmiko_device = ConnectHandler(
                           ^^^^^^^^^^^^^^^
  File "/home/kali/.local/lib/python3.11/site-packages/netmiko/ssh_dispatcher.py", line 399, in ConnectHandler
    return ConnectionClass(*args, **kwargs)
           ^^^^^^^^^^^^^^^^^^^^^^^^^^^^^^^^
  File "/home/kali/.local/lib/python3.11/site-packages/netmiko/base_connection.py", line 488, in __init__
    self._open()
  File "/home/kali/.local/lib/python3.11/site-packages/netmiko/base_connection.py", line 493, in _open
    self.establish_connection()
  File "/home/kali/.local/lib/python3.11/site-packages/netmiko/base_connection.py", line 1174, in establish_connection
    raise NetmikoAuthenticationException(msg)
netmiko.exceptions.NetmikoAuthenticationException: Authentication to device failed.

Common causes of this problem are:
1. Invalid username and password
2. Incorrect SSH-key file
3. Connecting to the wrong device

Device settings: cisco_ios 10.5.48.51:22


Authentication failed.

2024-04-19 05:09:39,429 - nornir.core.task -    ERROR -      start() - Host 'BHN-A-GF-SW': task 'nornir_napalm_cli_commands_example' failed with traceback:
Traceback (most recent call last):
  File "/home/kali/.local/lib/python3.11/site-packages/nornir/core/task.py", line 99, in start
    r = self.task(self, **self.params)
        ^^^^^^^^^^^^^^^^^^^^^^^^^^^^^^
  File "/home/kali/Desktop/Nornir/2023/5.nornir_napalm/IITH/cli_inventory_nornir_napalm.py", line 13, in nornir_napalm_cli_commands_example
    task.run(task=napalm_cli, commands=[command])
  File "/home/kali/.local/lib/python3.11/site-packages/nornir/core/task.py", line 174, in run
    raise NornirSubTaskError(task=run_task, result=r)
nornir.core.exceptions.NornirSubTaskError: Subtask: napalm_cli (failed)


2024-04-19 05:09:39,624 - nornir.core.task -    ERROR -      start() - Host 'BHN-B-GF-SW': task 'napalm_cli' failed with traceback:
Traceback (most recent call last):
  File "/home/kali/.local/lib/python3.11/site-packages/netmiko/base_connection.py", line 1137, in establish_connection
    self.remote_conn_pre.connect(**ssh_connect_params)
  File "/usr/lib/python3/dist-packages/paramiko/client.py", line 450, in connect
    self._auth(
  File "/usr/lib/python3/dist-packages/paramiko/client.py", line 781, in _auth
    raise saved_exception
  File "/usr/lib/python3/dist-packages/paramiko/client.py", line 768, in _auth
    self._transport.auth_password(username, password)
  File "/usr/lib/python3/dist-packages/paramiko/transport.py", line 1564, in auth_password
    return self.auth_handler.wait_for_response(my_event)
           ^^^^^^^^^^^^^^^^^^^^^^^^^^^^^^^^^^^^^^^^^^^^^
  File "/usr/lib/python3/dist-packages/paramiko/auth_handler.py", line 259, in wait_for_response
    raise e
paramiko.ssh_exception.AuthenticationException: Authentication failed.

During handling of the above exception, another exception occurred:

Traceback (most recent call last):
  File "/home/kali/.local/lib/python3.11/site-packages/nornir/core/task.py", line 99, in start
    r = self.task(self, **self.params)
        ^^^^^^^^^^^^^^^^^^^^^^^^^^^^^^
  File "/home/kali/.local/lib/python3.11/site-packages/nornir_napalm/plugins/tasks/napalm_cli.py", line 19, in napalm_cli
    device = task.host.get_connection(CONNECTION_NAME, task.nornir.config)
             ^^^^^^^^^^^^^^^^^^^^^^^^^^^^^^^^^^^^^^^^^^^^^^^^^^^^^^^^^^^^^
  File "/home/kali/.local/lib/python3.11/site-packages/nornir/core/inventory.py", line 494, in get_connection
    self.open_connection(
  File "/home/kali/.local/lib/python3.11/site-packages/nornir/core/inventory.py", line 546, in open_connection
    conn_obj.open(
  File "/home/kali/.local/lib/python3.11/site-packages/nornir_napalm/plugins/connections/__init__.py", line 57, in open
    connection.open()
  File "/home/kali/.local/lib/python3.11/site-packages/napalm/ios/ios.py", line 173, in open
    self.device = self._netmiko_open(
                  ^^^^^^^^^^^^^^^^^^^
  File "/home/kali/.local/lib/python3.11/site-packages/napalm/base/base.py", line 114, in _netmiko_open
    self._netmiko_device = ConnectHandler(
                           ^^^^^^^^^^^^^^^
  File "/home/kali/.local/lib/python3.11/site-packages/netmiko/ssh_dispatcher.py", line 399, in ConnectHandler
    return ConnectionClass(*args, **kwargs)
           ^^^^^^^^^^^^^^^^^^^^^^^^^^^^^^^^
  File "/home/kali/.local/lib/python3.11/site-packages/netmiko/base_connection.py", line 488, in __init__
    self._open()
  File "/home/kali/.local/lib/python3.11/site-packages/netmiko/base_connection.py", line 493, in _open
    self.establish_connection()
  File "/home/kali/.local/lib/python3.11/site-packages/netmiko/base_connection.py", line 1174, in establish_connection
    raise NetmikoAuthenticationException(msg)
netmiko.exceptions.NetmikoAuthenticationException: Authentication to device failed.

Common causes of this problem are:
1. Invalid username and password
2. Incorrect SSH-key file
3. Connecting to the wrong device

Device settings: cisco_ios 10.5.48.56:22


Authentication failed.

2024-04-19 05:09:39,625 - nornir.core.task -    ERROR -      start() - Host 'BHN-B-GF-SW': task 'nornir_napalm_cli_commands_example' failed with traceback:
Traceback (most recent call last):
  File "/home/kali/.local/lib/python3.11/site-packages/nornir/core/task.py", line 99, in start
    r = self.task(self, **self.params)
        ^^^^^^^^^^^^^^^^^^^^^^^^^^^^^^
  File "/home/kali/Desktop/Nornir/2023/5.nornir_napalm/IITH/cli_inventory_nornir_napalm.py", line 13, in nornir_napalm_cli_commands_example
    task.run(task=napalm_cli, commands=[command])
  File "/home/kali/.local/lib/python3.11/site-packages/nornir/core/task.py", line 174, in run
    raise NornirSubTaskError(task=run_task, result=r)
nornir.core.exceptions.NornirSubTaskError: Subtask: napalm_cli (failed)


2024-04-19 05:10:19,899 -  nornir.core -     INFO -        run() - Running task 'nornir_napalm_cli_commands_example' with args {} on 57 hosts
2024-04-19 05:10:24,006 - nornir.core.task -    ERROR -      start() - Host 'BHN-A-GF-SW': task 'napalm_cli' failed with traceback:
Traceback (most recent call last):
  File "/home/kali/.local/lib/python3.11/site-packages/netmiko/base_connection.py", line 1137, in establish_connection
    self.remote_conn_pre.connect(**ssh_connect_params)
  File "/usr/lib/python3/dist-packages/paramiko/client.py", line 450, in connect
    self._auth(
  File "/usr/lib/python3/dist-packages/paramiko/client.py", line 781, in _auth
    raise saved_exception
  File "/usr/lib/python3/dist-packages/paramiko/client.py", line 768, in _auth
    self._transport.auth_password(username, password)
  File "/usr/lib/python3/dist-packages/paramiko/transport.py", line 1564, in auth_password
    return self.auth_handler.wait_for_response(my_event)
           ^^^^^^^^^^^^^^^^^^^^^^^^^^^^^^^^^^^^^^^^^^^^^
  File "/usr/lib/python3/dist-packages/paramiko/auth_handler.py", line 259, in wait_for_response
    raise e
paramiko.ssh_exception.AuthenticationException: Authentication failed.

During handling of the above exception, another exception occurred:

Traceback (most recent call last):
  File "/home/kali/.local/lib/python3.11/site-packages/nornir/core/task.py", line 99, in start
    r = self.task(self, **self.params)
        ^^^^^^^^^^^^^^^^^^^^^^^^^^^^^^
  File "/home/kali/.local/lib/python3.11/site-packages/nornir_napalm/plugins/tasks/napalm_cli.py", line 19, in napalm_cli
    device = task.host.get_connection(CONNECTION_NAME, task.nornir.config)
             ^^^^^^^^^^^^^^^^^^^^^^^^^^^^^^^^^^^^^^^^^^^^^^^^^^^^^^^^^^^^^
  File "/home/kali/.local/lib/python3.11/site-packages/nornir/core/inventory.py", line 494, in get_connection
    self.open_connection(
  File "/home/kali/.local/lib/python3.11/site-packages/nornir/core/inventory.py", line 546, in open_connection
    conn_obj.open(
  File "/home/kali/.local/lib/python3.11/site-packages/nornir_napalm/plugins/connections/__init__.py", line 57, in open
    connection.open()
  File "/home/kali/.local/lib/python3.11/site-packages/napalm/ios/ios.py", line 173, in open
    self.device = self._netmiko_open(
                  ^^^^^^^^^^^^^^^^^^^
  File "/home/kali/.local/lib/python3.11/site-packages/napalm/base/base.py", line 114, in _netmiko_open
    self._netmiko_device = ConnectHandler(
                           ^^^^^^^^^^^^^^^
  File "/home/kali/.local/lib/python3.11/site-packages/netmiko/ssh_dispatcher.py", line 399, in ConnectHandler
    return ConnectionClass(*args, **kwargs)
           ^^^^^^^^^^^^^^^^^^^^^^^^^^^^^^^^
  File "/home/kali/.local/lib/python3.11/site-packages/netmiko/base_connection.py", line 488, in __init__
    self._open()
  File "/home/kali/.local/lib/python3.11/site-packages/netmiko/base_connection.py", line 493, in _open
    self.establish_connection()
  File "/home/kali/.local/lib/python3.11/site-packages/netmiko/base_connection.py", line 1174, in establish_connection
    raise NetmikoAuthenticationException(msg)
netmiko.exceptions.NetmikoAuthenticationException: Authentication to device failed.

Common causes of this problem are:
1. Invalid username and password
2. Incorrect SSH-key file
3. Connecting to the wrong device

Device settings: cisco_ios 10.5.48.51:22


Authentication failed.

2024-04-19 05:10:24,007 - nornir.core.task -    ERROR -      start() - Host 'BHN-A-GF-SW': task 'nornir_napalm_cli_commands_example' failed with traceback:
Traceback (most recent call last):
  File "/home/kali/.local/lib/python3.11/site-packages/nornir/core/task.py", line 99, in start
    r = self.task(self, **self.params)
        ^^^^^^^^^^^^^^^^^^^^^^^^^^^^^^
  File "/home/kali/Desktop/Nornir/2023/5.nornir_napalm/IITH/cli_inventory_nornir_napalm.py", line 13, in nornir_napalm_cli_commands_example
    task.run(task=napalm_cli, commands=[command])
  File "/home/kali/.local/lib/python3.11/site-packages/nornir/core/task.py", line 174, in run
    raise NornirSubTaskError(task=run_task, result=r)
nornir.core.exceptions.NornirSubTaskError: Subtask: napalm_cli (failed)


2024-04-19 05:11:28,341 -  nornir.core -     INFO -        run() - Running task 'nornir_napalm_cli_commands_example' with args {} on 57 hosts
